Workbook

Sheet 26년 타임테이블_조정안(전세라)
A3: 46133
A4: 발표10분 질의 10분 이동5분 | G4: : 추가 취소자 | K4: : 유형 중복(실특으로 통합 발표, 2개 심사표 작성(이승원-지역기반중복, 박한규-대학발 중복) | U4: : 온라인 발표
F5: 정보ㆍ통신1 | K5: 정보ㆍ통신2 | P5: 정보ㆍ통신3(친성) | U5: 정보ㆍ통신4 | Z5: 전기ㆍ전자 | AE5: 기계ㆍ소재 | AJ5: 바이오ㆍ의료ㆍ생명1 | AO5: 바이오ㆍ의료ㆍ생명2 | AT5: 화공ㆍ섬유 | AY5: 에너지ㆍ자원 | BD5: 공예ㆍ디자인
A6: 연번 | C6: 시작 | D6: 종료 | E6: 소요시간 | F6: 위원7명 | G6: 105호 | J6: 박유진 | K6: 위원7명 | L6: 108호 | O6: 이수화 | P6: 위원7명 | Q6: 107호 | T6: 김이진 | U6: 위원7명 | V6: 110호 | Y6: 김지희 | Z6: 위원7명 | AA6: 205호 | AD6: 신동영 | AE6: 위원7명 | AF6: 1304호 | AI6: 박영선 | AJ6: 위원7명 | AK6: 1301호 | AN6: 김도훈 | AO6: 위원7명 | AP6: 1302호 | AS6: 지진훈 | AT6: 위원7명 | AU6: 201호 | AX6: 최희정 | AY6: 위원7명 | AZ6: 208~209호 | BC6: 정승아 | BD6: 위원7명 | BE6: 202호 | BH6: 김수진
C7: 0930 | D7: 1000 | E7: 30 | F7: OT 등
A8: =SUBTOTAL(103,$B$7:B8) -> 1 | B8: 1일차 | C8: 1000 | D8: 1020 | E8: 20 | F8: 20426148 | G8: =VLOOKUP(F8,[1]데이터시트!$B$3:$N$196,2,FALSE) -> 강경민 | H8: =VLOOKUP(F8,[1]데이터시트!$B$3:$N$196,4,FALSE) -> 0 | I8: =VLOOKUP(F8,[1]데이터시트!$B$3:$N$196,11,FALSE) -> 예비 | J8: =VLOOKUP(F8,[1]데이터시트!$B$3:$N$196,6,FALSE) -> 지역기반 | K8: 20418814 | L8: =VLOOKUP(K8,[1]데이터시트!$B$3:$N$196,2,FALSE) -> 현성재 | M8: =VLOOKUP(K8,[1]데이터시트!$B$3:$N$196,4,FALSE) -> 0 | N8: =VLOOKUP(K8,[1]데이터시트!$B$3:$N$196,11,FALSE) -> 예비 | O8: =VLOOKUP(K8,[1]데이터시트!$B$3:$N$196,6,FALSE) -> 지역기반 | P8: 20431973 | Q8: =VLOOKUP(P8,[1]데이터시트!$B$3:$N$196,2,FALSE) -> 길민선 | R8: =VLOOKUP(P8,[1]데이터시트!$B$3:$N$196,4,FALSE) -> 0 | S8: =VLOOKUP(P8,[1]데이터시트!$B$3:$N$196,11,FALSE) -> 예비 | T8: =VLOOKUP(P8,[1]데이터시트!$B$3:$N$196,6,FALSE) -> 지역기반 | U8: 20406894 | V8: =VLOOKUP(U8,[1]데이터시트!$B$3:$N$196,2,FALSE) -> 이송목 | W8: =VLOOKUP(U8,[1]데이터시트!$B$3:$N$196,4,FALSE) -> 잠재력 확인팀 | X8: =VLOOKUP(U8,[1]데이터시트!$B$3:$N$196,11,FALSE) -> 예비 | Y8: =VLOOKUP(U8,[1]데이터시트!$B$3:$N$196,6,FALSE) -> 대학발 | AJ8: 20424315 | AK8: =VLOOKUP(AJ8,[1]데이터시트!$B$3:$N$196,2,FALSE) -> 오원준 | AL8: =VLOOKUP(AJ8,[1]데이터시트!$B$3:$N$196,4,FALSE) -> 0 | AM8: =VLOOKUP(AJ8,[1]데이터시트!$B$3:$N$196,11,FALSE) -> 예비 | AN8: =VLOOKUP(AJ8,[1]데이터시트!$B$3:$N$196,6,FALSE) -> 지역기반 | AO8: 20414096 | AP8: =VLOOKUP(AO8,[1]데이터시트!$B$3:$N$196,2,FALSE) -> 간원진 | AQ8: =VLOOKUP(AO8,[1]데이터시트!$B$3:$N$196,4,FALSE) -> 0 | AR8: =VLOOKUP(AO8,[1]데이터시트!$B$3:$N$196,11,FALSE) -> 예비 | AS8: =VLOOKUP(AO8,[1]데이터시트!$B$3:$N$196,6,FALSE) -> 대학발
A9: =SUBTOTAL(103,$B$7:B9) -> 2 | B9: 1일차 | C9: =D8+5 -> 1025 | D9: 1045 | E9: 20 | F9: 20415839 | G9: =VLOOKUP(F9,[1]데이터시트!$B$3:$N$196,2,FALSE) -> 박상준 | H9: =VLOOKUP(F9,[1]데이터시트!$B$3:$N$196,4,FALSE) -> 0 | I9: =VLOOKUP(F9,[1]데이터시트!$B$3:$N$196,11,FALSE) -> 예비 | J9: =VLOOKUP(F9,[1]데이터시트!$B$3:$N$196,6,FALSE) -> 지역기반 | K9: 20425711 | L9: =VLOOKUP(K9,[1]데이터시트!$B$3:$N$196,2,FALSE) -> 김주연 | M9: =VLOOKUP(K9,[1]데이터시트!$B$3:$N$196,4,FALSE) -> 0 | N9: =VLOOKUP(K9,[1]데이터시트!$B$3:$N$196,11,FALSE) -> 예비 | O9: =VLOOKUP(K9,[1]데이터시트!$B$3:$N$196,6,FALSE) -> 지역기반 | P9: 20428596 | Q9: =VLOOKUP(P9,[1]데이터시트!$B$3:$N$196,2,FALSE) -> 변유한 | R9: =VLOOKUP(P9,[1]데이터시트!$B$3:$N$196,4,FALSE) -> 0 | S9: =VLOOKUP(P9,[1]데이터시트!$B$3:$N$196,11,FALSE) -> 예비 | T9: =VLOOKUP(P9,[1]데이터시트!$B$3:$N$196,6,FALSE) -> 지역기반 | U9: 20425601 | V9: =VLOOKUP(U9,[1]데이터시트!$B$3:$N$196,2,FALSE) -> 박민수 | W9: =VLOOKUP(U9,[1]데이터시트!$B$3:$N$196,4,FALSE) -> 0 | X9: =VLOOKUP(U9,[1]데이터시트!$B$3:$N$196,11,FALSE) -> 예비 | Y9: =VLOOKUP(U9,[1]데이터시트!$B$3:$N$196,6,FALSE) -> 대학발 | AJ9: 20424587 | AK9: =VLOOKUP(AJ9,[1]데이터시트!$B$3:$N$196,2,FALSE) -> 황경래 | AL9: =VLOOKUP(AJ9,[1]데이터시트!$B$3:$N$196,4,FALSE) -> 0 | AM9: =VLOOKUP(AJ9,[1]데이터시트!$B$3:$N$196,11,FALSE) -> 예비 | AN9: =VLOOKUP(AJ9,[1]데이터시트!$B$3:$N$196,6,FALSE) -> 지역기반 | AO9: 20424497 | AP9: =VLOOKUP(AO9,[1]데이터시트!$B$3:$N$196,2,FALSE) -> 김경민 | AQ9: =VLOOKUP(AO9,[1]데이터시트!$B$3:$N$196,4,FALSE) -> 전임교원 | AR9: =VLOOKUP(AO9,[1]데이터시트!$B$3:$N$196,11,FALSE) -> 예비 | AS9: =VLOOKUP(AO9,[1]데이터시트!$B$3:$N$196,6,FALSE) -> 대학발
A10: =SUBTOTAL(103,$B$7:B10) -> 3 | B10: 1일차 | C10: =D9+5 -> 1050 | D10: 1110 | E10: 20 | F10: 20416056 | G10: =VLOOKUP(F10,[1]데이터시트!$B$3:$N$196,2,FALSE) -> 강태환 | H10: =VLOOKUP(F10,[1]데이터시트!$B$3:$N$196,4,FALSE) -> 0 | I10: =VLOOKUP(F10,[1]데이터시트!$B$3:$N$196,11,FALSE) -> 초기 | J10: =VLOOKUP(F10,[1]데이터시트!$B$3:$N$196,6,FALSE) -> 지역기반 | K10: 20414883 | L10: =VLOOKUP(K10,[1]데이터시트!$B$3:$N$196,2,FALSE) -> 윤상민 | M10: =VLOOKUP(K10,[1]데이터시트!$B$3:$N$196,4,FALSE) -> 매출실적우수 | N10: =VLOOKUP(K10,[1]데이터시트!$B$3:$N$196,11,FALSE) -> 초기 | O10: =VLOOKUP(K10,[1]데이터시트!$B$3:$N$196,6,FALSE) -> 지역기반 | P10: 20428535 | Q10: =VLOOKUP(P10,[1]데이터시트!$B$3:$N$196,2,FALSE) -> 양승빈 | R10: =VLOOKUP(P10,[1]데이터시트!$B$3:$N$196,4,FALSE) -> 잠재력 확인 팀 | S10: =VLOOKUP(P10,[1]데이터시트!$B$3:$N$196,11,FALSE) -> 예비 | T10: =VLOOKUP(P10,[1]데이터시트!$B$3:$N$196,6,FALSE) -> 지역기반 | U10: 20424645 | V10: =VLOOKUP(U10,[1]데이터시트!$B$3:$N$196,2,FALSE) -> 이장원 | W10: =VLOOKUP(U10,[1]데이터시트!$B$3:$N$196,4,FALSE) -> 전임교원 | X10: =VLOOKUP(U10,[1]데이터시트!$B$3:$N$196,11,FALSE) -> 예비 | Y10: =VLOOKUP(U10,[1]데이터시트!$B$3:$N$196,6,FALSE) -> 대학발 | AJ10: 20424775 | AK10: =VLOOKUP(AJ10,[1]데이터시트!$B$3:$N$196,2,FALSE) -> 김유성 | AL10: =VLOOKUP(AJ10,[1]데이터시트!$B$3:$N$196,4,FALSE) -> 0 | AM10: =VLOOKUP(AJ10,[1]데이터시트!$B$3:$N$196,11,FALSE) -> 예비 | AN10: =VLOOKUP(AJ10,[1]데이터시트!$B$3:$N$196,6,FALSE) -> 지역기반 | AO10: 20418691 | AP10: =VLOOKUP(AO10,[1]데이터시트!$B$3:$N$196,2,FALSE) -> 최우석 | AQ10: =VLOOKUP(AO10,[1]데이터시트!$B$3:$N$196,4,FALSE) -> 전임교원 | AR10: =VLOOKUP(AO10,[1]데이터시트!$B$3:$N$196,11,FALSE) -> 예비 | AS10: =VLOOKUP(AO10,[1]데이터시트!$B$3:$N$196,6,FALSE) -> 대학발
A11: =SUBTOTAL(103,$B$7:B11) -> 4 | B11: 1일차 | C11: =D10+5 -> 1115 | D11: 1135 | E11: 20 | F11: 20423046 | G11: =VLOOKUP(F11,[1]데이터시트!$B$3:$N$196,2,FALSE) -> 김대호 | H11: =VLOOKUP(F11,[1]데이터시트!$B$3:$N$196,4,FALSE) -> 0 | I11: =VLOOKUP(F11,[1]데이터시트!$B$3:$N$196,11,FALSE) -> 초기 | J11: =VLOOKUP(F11,[1]데이터시트!$B$3:$N$196,6,FALSE) -> 지역기반 | K11: 20427569 | L11: =VLOOKUP(K11,[1]데이터시트!$B$3:$N$196,2,FALSE) -> 김선일 | M11: =VLOOKUP(K11,[1]데이터시트!$B$3:$N$196,4,FALSE) -> 0 | N11: =VLOOKUP(K11,[1]데이터시트!$B$3:$N$196,11,FALSE) -> 초기 | O11: =VLOOKUP(K11,[1]데이터시트!$B$3:$N$196,6,FALSE) -> 지역기반 | P11: 20418175 | Q11: =VLOOKUP(P11,[1]데이터시트!$B$3:$N$196,2,FALSE) -> 안세정 | R11: =VLOOKUP(P11,[1]데이터시트!$B$3:$N$196,4,FALSE) -> 잠재력 확인 팀 | S11: =VLOOKUP(P11,[1]데이터시트!$B$3:$N$196,11,FALSE) -> 예비 | T11: =VLOOKUP(P11,[1]데이터시트!$B$3:$N$196,6,FALSE) -> 지역기반 | U11: 20420127 | V11: =VLOOKUP(U11,[1]데이터시트!$B$3:$N$196,2,FALSE) -> 명대호 | W11: =VLOOKUP(U11,[1]데이터시트!$B$3:$N$196,4,FALSE) -> 0 | X11: =VLOOKUP(U11,[1]데이터시트!$B$3:$N$196,11,FALSE) -> 예비 | Y11: =VLOOKUP(U11,[1]데이터시트!$B$3:$N$196,6,FALSE) -> 대학발 | AJ11: 20412297 | AK11: =VLOOKUP(AJ11,[1]데이터시트!$B$3:$N$196,2,FALSE) -> 황현우 | AL11: =VLOOKUP(AJ11,[1]데이터시트!$B$3:$N$196,4,FALSE) -> 0 | AM11: =VLOOKUP(AJ11,[1]데이터시트!$B$3:$N$196,11,FALSE) -> 초기 | AN11: =VLOOKUP(AJ11,[1]데이터시트!$B$3:$N$196,6,FALSE) -> 지역기반 | AO11: 20428779 | AP11: =VLOOKUP(AO11,[1]데이터시트!$B$3:$N$196,2,FALSE) -> 조덕수 | AQ11: =VLOOKUP(AO11,[1]데이터시트!$B$3:$N$196,4,FALSE) -> 0 | AR11: =VLOOKUP(AO11,[1]데이터시트!$B$3:$N$196,11,FALSE) -> 도약 | AS11: =VLOOKUP(AO11,[1]데이터시트!$B$3:$N$196,6,FALSE) -> 대학발
A12: =SUBTOTAL(103,$B$7:B12) -> 5 | B12: 1일차 | C12: =D11+5 -> 1140 | D12: 1200 | E12: 20 | F12: 20428945 | G12: =VLOOKUP(F12,[1]데이터시트!$B$3:$N$196,2,FALSE) -> 이건희 | H12: =VLOOKUP(F12,[1]데이터시트!$B$3:$N$196,4,FALSE) -> 0 | I12: =VLOOKUP(F12,[1]데이터시트!$B$3:$N$196,11,FALSE) -> 초기 | J12: =VLOOKUP(F12,[1]데이터시트!$B$3:$N$196,6,FALSE) -> 지역기반 | K12: 20431661 | L12: =VLOOKUP(K12,[1]데이터시트!$B$3:$N$196,2,FALSE) -> 문상윤 | M12: =VLOOKUP(K12,[1]데이터시트!$B$3:$N$196,4,FALSE) -> 0 | N12: =VLOOKUP(K12,[1]데이터시트!$B$3:$N$196,11,FALSE) -> 초기 | O12: =VLOOKUP(K12,[1]데이터시트!$B$3:$N$196,6,FALSE) -> 지역기반 | P12: 20429808 | Q12: =VLOOKUP(P12,[1]데이터시트!$B$3:$N$196,2,FALSE) -> 정웅택 | R12: =VLOOKUP(P12,[1]데이터시트!$B$3:$N$196,4,FALSE) -> (후속)청년창업사관학교추천 | S12: =VLOOKUP(P12,[1]데이터시트!$B$3:$N$196,11,FALSE) -> 초기 | T12: =VLOOKUP(P12,[1]데이터시트!$B$3:$N$196,6,FALSE) -> 지역기반 | AJ12: 20405890 | AK12: =VLOOKUP(AJ12,[1]데이터시트!$B$3:$N$196,2,FALSE) -> 조희준 | AL12: =VLOOKUP(AJ12,[1]데이터시트!$B$3:$N$196,4,FALSE) -> 0 | AM12: =VLOOKUP(AJ12,[1]데이터시트!$B$3:$N$196,11,FALSE) -> 초기 | AN12: =VLOOKUP(AJ12,[1]데이터시트!$B$3:$N$196,6,FALSE) -> 지역기반
C13: 1200 | D13: 1300 | E13: 60 | F13: 점심
A14: =SUBTOTAL(103,$B$7:B14) -> 6 | B14: 1일차 | C14: 1300 | D14: 1320 | E14: 20 | F14: 20420108 | G14: =VLOOKUP(F14,[1]데이터시트!$B$3:$N$196,2,FALSE) -> 이여진 | H14: =VLOOKUP(F14,[1]데이터시트!$B$3:$N$196,4,FALSE) -> 0 | I14: =VLOOKUP(F14,[1]데이터시트!$B$3:$N$196,11,FALSE) -> 초기 | J14: =VLOOKUP(F14,[1]데이터시트!$B$3:$N$196,6,FALSE) -> 지역기반 | K14: 20417471 | L14: =VLOOKUP(K14,[1]데이터시트!$B$3:$N$196,2,FALSE) -> 하은주 | M14: =VLOOKUP(K14,[1]데이터시트!$B$3:$N$196,4,FALSE) -> 0 | N14: =VLOOKUP(K14,[1]데이터시트!$B$3:$N$196,11,FALSE) -> 도약 | O14: =VLOOKUP(K14,[1]데이터시트!$B$3:$N$196,6,FALSE) -> 지역기반 | P14: 20418037 | Q14: =VLOOKUP(P14,[1]데이터시트!$B$3:$N$196,2,FALSE) -> 조영숙 | R14: =VLOOKUP(P14,[1]데이터시트!$B$3:$N$196,4,FALSE) -> 0 | S14: =VLOOKUP(P14,[1]데이터시트!$B$3:$N$196,11,FALSE) -> 초기 | T14: =VLOOKUP(P14,[1]데이터시트!$B$3:$N$196,6,FALSE) -> 지역기반 | U14: 20429253 | V14: =VLOOKUP(U14,[1]데이터시트!$B$3:$N$196,2,FALSE) -> 임재우 | W14: =VLOOKUP(U14,[1]데이터시트!$B$3:$N$196,4,FALSE) -> 0 | X14: =VLOOKUP(U14,[1]데이터시트!$B$3:$N$196,11,FALSE) -> 초기 | Y14: =VLOOKUP(U14,[1]데이터시트!$B$3:$N$196,6,FALSE) -> 대학발 | AJ14: 20417774 | AK14: =VLOOKUP(AJ14,[1]데이터시트!$B$3:$N$196,2,FALSE) -> 김홍국 | AL14: =VLOOKUP(AJ14,[1]데이터시트!$B$3:$N$196,4,FALSE) -> 0 | AM14: =VLOOKUP(AJ14,[1]데이터시트!$B$3:$N$196,11,FALSE) -> 도약 | AN14: =VLOOKUP(AJ14,[1]데이터시트!$B$3:$N$196,6,FALSE) -> 지역기반 | AO14: 20425607 | AP14: =VLOOKUP(AO14,[1]데이터시트!$B$3:$N$196,2,FALSE) -> 신동성 | AQ14: =VLOOKUP(AO14,[1]데이터시트!$B$3:$N$196,4,FALSE) -> 0 | AR14: =VLOOKUP(AO14,[1]데이터시트!$B$3:$N$196,11,FALSE) -> 초기 | AS14: =VLOOKUP(AO14,[1]데이터시트!$B$3:$N$196,6,FALSE) -> 대학발
A15: =SUBTOTAL(103,$B$7:B15) -> 7 | B15: 1일차 | C15: =D14+5 -> 1325 | D15: 1345 | E15: 20 | F15: 20429573 | G15: =VLOOKUP(F15,[1]데이터시트!$B$3:$N$196,2,FALSE) -> 배경환 | H15: =VLOOKUP(F15,[1]데이터시트!$B$3:$N$196,4,FALSE) -> 0 | I15: =VLOOKUP(F15,[1]데이터시트!$B$3:$N$196,11,FALSE) -> 초기 | J15: =VLOOKUP(F15,[1]데이터시트!$B$3:$N$196,6,FALSE) -> 지역기반 | K15: 20418401 | L15: =VLOOKUP(K15,[1]데이터시트!$B$3:$N$196,2,FALSE) -> 박종명 | M15: =VLOOKUP(K15,[1]데이터시트!$B$3:$N$196,4,FALSE) -> 0 | N15: =VLOOKUP(K15,[1]데이터시트!$B$3:$N$196,11,FALSE) -> 도약 | O15: =VLOOKUP(K15,[1]데이터시트!$B$3:$N$196,6,FALSE) -> 지역기반 | P15: 20425812 | Q15: =VLOOKUP(P15,[1]데이터시트!$B$3:$N$196,2,FALSE) -> 이승한 | R15: =VLOOKUP(P15,[1]데이터시트!$B$3:$N$196,4,FALSE) -> 0 | S15: =VLOOKUP(P15,[1]데이터시트!$B$3:$N$196,11,FALSE) -> 초기 | T15: =VLOOKUP(P15,[1]데이터시트!$B$3:$N$196,6,FALSE) -> 지역기반 | U15: 20429524 | V15: =VLOOKUP(U15,[1]데이터시트!$B$3:$N$196,2,FALSE) -> 김동현 | W15: =VLOOKUP(U15,[1]데이터시트!$B$3:$N$196,4,FALSE) -> 0 | X15: =VLOOKUP(U15,[1]데이터시트!$B$3:$N$196,11,FALSE) -> 초기 | Y15: =VLOOKUP(U15,[1]데이터시트!$B$3:$N$196,6,FALSE) -> 대학발 | AJ15: 20417896 | AK15: =VLOOKUP(AJ15,[1]데이터시트!$B$3:$N$196,2,FALSE) -> 백승엽 | AL15: =VLOOKUP(AJ15,[1]데이터시트!$B$3:$N$196,4,FALSE) -> 0 | AM15: =VLOOKUP(AJ15,[1]데이터시트!$B$3:$N$196,11,FALSE) -> 도약 | AN15: =VLOOKUP(AJ15,[1]데이터시트!$B$3:$N$196,6,FALSE) -> 지역기반 | AO15: 20425675 | AP15: =VLOOKUP(AO15,[1]데이터시트!$B$3:$N$196,2,FALSE) -> 양준우 | AQ15: =VLOOKUP(AO15,[1]데이터시트!$B$3:$N$196,4,FALSE) -> 0 | AR15: =VLOOKUP(AO15,[1]데이터시트!$B$3:$N$196,11,FALSE) -> 초기 | AS15: =VLOOKUP(AO15,[1]데이터시트!$B$3:$N$196,6,FALSE) -> 대학발
A16: =SUBTOTAL(103,$B$7:B16) -> 8 | B16: 1일차 | C16: =D15+5 -> 1350 | D16: 1410 | E16: 20 | F16: 20420270 | G16: =VLOOKUP(F16,[1]데이터시트!$B$3:$N$196,2,FALSE) -> 박수연 | H16: =VLOOKUP(F16,[1]데이터시트!$B$3:$N$196,4,FALSE) -> 0 | I16: =VLOOKUP(F16,[1]데이터시트!$B$3:$N$196,11,FALSE) -> 도약 | J16: =VLOOKUP(F16,[1]데이터시트!$B$3:$N$196,6,FALSE) -> 지역기반 | K16: 20425290 | L16: =VLOOKUP(K16,[1]데이터시트!$B$3:$N$196,2,FALSE) -> 정희철 | M16: =VLOOKUP(K16,[1]데이터시트!$B$3:$N$196,4,FALSE) -> 0 | N16: =VLOOKUP(K16,[1]데이터시트!$B$3:$N$196,11,FALSE) -> 도약 | O16: =VLOOKUP(K16,[1]데이터시트!$B$3:$N$196,6,FALSE) -> 지역기반 | P16: 20428287 | Q16: =VLOOKUP(P16,[1]데이터시트!$B$3:$N$196,2,FALSE) -> 황해수 | R16: =VLOOKUP(P16,[1]데이터시트!$B$3:$N$196,4,FALSE) -> 잠재력 확인 팀 | S16: =VLOOKUP(P16,[1]데이터시트!$B$3:$N$196,11,FALSE) -> 초기 | T16: =VLOOKUP(P16,[1]데이터시트!$B$3:$N$196,6,FALSE) -> 지역기반 | U16: 20429214 | V16: =VLOOKUP(U16,[1]데이터시트!$B$3:$N$196,2,FALSE) -> 김영진 | W16: =VLOOKUP(U16,[1]데이터시트!$B$3:$N$196,4,FALSE) -> 0 | X16: =VLOOKUP(U16,[1]데이터시트!$B$3:$N$196,11,FALSE) -> 초기 | Y16: =VLOOKUP(U16,[1]데이터시트!$B$3:$N$196,6,FALSE) -> 대학발 | AJ16: 20418609 | AK16: =VLOOKUP(AJ16,[1]데이터시트!$B$3:$N$196,2,FALSE) -> 이상헌 | AL16: =VLOOKUP(AJ16,[1]데이터시트!$B$3:$N$196,4,FALSE) -> 0 | AM16: =VLOOKUP(AJ16,[1]데이터시트!$B$3:$N$196,11,FALSE) -> 도약 | AN16: =VLOOKUP(AJ16,[1]데이터시트!$B$3:$N$196,6,FALSE) -> 지역기반 | AO16: 20418903 | AP16: =VLOOKUP(AO16,[1]데이터시트!$B$3:$N$196,2,FALSE) -> 신재영 | AQ16: =VLOOKUP(AO16,[1]데이터시트!$B$3:$N$196,4,FALSE) -> 0 | AR16: =VLOOKUP(AO16,[1]데이터시트!$B$3:$N$196,11,FALSE) -> 초기 | AS16: =VLOOKUP(AO16,[1]데이터시트!$B$3:$N$196,6,FALSE) -> 대학발
A17: =SUBTOTAL(103,$B$7:B17) -> 9 | B17: 1일차 | C17: =D16+5 -> 1415 | D17: 1435 | E17: 20 | F17: 20428115 | G17: =VLOOKUP(F17,[1]데이터시트!$B$3:$N$196,2,FALSE) -> 권정훈 | H17: =VLOOKUP(F17,[1]데이터시트!$B$3:$N$196,4,FALSE) -> 0 | I17: =VLOOKUP(F17,[1]데이터시트!$B$3:$N$196,11,FALSE) -> 도약 | J17: =VLOOKUP(F17,[1]데이터시트!$B$3:$N$196,6,FALSE) -> 지역기반 | K17: 20429725 | L17: =VLOOKUP(K17,[1]데이터시트!$B$3:$N$196,2,FALSE) -> 김현 | M17: =VLOOKUP(K17,[1]데이터시트!$B$3:$N$196,4,FALSE) -> 0 | N17: =VLOOKUP(K17,[1]데이터시트!$B$3:$N$196,11,FALSE) -> 도약 | O17: =VLOOKUP(K17,[1]데이터시트!$B$3:$N$196,6,FALSE) -> 지역기반 | P17: 20429982 | Q17: =VLOOKUP(P17,[1]데이터시트!$B$3:$N$196,2,FALSE) -> 이은지 | R17: =VLOOKUP(P17,[1]데이터시트!$B$3:$N$196,4,FALSE) -> 잠재력 확인 팀 | S17: =VLOOKUP(P17,[1]데이터시트!$B$3:$N$196,11,FALSE) -> 도약 | T17: =VLOOKUP(P17,[1]데이터시트!$B$3:$N$196,6,FALSE) -> 지역기반 | U17: 20426082 | V17: =VLOOKUP(U17,[1]데이터시트!$B$3:$N$196,2,FALSE) -> 박주혁 | W17: =VLOOKUP(U17,[1]데이터시트!$B$3:$N$196,4,FALSE) -> 매출실적우수 | X17: =VLOOKUP(U17,[1]데이터시트!$B$3:$N$196,11,FALSE) -> 도약 | Y17: =VLOOKUP(U17,[1]데이터시트!$B$3:$N$196,6,FALSE) -> 대학발 | AJ17: 20418733 | AK17: =VLOOKUP(AJ17,[1]데이터시트!$B$3:$N$196,2,FALSE) -> 김진웅 | AL17: =VLOOKUP(AJ17,[1]데이터시트!$B$3:$N$196,4,FALSE) -> 0 | AM17: =VLOOKUP(AJ17,[1]데이터시트!$B$3:$N$196,11,FALSE) -> 도약 | AN17: =VLOOKUP(AJ17,[1]데이터시트!$B$3:$N$196,6,FALSE) -> 지역기반 | AO17: 20429861 | AP17: =VLOOKUP(AO17,[1]데이터시트!$B$3:$N$196,2,FALSE) -> 오혜린 | AQ17: =VLOOKUP(AO17,[1]데이터시트!$B$3:$N$196,4,FALSE) -> 0 | AR17: =VLOOKUP(AO17,[1]데이터시트!$B$3:$N$196,11,FALSE) -> 초기 | AS17: =VLOOKUP(AO17,[1]데이터시트!$B$3:$N$196,6,FALSE) -> 대학발
A18: =SUBTOTAL(103,$B$7:B18) -> 10 | B18: 1일차 | C18: =D17+5 -> 1440 | D18: 1500 | E18: 20 | F18: 20428639 | G18: =VLOOKUP(F18,[1]데이터시트!$B$3:$N$196,2,FALSE) -> 권도현 | H18: =VLOOKUP(F18,[1]데이터시트!$B$3:$N$196,4,FALSE) -> 0 | I18: =VLOOKUP(F18,[1]데이터시트!$B$3:$N$196,11,FALSE) -> 도약 | J18: =VLOOKUP(F18,[1]데이터시트!$B$3:$N$196,6,FALSE) -> 지역기반 | K18: 20408825 | L18: =VLOOKUP(K18,[1]데이터시트!$B$3:$N$196,2,FALSE) -> 한대희 | M18: =VLOOKUP(K18,[1]데이터시트!$B$3:$N$196,4,FALSE) -> 0 | N18: =VLOOKUP(K18,[1]데이터시트!$B$3:$N$196,11,FALSE) -> 도약 | O18: =VLOOKUP(K18,[1]데이터시트!$B$3:$N$196,6,FALSE) -> 지역기반 | P18: 20415684 | Q18: =VLOOKUP(P18,[1]데이터시트!$B$3:$N$196,2,FALSE) -> 김명곤 | R18: =VLOOKUP(P18,[1]데이터시트!$B$3:$N$196,4,FALSE) -> 0 | S18: =VLOOKUP(P18,[1]데이터시트!$B$3:$N$196,11,FALSE) -> 도약 | T18: =VLOOKUP(P18,[1]데이터시트!$B$3:$N$196,6,FALSE) -> 지역기반 | U18: 20424850 | V18: =VLOOKUP(U18,[1]데이터시트!$B$3:$N$196,2,FALSE) -> 안영샘 | W18: =VLOOKUP(U18,[1]데이터시트!$B$3:$N$196,4,FALSE) -> 0 | X18: =VLOOKUP(U18,[1]데이터시트!$B$3:$N$196,11,FALSE) -> 도약 | Y18: =VLOOKUP(U18,[1]데이터시트!$B$3:$N$196,6,FALSE) -> 대학발 | AJ18: 20407665 | AK18: =VLOOKUP(AJ18,[1]데이터시트!$B$3:$N$196,2,FALSE) -> 박지은 | AL18: =VLOOKUP(AJ18,[1]데이터시트!$B$3:$N$196,4,FALSE) -> 0 | AM18: =VLOOKUP(AJ18,[1]데이터시트!$B$3:$N$196,11,FALSE) -> 도약 | AN18: =VLOOKUP(AJ18,[1]데이터시트!$B$3:$N$196,6,FALSE) -> 지역기반 | AO18: 20427486 | AP18: =VLOOKUP(AO18,[1]데이터시트!$B$3:$N$196,2,FALSE) -> 손창호 | AQ18: =VLOOKUP(AO18,[1]데이터시트!$B$3:$N$196,4,FALSE) -> 0 | AR18: =VLOOKUP(AO18,[1]데이터시트!$B$3:$N$196,11,FALSE) -> 초기 | AS18: =VLOOKUP(AO18,[1]데이터시트!$B$3:$N$196,6,FALSE) -> 실험실
A19: =SUBTOTAL(103,$B$7:B19) -> 11 | B19: 1일차 | C19: =D18+5 -> 1505 | D19: 1525 | E19: 20 | F19: 20414308 | G19: =VLOOKUP(F19,[1]데이터시트!$B$3:$N$196,2,FALSE) -> 최용호 | H19: =VLOOKUP(F19,[1]데이터시트!$B$3:$N$196,4,FALSE) -> 0 | I19: =VLOOKUP(F19,[1]데이터시트!$B$3:$N$196,11,FALSE) -> 도약 | J19: =VLOOKUP(F19,[1]데이터시트!$B$3:$N$196,6,FALSE) -> 지역기반 | K19: 20422010 | L19: =VLOOKUP(K19,[1]데이터시트!$B$3:$N$196,2,FALSE) -> 김예지 | M19: =VLOOKUP(K19,[1]데이터시트!$B$3:$N$196,4,FALSE) -> 0 | N19: =VLOOKUP(K19,[1]데이터시트!$B$3:$N$196,11,FALSE) -> 도약 | O19: =VLOOKUP(K19,[1]데이터시트!$B$3:$N$196,6,FALSE) -> 지역기반 | P19: 20418458 | Q19: =VLOOKUP(P19,[1]데이터시트!$B$3:$N$196,2,FALSE) -> 임유진 | R19: =VLOOKUP(P19,[1]데이터시트!$B$3:$N$196,4,FALSE) -> 0 | S19: =VLOOKUP(P19,[1]데이터시트!$B$3:$N$196,11,FALSE) -> 도약 | T19: =VLOOKUP(P19,[1]데이터시트!$B$3:$N$196,6,FALSE) -> 지역기반 | AJ19: 20410913 | AK19: =VLOOKUP(AJ19,[1]데이터시트!$B$3:$N$196,2,FALSE) -> 윤병현 | AL19: =VLOOKUP(AJ19,[1]데이터시트!$B$3:$N$196,4,FALSE) -> 0 | AM19: =VLOOKUP(AJ19,[1]데이터시트!$B$3:$N$196,11,FALSE) -> 도약 | AN19: =VLOOKUP(AJ19,[1]데이터시트!$B$3:$N$196,6,FALSE) -> 지역기반 | AO19: 20428862 | AP19: =VLOOKUP(AO19,[1]데이터시트!$B$3:$N$196,2,FALSE) -> 왕준호 | AQ19: =VLOOKUP(AO19,[1]데이터시트!$B$3:$N$196,4,FALSE) -> 전임교원 | AR19: =VLOOKUP(AO19,[1]데이터시트!$B$3:$N$196,11,FALSE) -> 초기 | AS19: =VLOOKUP(AO19,[1]데이터시트!$B$3:$N$196,6,FALSE) -> 실험실
A20: =SUBTOTAL(103,$B$7:B20) -> 12 | B20: 1일차 | C20: =D19+5 -> 1530 | D20: 1550 | E20: 20 | F20: 20427459 | G20: =VLOOKUP(F20,[1]데이터시트!$B$3:$N$196,2,FALSE) -> 신인근 | H20: =VLOOKUP(F20,[1]데이터시트!$B$3:$N$196,4,FALSE) -> 0 | I20: =VLOOKUP(F20,[1]데이터시트!$B$3:$N$196,11,FALSE) -> 도약 | J20: =VLOOKUP(F20,[1]데이터시트!$B$3:$N$196,6,FALSE) -> 지역기반 | K20: 20426671 | L20: =VLOOKUP(K20,[1]데이터시트!$B$3:$N$196,2,FALSE) -> 이해섭 | M20: =VLOOKUP(K20,[1]데이터시트!$B$3:$N$196,4,FALSE) -> 0 | N20: =VLOOKUP(K20,[1]데이터시트!$B$3:$N$196,11,FALSE) -> 도약 | O20: =VLOOKUP(K20,[1]데이터시트!$B$3:$N$196,6,FALSE) -> 지역기반 | P20: 20413200 | Q20: =VLOOKUP(P20,[1]데이터시트!$B$3:$N$196,2,FALSE) -> 승영욱 | R20: =VLOOKUP(P20,[1]데이터시트!$B$3:$N$196,4,FALSE) -> 잠재력 확인 팀 | S20: =VLOOKUP(P20,[1]데이터시트!$B$3:$N$196,11,FALSE) -> 도약 | T20: =VLOOKUP(P20,[1]데이터시트!$B$3:$N$196,6,FALSE) -> 지역기반 | AJ20: 20413981 | AK20: =VLOOKUP(AJ20,[1]데이터시트!$B$3:$N$196,2,FALSE) -> 조백상 | AL20: =VLOOKUP(AJ20,[1]데이터시트!$B$3:$N$196,4,FALSE) -> 0 | AM20: =VLOOKUP(AJ20,[1]데이터시트!$B$3:$N$196,11,FALSE) -> 도약 | AN20: =VLOOKUP(AJ20,[1]데이터시트!$B$3:$N$196,6,FALSE) -> 지역기반
A21: =SUBTOTAL(103,$B$7:B21) -> 13 | B21: 1일차 | C21: =D20+5 -> 1555 | D21: 1615 | E21: 20
A22: =SUBTOTAL(103,$B$7:B22) -> 14 | B22: 1일차 | C22: =D21+5 -> 1620 | D22: 1640 | E22: 20
A24: 46134
A25: 발표10분 질의 10분 이동5분
F26: 정보ㆍ통신1 | K26: 정보ㆍ통신2 | P26: 정보ㆍ통신3(친성) | U26: 정보ㆍ통신4 | Z26: 전기ㆍ전자 | AE26: 기계ㆍ소재 | AJ26: 바이오ㆍ의료ㆍ생명1 | AO26: 바이오ㆍ의료ㆍ생명2 | AT26: 화공ㆍ섬유 | AY26: 에너지ㆍ자원 | BD26: 공예ㆍ디자인
A27: 순번 | B27: 연번 | C27: 시작 | D27: 종료 | E27: 소요시간 | F27: 위원7명 | G27: =G6 -> 105호 | J27: =J6 -> 박유진 | K27: 위원7명 | L27: =L6 -> 108호 | O27: =O6 -> 이수화 | P27: 위원7명 | Q27: =Q6 -> 107호 | T27: =T6 -> 김이진 | U27: 위원7명 | V27: =V6 -> 110호 | Y27: =Y6 -> 김지희 | Z27: 위원7명 | AA27: =AA6 -> 205호 | AD27: =AD6 -> 신동영 | AE27: 위원7명 | AF27: =AF6 -> 1304호 | AI27: =AI6 -> 박영선 | AJ27: 위원7명 | AK27: =AK6 -> 1301호 | AN27: =AN6 -> 김도훈 | AO27: 위원7명 | AP27: =AP6 -> 1302호 | AS27: =AS6 -> 지진훈 | AT27: 위원7명 | AU27: =AU6 -> 201호 | AX27: =AX6 -> 최희정 | AY27: 위원7명 | AZ27: =AZ6 -> 208~209호 | BC27: =BC6 -> 정승아 | BD27: 위원7명 | BE27: 20428661 | BH27: =BH6 -> 김수진
C28: 0930 | D28: 1000 | E28: 30 | F28: OT 등
A29: =SUBTOTAL(103,$B$29:B29) -> 1 | B29: 2일차 | C29: 1000 | D29: 1020 | E29: 20 | F29: 20424619 | G29: =VLOOKUP(F29,[1]데이터시트!$B$3:$N$196,2,FALSE) -> 김현지 | H29: =VLOOKUP(F29,[1]데이터시트!$B$3:$N$196,4,FALSE) -> 0 | I29: =VLOOKUP(F29,[1]데이터시트!$B$3:$N$196,11,FALSE) -> 초기 | J29: =VLOOKUP(F29,[1]데이터시트!$B$3:$N$196,6,FALSE) -> 지역기반 | K29: 20412766 | L29: =VLOOKUP(K29,[1]데이터시트!$B$3:$N$196,2,FALSE) -> 한경용 | M29: =VLOOKUP(K29,[1]데이터시트!$B$3:$N$196,4,FALSE) -> 0 | N29: =VLOOKUP(K29,[1]데이터시트!$B$3:$N$196,11,FALSE) -> 예비 | O29: =VLOOKUP(K31,[1]데이터시트!$B$3:$N$196,6,FALSE) -> 지역기반 | P29: 20430270 | Q29: =VLOOKUP(P29,[1]데이터시트!$B$3:$N$196,2,FALSE) -> 백종욱 | R29: =VLOOKUP(P29,[1]데이터시트!$B$3:$N$196,4,FALSE) -> 0 | S29: =VLOOKUP(P29,[1]데이터시트!$B$3:$N$196,11,FALSE) -> 도약 | T29: =VLOOKUP(P29,[1]데이터시트!$B$3:$N$196,6,FALSE) -> 지역기반 | U29: 20431469 | V29: =VLOOKUP(U29,[1]데이터시트!$B$3:$N$196,2,FALSE) -> 고형진 | W29: =VLOOKUP(U29,[1]데이터시트!$B$3:$N$196,4,FALSE) -> 전임교원 | X29: =VLOOKUP(U29,[1]데이터시트!$B$3:$N$196,11,FALSE) -> 예비 | Y29: =VLOOKUP(U29,[1]데이터시트!$B$3:$N$196,6,FALSE) -> 대학발 | Z29: 20413968 | AA29: =VLOOKUP(Z29,[1]데이터시트!$B$3:$N$196,2,FALSE) -> 이승준 | AB29: =VLOOKUP(Z29,[1]데이터시트!$B$3:$N$196,4,FALSE) -> 0 | AC29: =VLOOKUP(Z29,[1]데이터시트!$B$3:$N$196,11,FALSE) -> 초기 | AD29: =VLOOKUP(Z29,[1]데이터시트!$B$3:$N$196,6,FALSE) -> 지역기반 | AE29: 20408877 | AF29: =VLOOKUP(AE29,[1]데이터시트!$B$3:$N$196,2,FALSE) -> 노형도 | AG29: =VLOOKUP(AE29,[1]데이터시트!$B$3:$N$196,4,FALSE) -> 0 | AH29: =VLOOKUP(AE29,[1]데이터시트!$B$3:$N$196,11,FALSE) -> 예비 | AI29: =VLOOKUP(AE29,[1]데이터시트!$B$3:$N$196,6,FALSE) -> 지역기반 | AJ29: 20415588 | AK29: =VLOOKUP(AJ29,[1]데이터시트!$B$3:$N$196,2,FALSE) -> 조성윤 | AL29: =VLOOKUP(AJ29,[1]데이터시트!$B$3:$N$196,4,FALSE) -> 0 | AM29: =VLOOKUP(AJ29,[1]데이터시트!$B$3:$N$196,11,FALSE) -> 초기 | AN29: =VLOOKUP(AJ29,[1]데이터시트!$B$3:$N$196,6,FALSE) -> 지역기반 | AO29: 20404581 | AP29: =VLOOKUP(AO29,[1]데이터시트!$B$3:$N$196,2,FALSE) -> 임세진 | AQ29: =VLOOKUP(AO29,[1]데이터시트!$B$3:$N$196,4,FALSE) -> 전임교원 | AR29: =VLOOKUP(AO29,[1]데이터시트!$B$3:$N$196,11,FALSE) -> 초기 | AS29: =VLOOKUP(AO29,[1]데이터시트!$B$3:$N$196,6,FALSE) -> 실험실 | AT29: 20414625 | AU29: =VLOOKUP(AT29,[1]데이터시트!$B$3:$N$196,2,FALSE) -> 김선진 | AV29: =VLOOKUP(AT29,[1]데이터시트!$B$3:$N$196,4,FALSE) -> 0 | AW29: =VLOOKUP(AT29,[1]데이터시트!$B$3:$N$196,11,FALSE) -> 예비 | AX29: =VLOOKUP(AT29,[1]데이터시트!$B$3:$N$196,6,FALSE) -> 지역기반 | AY29: 20432406 | AZ29: =VLOOKUP(AY29,[1]데이터시트!$B$3:$N$196,2,FALSE) -> 배성찬 | BA29: =VLOOKUP(AY29,[1]데이터시트!$B$3:$N$196,4,FALSE) -> 0 | BB29: =VLOOKUP(AY29,[1]데이터시트!$B$3:$N$196,11,FALSE) -> 도약 | BC29: =VLOOKUP(AY29,[1]데이터시트!$B$3:$N$196,6,FALSE) -> 대학발 | BD29: 20416188 | BE29: =VLOOKUP(BD29,[1]데이터시트!$B$3:$N$196,2,FALSE) -> 왕지혜 | BF29: =VLOOKUP(BD29,[1]데이터시트!$B$3:$N$196,4,FALSE) -> 0 | BG29: =VLOOKUP(BD29,[1]데이터시트!$B$3:$N$196,11,FALSE) -> 초기 | BH29: =VLOOKUP(BD29,[1]데이터시트!$B$3:$N$196,6,FALSE) -> 지역기반
A30: =SUBTOTAL(103,$B$29:B30) -> 2 | B30: 2일차 | C30: =D29+5 -> 1025 | D30: 1045 | E30: 20 | F30: 20431696 | G30: =VLOOKUP(F30,[1]데이터시트!$B$3:$N$196,2,FALSE) -> 박철환 | H30: =VLOOKUP(F30,[1]데이터시트!$B$3:$N$196,4,FALSE) -> 0 | I30: =VLOOKUP(F30,[1]데이터시트!$B$3:$N$196,11,FALSE) -> 초기 | J30: =VLOOKUP(F30,[1]데이터시트!$B$3:$N$196,6,FALSE) -> 지역기반 | K30: 20428259 | L30: =VLOOKUP(K30,[1]데이터시트!$B$3:$N$196,2,FALSE) -> 박민준 | M30: =VLOOKUP(K30,[1]데이터시트!$B$3:$N$196,4,FALSE) -> 0 | N30: =VLOOKUP(K30,[1]데이터시트!$B$3:$N$196,11,FALSE) -> 예비 | O30: =VLOOKUP(K32,[1]데이터시트!$B$3:$N$196,6,FALSE) -> 지역기반 | P30: 20428346 | Q30: =VLOOKUP(P30,[1]데이터시트!$B$3:$N$196,2,FALSE) -> 김태겸 | R30: =VLOOKUP(P30,[1]데이터시트!$B$3:$N$196,4,FALSE) -> 0 | S30: =VLOOKUP(P30,[1]데이터시트!$B$3:$N$196,11,FALSE) -> 도약 | T30: =VLOOKUP(P30,[1]데이터시트!$B$3:$N$196,6,FALSE) -> 지역기반 | U30: 20423461 | V30: =VLOOKUP(U30,[1]데이터시트!$B$3:$N$196,2,FALSE) -> 이은석 | W30: =VLOOKUP(U30,[1]데이터시트!$B$3:$N$196,4,FALSE) -> 전임교원 | X30: =VLOOKUP(U30,[1]데이터시트!$B$3:$N$196,11,FALSE) -> 예비 | Y30: =VLOOKUP(U30,[1]데이터시트!$B$3:$N$196,6,FALSE) -> 대학발 | Z30: 20430589 | AA30: =VLOOKUP(Z30,[1]데이터시트!$B$3:$N$196,2,FALSE) -> 윤대원 | AB30: =VLOOKUP(Z30,[1]데이터시트!$B$3:$N$196,4,FALSE) -> 0 | AC30: =VLOOKUP(Z30,[1]데이터시트!$B$3:$N$196,11,FALSE) -> 초기 | AD30: =VLOOKUP(Z30,[1]데이터시트!$B$3:$N$196,6,FALSE) -> 지역기반 | AE30: 20413111 | AF30: =VLOOKUP(AE30,[1]데이터시트!$B$3:$N$196,2,FALSE) -> 안지인 | AG30: =VLOOKUP(AE30,[1]데이터시트!$B$3:$N$196,4,FALSE) -> 0 | AH30: =VLOOKUP(AE30,[1]데이터시트!$B$3:$N$196,11,FALSE) -> 초기 | AI30: =VLOOKUP(AE30,[1]데이터시트!$B$3:$N$196,6,FALSE) -> 지역기반 | AJ30: 20417534 | AK30: =VLOOKUP(AJ30,[1]데이터시트!$B$3:$N$196,2,FALSE) -> 김이철 | AL30: =VLOOKUP(AJ30,[1]데이터시트!$B$3:$N$196,4,FALSE) -> 0 | AM30: =VLOOKUP(AJ30,[1]데이터시트!$B$3:$N$196,11,FALSE) -> 초기 | AN30: =VLOOKUP(AJ30,[1]데이터시트!$B$3:$N$196,6,FALSE) -> 지역기반 | AO30: 20404954 | AP30: =VLOOKUP(AO30,[1]데이터시트!$B$3:$N$196,2,FALSE) -> 이승민 | AQ30: =VLOOKUP(AO30,[1]데이터시트!$B$3:$N$196,4,FALSE) -> 0 | AR30: =VLOOKUP(AO30,[1]데이터시트!$B$3:$N$196,11,FALSE) -> 초기 | AS30: =VLOOKUP(AO30,[1]데이터시트!$B$3:$N$196,6,FALSE) -> 실험실 | AT30: 20414167 | AU30: =VLOOKUP(AT30,[1]데이터시트!$B$3:$N$196,2,FALSE) -> 손석봉 | AV30: =VLOOKUP(AT30,[1]데이터시트!$B$3:$N$196,4,FALSE) -> 0 | AW30: =VLOOKUP(AT30,[1]데이터시트!$B$3:$N$196,11,FALSE) -> 도약 | AX30: =VLOOKUP(AT30,[1]데이터시트!$B$3:$N$196,6,FALSE) -> 지역기반 | AY30: 20417599 | AZ30: =VLOOKUP(AY30,[1]데이터시트!$B$3:$N$196,2,FALSE) -> 김수전 | BA30: =VLOOKUP(AY30,[1]데이터시트!$B$3:$N$196,4,FALSE) -> 0 | BB30: =VLOOKUP(AY30,[1]데이터시트!$B$3:$N$196,11,FALSE) -> 초기 | BC30: =VLOOKUP(AY30,[1]데이터시트!$B$3:$N$196,6,FALSE) -> 실험실 | BD30: 20419372 | BE30: =VLOOKUP(BD30,[1]데이터시트!$B$3:$N$196,2,FALSE) -> 김태희 | BF30: =VLOOKUP(BD30,[1]데이터시트!$B$3:$N$196,4,FALSE) -> 0 | BG30: =VLOOKUP(BD30,[1]데이터시트!$B$3:$N$196,11,FALSE) -> 초기 | BH30: =VLOOKUP(BD30,[1]데이터시트!$B$3:$N$196,6,FALSE) -> 지역기반
A31: =SUBTOTAL(103,$B$29:B31) -> 3 | B31: 2일차 | C31: =D30+5 -> 1050 | D31: 1110 | E31: 20 | F31: 20415817 | G31: =VLOOKUP(F31,[1]데이터시트!$B$3:$N$196,2,FALSE) -> 조만희 | H31: =VLOOKUP(F31,[1]데이터시트!$B$3:$N$196,4,FALSE) -> 0 | I31: =VLOOKUP(F31,[1]데이터시트!$B$3:$N$196,11,FALSE) -> 초기 | J31: =VLOOKUP(F31,[1]데이터시트!$B$3:$N$196,6,FALSE) -> 지역기반 | K31: 20410732 | L31: =VLOOKUP(K31,[1]데이터시트!$B$3:$N$196,2,FALSE) -> 여혜은 | M31: =VLOOKUP(K31,[1]데이터시트!$B$3:$N$196,4,FALSE) -> 0 | N31: =VLOOKUP(K31,[1]데이터시트!$B$3:$N$196,11,FALSE) -> 초기 | O31: =VLOOKUP(K33,[1]데이터시트!$B$3:$N$196,6,FALSE) -> 지역기반 | P31: 20428037 | Q31: =VLOOKUP(P31,[1]데이터시트!$B$3:$N$196,2,FALSE) -> 이원형 | R31: =VLOOKUP(P31,[1]데이터시트!$B$3:$N$196,4,FALSE) -> 0 | S31: =VLOOKUP(P31,[1]데이터시트!$B$3:$N$196,11,FALSE) -> 초기 | T31: =VLOOKUP(P31,[1]데이터시트!$B$3:$N$196,6,FALSE) -> 지역기반 | U31: 20406455 | V31: =VLOOKUP(U31,[1]데이터시트!$B$3:$N$196,2,FALSE) -> 홍기증 | W31: =VLOOKUP(U31,[1]데이터시트!$B$3:$N$196,4,FALSE) -> 0 | X31: =VLOOKUP(U31,[1]데이터시트!$B$3:$N$196,11,FALSE) -> 예비 | Y31: =VLOOKUP(U31,[1]데이터시트!$B$3:$N$196,6,FALSE) -> 대학발 | Z31: 20425817 | AA31: =VLOOKUP(Z31,[1]데이터시트!$B$3:$N$196,2,FALSE) -> 이종근 | AB31: =VLOOKUP(Z31,[1]데이터시트!$B$3:$N$196,4,FALSE) -> 0 | AC31: =VLOOKUP(Z31,[1]데이터시트!$B$3:$N$196,11,FALSE) -> 초기 | AD31: =VLOOKUP(Z31,[1]데이터시트!$B$3:$N$196,6,FALSE) -> 지역기반 | AE31: 20413444 | AF31: =VLOOKUP(AE31,[1]데이터시트!$B$3:$N$196,2,FALSE) -> 박재민 | AG31: =VLOOKUP(AE31,[1]데이터시트!$B$3:$N$196,4,FALSE) -> 0 | AH31: =VLOOKUP(AE31,[1]데이터시트!$B$3:$N$196,11,FALSE) -> 초기 | AI31: =VLOOKUP(AE31,[1]데이터시트!$B$3:$N$196,6,FALSE) -> 지역기반 | AJ31: 20415851 | AK31: =VLOOKUP(AJ31,[1]데이터시트!$B$3:$N$196,2,FALSE) -> 김지원 | AL31: =VLOOKUP(AJ31,[1]데이터시트!$B$3:$N$196,4,FALSE) -> 0 | AM31: =VLOOKUP(AJ31,[1]데이터시트!$B$3:$N$196,11,FALSE) -> 초기 | AN31: =VLOOKUP(AJ31,[1]데이터시트!$B$3:$N$196,6,FALSE) -> 지역기반 | AO31: 20412385 | AP31: =VLOOKUP(AO31,[1]데이터시트!$B$3:$N$196,2,FALSE) -> 엄선우 | AQ31: =VLOOKUP(AO31,[1]데이터시트!$B$3:$N$196,4,FALSE) -> 0 | AR31: =VLOOKUP(AO31,[1]데이터시트!$B$3:$N$196,11,FALSE) -> 초기 | AS31: =VLOOKUP(AO31,[1]데이터시트!$B$3:$N$196,6,FALSE) -> 실험실 | AT31: 20410202 | AU31: =VLOOKUP(AT31,[1]데이터시트!$B$3:$N$196,2,FALSE) -> 김준 | AV31: =VLOOKUP(AT31,[1]데이터시트!$B$3:$N$196,4,FALSE) -> 0 | AW31: =VLOOKUP(AT31,[1]데이터시트!$B$3:$N$196,11,FALSE) -> 도약 | AX31: =VLOOKUP(AT31,[1]데이터시트!$B$3:$N$196,6,FALSE) -> 지역기반 | AY31: 20403842 | AZ31: =VLOOKUP(AY31,[1]데이터시트!$B$3:$N$196,2,FALSE) -> 조나라 | BA31: =VLOOKUP(AY31,[1]데이터시트!$B$3:$N$196,4,FALSE) -> 0 | BB31: =VLOOKUP(AY31,[1]데이터시트!$B$3:$N$196,11,FALSE) -> 예비 | BC31: =VLOOKUP(AY31,[1]데이터시트!$B$3:$N$196,6,FALSE) -> 지역기반 | BD31: 20419388 | BE31: =VLOOKUP(BD31,[1]데이터시트!$B$3:$N$196,2,FALSE) -> 이명진 | BF31: =VLOOKUP(BD31,[1]데이터시트!$B$3:$N$196,4,FALSE) -> 0 | BG31: =VLOOKUP(BD31,[1]데이터시트!$B$3:$N$196,11,FALSE) -> 초기 | BH31: =VLOOKUP(BD31,[1]데이터시트!$B$3:$N$196,6,FALSE) -> 지역기반
A32: =SUBTOTAL(103,$B$29:B32) -> 4 | B32: 2일차 | C32: =D31+5 -> 1115 | D32: 1135 | E32: 20 | F32: 20421734 | G32: =VLOOKUP(F32,[1]데이터시트!$B$3:$N$196,2,FALSE) -> 이영주 | H32: =VLOOKUP(F32,[1]데이터시트!$B$3:$N$196,4,FALSE) -> 전임교원 | I32: =VLOOKUP(F32,[1]데이터시트!$B$3:$N$196,11,FALSE) -> 초기 | J32: =VLOOKUP(F32,[1]데이터시트!$B$3:$N$196,6,FALSE) -> 지역기반 | K32: 20419317 | L32: =VLOOKUP(K32,[1]데이터시트!$B$3:$N$196,2,FALSE) -> 조효정 | M32: =VLOOKUP(K32,[1]데이터시트!$B$3:$N$196,4,FALSE) -> 0 | N32: =VLOOKUP(K32,[1]데이터시트!$B$3:$N$196,11,FALSE) -> 초기 | O32: =VLOOKUP(K35,[1]데이터시트!$B$3:$N$196,6,FALSE) -> 지역기반 | P32: 20409229 | Q32: =VLOOKUP(P32,[1]데이터시트!$B$3:$N$196,2,FALSE) -> 박준호 | R32: =VLOOKUP(P32,[1]데이터시트!$B$3:$N$196,4,FALSE) -> 창업기업미해당 | S32: =VLOOKUP(P32,[1]데이터시트!$B$3:$N$196,11,FALSE) -> 0 | T32: =VLOOKUP(P32,[1]데이터시트!$B$3:$N$196,6,FALSE) -> 0 | U32: 20423136 | V32: =VLOOKUP(U32,[1]데이터시트!$B$3:$N$196,2,FALSE) -> 민무홍 | W32: =VLOOKUP(U32,[1]데이터시트!$B$3:$N$196,4,FALSE) -> 전임교원 | X32: =VLOOKUP(U32,[1]데이터시트!$B$3:$N$196,11,FALSE) -> 예비 | Y32: =VLOOKUP(U32,[1]데이터시트!$B$3:$N$196,6,FALSE) -> 대학발 | Z32: 20428574 | AA32: =VLOOKUP(Z32,[1]데이터시트!$B$3:$N$196,2,FALSE) -> 최승천 | AB32: =VLOOKUP(Z32,[1]데이터시트!$B$3:$N$196,4,FALSE) -> 0 | AC32: =VLOOKUP(Z32,[1]데이터시트!$B$3:$N$196,11,FALSE) -> 초기 | AD32: =VLOOKUP(Z32,[1]데이터시트!$B$3:$N$196,6,FALSE) -> 지역기반 | AE32: 20422710 | AF32: =VLOOKUP(AE32,[1]데이터시트!$B$3:$N$196,2,FALSE) -> 유봉현 | AG32: =VLOOKUP(AE32,[1]데이터시트!$B$3:$N$196,4,FALSE) -> 0 | AH32: =VLOOKUP(AE32,[1]데이터시트!$B$3:$N$196,11,FALSE) -> 초기 | AI32: =VLOOKUP(AE32,[1]데이터시트!$B$3:$N$196,6,FALSE) -> 지역기반 | AJ32: 20428457 | AK32: =VLOOKUP(AJ32,[1]데이터시트!$B$3:$N$196,2,FALSE) -> 김민수 | AL32: =VLOOKUP(AJ32,[1]데이터시트!$B$3:$N$196,4,FALSE) -> 0 | AM32: =VLOOKUP(AJ32,[1]데이터시트!$B$3:$N$196,11,FALSE) -> 초기 | AN32: =VLOOKUP(AJ32,[1]데이터시트!$B$3:$N$196,6,FALSE) -> 지역기반 | AO32: 20413825 | AP32: =VLOOKUP(AO32,[1]데이터시트!$B$3:$N$196,2,FALSE) -> 노상용 | AQ32: =VLOOKUP(AO32,[1]데이터시트!$B$3:$N$196,4,FALSE) -> 0 | AR32: =VLOOKUP(AO32,[1]데이터시트!$B$3:$N$196,11,FALSE) -> 초기 | AS32: =VLOOKUP(AO32,[1]데이터시트!$B$3:$N$196,6,FALSE) -> 실험실 | AT32: 20401269 | AU32: =VLOOKUP(AT32,[1]데이터시트!$B$3:$N$196,2,FALSE) -> 윤수정 | AV32: =VLOOKUP(AT32,[1]데이터시트!$B$3:$N$196,4,FALSE) -> 0 | AW32: =VLOOKUP(AT32,[1]데이터시트!$B$3:$N$196,11,FALSE) -> 초기 | AX32: =VLOOKUP(AT32,[1]데이터시트!$B$3:$N$196,6,FALSE) -> 지역기반 | AY32: 20439414 | AZ32: =VLOOKUP(AY32,[1]데이터시트!$B$3:$N$196,2,FALSE) -> 송인우 | BA32: =VLOOKUP(AY32,[1]데이터시트!$B$3:$N$196,4,FALSE) -> 0 | BB32: =VLOOKUP(AY32,[1]데이터시트!$B$3:$N$196,11,FALSE) -> 예비 | BC32: =VLOOKUP(AY32,[1]데이터시트!$B$3:$N$196,6,FALSE) -> 지역기반 | BD32: 20424483 | BE32: =VLOOKUP(BD32,[1]데이터시트!$B$3:$N$196,2,FALSE) -> 윤태균 | BF32: =VLOOKUP(BD32,[1]데이터시트!$B$3:$N$196,4,FALSE) -> 투자파트발굴 | BG32: =VLOOKUP(BD32,[1]데이터시트!$B$3:$N$196,11,FALSE) -> 초기 | BH32: =VLOOKUP(BD32,[1]데이터시트!$B$3:$N$196,6,FALSE) -> 지역기반
A33: =SUBTOTAL(103,$B$29:B33) -> 5 | B33: 2일차 | C33: =D32+5 -> 1140 | D33: 1200 | E33: 20 | F33: 20428934 | G33: =VLOOKUP(F33,[1]데이터시트!$B$3:$N$196,2,FALSE) -> 이원택 | H33: =VLOOKUP(F33,[1]데이터시트!$B$3:$N$196,4,FALSE) -> 0 | I33: =VLOOKUP(F33,[1]데이터시트!$B$3:$N$196,11,FALSE) -> 초기 | J33: =VLOOKUP(F33,[1]데이터시트!$B$3:$N$196,6,FALSE) -> 지역기반 | K33: 20427103 | L33: =VLOOKUP(K33,[1]데이터시트!$B$3:$N$196,2,FALSE) -> 이창욱 | M33: =VLOOKUP(K33,[1]데이터시트!$B$3:$N$196,4,FALSE) -> 0 | N33: =VLOOKUP(K33,[1]데이터시트!$B$3:$N$196,11,FALSE) -> 초기 | O33: =VLOOKUP(K36,[1]데이터시트!$B$3:$N$196,6,FALSE) -> 지역기반 | P33: 20412024 | Q33: =VLOOKUP(P33,[1]데이터시트!$B$3:$N$196,2,FALSE) -> 민선화 | R33: =VLOOKUP(P33,[1]데이터시트!$B$3:$N$196,4,FALSE) -> 0 | S33: =VLOOKUP(P33,[1]데이터시트!$B$3:$N$196,11,FALSE) -> 초기 | T33: =VLOOKUP(P33,[1]데이터시트!$B$3:$N$196,6,FALSE) -> 지역기반 | U33: 20415837 | V33: =VLOOKUP(U33,[1]데이터시트!$B$3:$N$196,2,FALSE) -> 노건준 | W33: =VLOOKUP(U33,[1]데이터시트!$B$3:$N$196,4,FALSE) -> 잠재력 확인 팀 | X33: =VLOOKUP(U33,[1]데이터시트!$B$3:$N$196,11,FALSE) -> 예비 | Y33: =VLOOKUP(U33,[1]데이터시트!$B$3:$N$196,6,FALSE) -> 대학발 | Z33: 20429923 | AA33: =VLOOKUP(Z33,[1]데이터시트!$B$3:$N$196,2,FALSE) -> 고현웅 | AB33: =VLOOKUP(Z33,[1]데이터시트!$B$3:$N$196,4,FALSE) -> 투자파트발굴/교원 | AC33: =VLOOKUP(Z33,[1]데이터시트!$B$3:$N$196,11,FALSE) -> 도약 | AD33: =VLOOKUP(Z33,[1]데이터시트!$B$3:$N$196,6,FALSE) -> 지역기반 | AE33: 20427563 | AF33: =VLOOKUP(AE33,[1]데이터시트!$B$3:$N$196,2,FALSE) -> 김성욱 | AG33: =VLOOKUP(AE33,[1]데이터시트!$B$3:$N$196,4,FALSE) -> 0 | AH33: =VLOOKUP(AE33,[1]데이터시트!$B$3:$N$196,11,FALSE) -> 초기 | AI33: =VLOOKUP(AE33,[1]데이터시트!$B$3:$N$196,6,FALSE) -> 지역기반 | AJ33: 20429088 | AK33: =VLOOKUP(AJ33,[1]데이터시트!$B$3:$N$196,2,FALSE) -> 김용완 | AL33: =VLOOKUP(AJ33,[1]데이터시트!$B$3:$N$196,4,FALSE) -> 0 | AM33: =VLOOKUP(AJ33,[1]데이터시트!$B$3:$N$196,11,FALSE) -> 초기 | AN33: =VLOOKUP(AJ33,[1]데이터시트!$B$3:$N$196,6,FALSE) -> 지역기반 | AO33: 20417675 | AP33: =VLOOKUP(AO33,[1]데이터시트!$B$3:$N$196,2,FALSE) -> 박한규 | AQ33: =VLOOKUP(AO33,[1]데이터시트!$B$3:$N$196,4,FALSE) -> 전임교원 | AR33: =VLOOKUP(AO33,[1]데이터시트!$B$3:$N$196,11,FALSE) -> 초기 | AS33: =VLOOKUP(AO33,[1]데이터시트!$B$3:$N$196,6,FALSE) -> 실험실 | AT33: 20416443 | AU33: =VLOOKUP(AT33,[1]데이터시트!$B$3:$N$196,2,FALSE) -> 김성진 | AV33: =VLOOKUP(AT33,[1]데이터시트!$B$3:$N$196,4,FALSE) -> 0 | AW33: =VLOOKUP(AT33,[1]데이터시트!$B$3:$N$196,11,FALSE) -> 초기 | AX33: =VLOOKUP(AT33,[1]데이터시트!$B$3:$N$196,6,FALSE) -> 지역기반 | AY33: 20428829 | AZ33: =VLOOKUP(AY33,[1]데이터시트!$B$3:$N$196,2,FALSE) -> 이건희 | BA33: =VLOOKUP(AY33,[1]데이터시트!$B$3:$N$196,4,FALSE) -> 0 | BB33: =VLOOKUP(AY33,[1]데이터시트!$B$3:$N$196,11,FALSE) -> 초기 | BC33: =VLOOKUP(AY33,[1]데이터시트!$B$3:$N$196,6,FALSE) -> 지역기반 | BD33: 20427515 | BE33: =VLOOKUP(BD33,[1]데이터시트!$B$3:$N$196,2,FALSE) -> 정우재 | BF33: =VLOOKUP(BD33,[1]데이터시트!$B$3:$N$196,4,FALSE) -> 0 | BG33: =VLOOKUP(BD33,[1]데이터시트!$B$3:$N$196,11,FALSE) -> 초기 | BH33: =VLOOKUP(BD33,[1]데이터시트!$B$3:$N$196,6,FALSE) -> 지역기반
C34: 1200 | D34: 1300 | E34: 60 | F34: 점심
A35: =SUBTOTAL(103,$B$29:B35) -> 6 | B35: 2일차 | C35: 1300 | D35: 1320 | E35: 20 | F35: 20409931 | G35: =VLOOKUP(F35,[1]데이터시트!$B$3:$N$196,2,FALSE) -> 김서진 | H35: =VLOOKUP(F35,[1]데이터시트!$B$3:$N$196,4,FALSE) -> 0 | I35: =VLOOKUP(F35,[1]데이터시트!$B$3:$N$196,11,FALSE) -> 도약 | J35: =VLOOKUP(F35,[1]데이터시트!$B$3:$N$196,6,FALSE) -> 지역기반 | K35: 20417694 | L35: =VLOOKUP(K35,[1]데이터시트!$B$3:$N$196,2,FALSE) -> 홍태균 | M35: =VLOOKUP(K35,[1]데이터시트!$B$3:$N$196,4,FALSE) -> 0 | N35: =VLOOKUP(K35,[1]데이터시트!$B$3:$N$196,11,FALSE) -> 초기 | O35: =VLOOKUP(K29,[1]데이터시트!$B$3:$N$196,6,FALSE) -> 지역기반 | P35: 20414899 | Q35: =VLOOKUP(P35,[1]데이터시트!$B$3:$N$196,2,FALSE) -> 김정훈 | R35: =VLOOKUP(P35,[1]데이터시트!$B$3:$N$196,4,FALSE) -> 잠재력 확인 팀 | S35: =VLOOKUP(P35,[1]데이터시트!$B$3:$N$196,11,FALSE) -> 초기 | T35: =VLOOKUP(P35,[1]데이터시트!$B$3:$N$196,6,FALSE) -> 지역기반 | AE35: 20428661 | AF35: =VLOOKUP(AE35,[1]데이터시트!$B$3:$N$196,2,FALSE) -> 이준영 | AG35: =VLOOKUP(AE35,[1]데이터시트!$B$3:$N$196,4,FALSE) -> 0 | AH35: =VLOOKUP(AE35,[1]데이터시트!$B$3:$N$196,11,FALSE) -> 초기 | AI35: =VLOOKUP(AE35,[1]데이터시트!$B$3:$N$196,6,FALSE) -> 지역기반 | AT35: 20424839 | AU35: =VLOOKUP(AT35,[1]데이터시트!$B$3:$N$196,2,FALSE) -> 이경원 | AV35: =VLOOKUP(AT35,[1]데이터시트!$B$3:$N$196,4,FALSE) -> 0 | AW35: =VLOOKUP(AT35,[1]데이터시트!$B$3:$N$196,11,FALSE) -> 초기 | AX35: =VLOOKUP(AT35,[1]데이터시트!$B$3:$N$196,6,FALSE) -> 지역기반 | AY35: 20418464 | AZ35: =VLOOKUP(AY35,[1]데이터시트!$B$3:$N$196,2,FALSE) -> 이창하 | BA35: =VLOOKUP(AY35,[1]데이터시트!$B$3:$N$196,4,FALSE) -> 0 | BB35: =VLOOKUP(AY35,[1]데이터시트!$B$3:$N$196,11,FALSE) -> 초기 | BC35: =VLOOKUP(AY35,[1]데이터시트!$B$3:$N$196,6,FALSE) -> 지역기반
A36: =SUBTOTAL(103,$B$29:B36) -> 7 | B36: 2일차 | C36: =D35+5 -> 1325 | D36: 1345 | E36: 20 | F36: 20431043 | G36: =VLOOKUP(F36,[1]데이터시트!$B$3:$N$196,2,FALSE) -> 유병기 | H36: =VLOOKUP(F36,[1]데이터시트!$B$3:$N$196,4,FALSE) -> 0 | I36: =VLOOKUP(F36,[1]데이터시트!$B$3:$N$196,11,FALSE) -> 도약 | J36: =VLOOKUP(F36,[1]데이터시트!$B$3:$N$196,6,FALSE) -> 지역기반 | K36: 20418822 | L36: =VLOOKUP(K36,[1]데이터시트!$B$3:$N$196,2,FALSE) -> 이종민 | M36: =VLOOKUP(K36,[1]데이터시트!$B$3:$N$196,4,FALSE) -> 0 | N36: =VLOOKUP(K36,[1]데이터시트!$B$3:$N$196,11,FALSE) -> 초기 | O36: =VLOOKUP(K30,[1]데이터시트!$B$3:$N$196,6,FALSE) -> 지역기반 | P36: 20428312 | Q36: =VLOOKUP(P36,[1]데이터시트!$B$3:$N$196,2,FALSE) -> 최의순 | R36: =VLOOKUP(P36,[1]데이터시트!$B$3:$N$196,4,FALSE) -> 0 | S36: =VLOOKUP(P36,[1]데이터시트!$B$3:$N$196,11,FALSE) -> 초기 | T36: =VLOOKUP(P36,[1]데이터시트!$B$3:$N$196,6,FALSE) -> 지역기반 | Z36: 20430098 | AA36: =VLOOKUP(Z36,[1]데이터시트!$B$3:$N$196,2,FALSE) -> 김민중 | AB36: =VLOOKUP(Z36,[1]데이터시트!$B$3:$N$196,4,FALSE) -> 0 | AC36: =VLOOKUP(Z36,[1]데이터시트!$B$3:$N$196,11,FALSE) -> 도약 | AD36: =VLOOKUP(Z36,[1]데이터시트!$B$3:$N$196,6,FALSE) -> 지역기반 | AE36: 20431761 | AF36: =VLOOKUP(AE36,[1]데이터시트!$B$3:$N$196,2,FALSE) -> 김범수 | AG36: =VLOOKUP(AE36,[1]데이터시트!$B$3:$N$196,4,FALSE) -> 0 | AH36: =VLOOKUP(AE36,[1]데이터시트!$B$3:$N$196,11,FALSE) -> 초기 | AI36: =VLOOKUP(AE36,[1]데이터시트!$B$3:$N$196,6,FALSE) -> 지역기반 | AJ36: 20428133 | AK36: =VLOOKUP(AJ36,[1]데이터시트!$B$3:$N$196,2,FALSE) -> 배주모 | AL36: =VLOOKUP(AJ36,[1]데이터시트!$B$3:$N$196,4,FALSE) -> 0 | AM36: =VLOOKUP(AJ36,[1]데이터시트!$B$3:$N$196,11,FALSE) -> 도약 | AN36: =VLOOKUP(AJ36,[1]데이터시트!$B$3:$N$196,6,FALSE) -> 지역기반 | AO36: 20420569 | AP36: =VLOOKUP(AO36,[1]데이터시트!$B$3:$N$196,2,FALSE) -> 김영길 | AQ36: =VLOOKUP(AO36,[1]데이터시트!$B$3:$N$196,4,FALSE) -> 0 | AR36: =VLOOKUP(AO36,[1]데이터시트!$B$3:$N$196,11,FALSE) -> 초기 | AS36: =VLOOKUP(AO36,[1]데이터시트!$B$3:$N$196,6,FALSE) -> 실험실 | AT36: 20428258 | AU36: =VLOOKUP(AT36,[1]데이터시트!$B$3:$N$196,2,FALSE) -> 이정현 | AV36: =VLOOKUP(AT36,[1]데이터시트!$B$3:$N$196,4,FALSE) -> 0 | AW36: =VLOOKUP(AT36,[1]데이터시트!$B$3:$N$196,11,FALSE) -> 초기 | AX36: =VLOOKUP(AT36,[1]데이터시트!$B$3:$N$196,6,FALSE) -> 지역기반 | AY36: 20426658 | AZ36: =VLOOKUP(AY36,[1]데이터시트!$B$3:$N$196,2,FALSE) -> 최해란 | BA36: =VLOOKUP(AY36,[1]데이터시트!$B$3:$N$196,4,FALSE) -> 0 | BB36: =VLOOKUP(AY36,[1]데이터시트!$B$3:$N$196,11,FALSE) -> 초기 | BC36: =VLOOKUP(AY36,[1]데이터시트!$B$3:$N$196,6,FALSE) -> 지역기반
A37: =SUBTOTAL(103,$B$29:B37) -> 8 | B37: 2일차 | C37: =D36+5 -> 1350 | D37: 1410 | E37: 20 | F37: 20416947 | G37: =VLOOKUP(F37,[1]데이터시트!$B$3:$N$196,2,FALSE) -> 김민상 | H37: =VLOOKUP(F37,[1]데이터시트!$B$3:$N$196,4,FALSE) -> 0 | I37: =VLOOKUP(F37,[1]데이터시트!$B$3:$N$196,11,FALSE) -> 도약 | J37: =VLOOKUP(F37,[1]데이터시트!$B$3:$N$196,6,FALSE) -> 지역기반 | K37: 20415506 | L37: =VLOOKUP(K37,[1]데이터시트!$B$3:$N$196,2,FALSE) -> 남수정 | M37: =VLOOKUP(K37,[1]데이터시트!$B$3:$N$196,4,FALSE) -> 0 | N37: =VLOOKUP(K37,[1]데이터시트!$B$3:$N$196,11,FALSE) -> 도약 | O37: =VLOOKUP(K37,[1]데이터시트!$B$3:$N$196,6,FALSE) -> 지역기반 | P37: 20424540 | Q37: =VLOOKUP(P37,[1]데이터시트!$B$3:$N$196,2,FALSE) -> 배기쁨 | R37: =VLOOKUP(P37,[1]데이터시트!$B$3:$N$196,4,FALSE) -> 0 | S37: =VLOOKUP(P37,[1]데이터시트!$B$3:$N$196,11,FALSE) -> 초기 | T37: =VLOOKUP(P37,[1]데이터시트!$B$3:$N$196,6,FALSE) -> 지역기반 | Z37: 20426937 | AA37: =VLOOKUP(Z37,[1]데이터시트!$B$3:$N$196,2,FALSE) -> 이성수 | AB37: =VLOOKUP(Z37,[1]데이터시트!$B$3:$N$196,4,FALSE) -> 0 | AC37: =VLOOKUP(Z37,[1]데이터시트!$B$3:$N$196,11,FALSE) -> 도약 | AD37: =VLOOKUP(Z37,[1]데이터시트!$B$3:$N$196,6,FALSE) -> 지역기반 | AE37: 20417238 | AF37: =VLOOKUP(AE37,[1]데이터시트!$B$3:$N$196,2,FALSE) -> 서동석 | AG37: =VLOOKUP(AE37,[1]데이터시트!$B$3:$N$196,4,FALSE) -> 0 | AH37: =VLOOKUP(AE37,[1]데이터시트!$B$3:$N$196,11,FALSE) -> 초기 | AI37: =VLOOKUP(AE37,[1]데이터시트!$B$3:$N$196,6,FALSE) -> 실험실 | AJ37: 20432254 | AK37: =VLOOKUP(AJ37,[1]데이터시트!$B$3:$N$196,2,FALSE) -> 정재준 | AL37: =VLOOKUP(AJ37,[1]데이터시트!$B$3:$N$196,4,FALSE) -> 0 | AM37: =VLOOKUP(AJ37,[1]데이터시트!$B$3:$N$196,11,FALSE) -> 도약 | AN37: =VLOOKUP(AJ37,[1]데이터시트!$B$3:$N$196,6,FALSE) -> 지역기반 | AO37: 20419189 | AP37: =VLOOKUP(AO37,[1]데이터시트!$B$3:$N$196,2,FALSE) -> 권오석 | AQ37: =VLOOKUP(AO37,[1]데이터시트!$B$3:$N$196,4,FALSE) -> 전임교원 | AR37: =VLOOKUP(AO37,[1]데이터시트!$B$3:$N$196,11,FALSE) -> 초기 | AS37: =VLOOKUP(AO37,[1]데이터시트!$B$3:$N$196,6,FALSE) -> 실험실 | AT37: 20415499 | AU37: =VLOOKUP(AT37,[1]데이터시트!$B$3:$N$196,2,FALSE) -> 정진우 | AV37: =VLOOKUP(AT37,[1]데이터시트!$B$3:$N$196,4,FALSE) -> 0 | AW37: =VLOOKUP(AT37,[1]데이터시트!$B$3:$N$196,11,FALSE) -> 초기 | AX37: =VLOOKUP(AT37,[1]데이터시트!$B$3:$N$196,6,FALSE) -> 지역기반 | AY37: 20413666 | AZ37: =VLOOKUP(AY37,[1]데이터시트!$B$3:$N$196,2,FALSE) -> 김정현 | BA37: =VLOOKUP(AY37,[1]데이터시트!$B$3:$N$196,4,FALSE) -> 0 | BB37: =VLOOKUP(AY37,[1]데이터시트!$B$3:$N$196,11,FALSE) -> 초기 | BC37: =VLOOKUP(AY37,[1]데이터시트!$B$3:$N$196,6,FALSE) -> 지역기반 | BD37: 20416542 | BE37: =VLOOKUP(BD37,[1]데이터시트!$B$3:$N$196,2,FALSE) -> 박기호 | BF37: =VLOOKUP(BD37,[1]데이터시트!$B$3:$N$196,4,FALSE) -> 0 | BG37: =VLOOKUP(BD37,[1]데이터시트!$B$3:$N$196,11,FALSE) -> 도약 | BH37: =VLOOKUP(BD37,[1]데이터시트!$B$3:$N$196,6,FALSE) -> 지역기반
A38: =SUBTOTAL(103,$B$29:B38) -> 9 | B38: 2일차 | C38: =D37+5 -> 1415 | D38: 1435 | E38: 20 | F38: 20415487 | G38: =VLOOKUP(F38,[1]데이터시트!$B$3:$N$196,2,FALSE) -> 김용민 | H38: =VLOOKUP(F38,[1]데이터시트!$B$3:$N$196,4,FALSE) -> 0 | I38: =VLOOKUP(F38,[1]데이터시트!$B$3:$N$196,11,FALSE) -> 도약 | J38: =VLOOKUP(F38,[1]데이터시트!$B$3:$N$196,6,FALSE) -> 지역기반 | K38: 20431875 | L38: =VLOOKUP(K38,[1]데이터시트!$B$3:$N$196,2,FALSE) -> 강지현 | M38: =VLOOKUP(K38,[1]데이터시트!$B$3:$N$196,4,FALSE) -> 0 | N38: =VLOOKUP(K38,[1]데이터시트!$B$3:$N$196,11,FALSE) -> 도약 | O38: =VLOOKUP(K38,[1]데이터시트!$B$3:$N$196,6,FALSE) -> 지역기반 | P38: 20419192 | Q38: =VLOOKUP(P38,[1]데이터시트!$B$3:$N$196,2,FALSE) -> 박주연 | R38: =VLOOKUP(P38,[1]데이터시트!$B$3:$N$196,4,FALSE) -> 0 | S38: =VLOOKUP(P38,[1]데이터시트!$B$3:$N$196,11,FALSE) -> 초기 | T38: =VLOOKUP(P38,[1]데이터시트!$B$3:$N$196,6,FALSE) -> 실험실 | U38: 20403700 | V38: =VLOOKUP(U38,[1]데이터시트!$B$3:$N$196,2,FALSE) -> 강연구 | W38: =VLOOKUP(U38,[1]데이터시트!$B$3:$N$196,4,FALSE) -> 0 | X38: =VLOOKUP(U38,[1]데이터시트!$B$3:$N$196,11,FALSE) -> 초기 | Y38: =VLOOKUP(U38,[1]데이터시트!$B$3:$N$196,6,FALSE) -> 대학발 | Z38: 20418623 | AA38: =VLOOKUP(Z38,[1]데이터시트!$B$3:$N$196,2,FALSE) -> 이성욱 | AB38: =VLOOKUP(Z38,[1]데이터시트!$B$3:$N$196,4,FALSE) -> 0 | AC38: =VLOOKUP(Z38,[1]데이터시트!$B$3:$N$196,11,FALSE) -> 초기 | AD38: =VLOOKUP(Z38,[1]데이터시트!$B$3:$N$196,6,FALSE) -> 실험실 | AE38: 20417596 | AF38: =VLOOKUP(AE38,[1]데이터시트!$B$3:$N$196,2,FALSE) -> 전일 | AG38: =VLOOKUP(AE38,[1]데이터시트!$B$3:$N$196,4,FALSE) -> 전임교원 | AH38: =VLOOKUP(AE38,[1]데이터시트!$B$3:$N$196,11,FALSE) -> 초기 | AI38: =VLOOKUP(AE38,[1]데이터시트!$B$3:$N$196,6,FALSE) -> 대학발 | AJ38: 20415849 | AK38: =VLOOKUP(AJ38,[1]데이터시트!$B$3:$N$196,2,FALSE) -> 서상수 | AL38: =VLOOKUP(AJ38,[1]데이터시트!$B$3:$N$196,4,FALSE) -> 0 | AM38: =VLOOKUP(AJ38,[1]데이터시트!$B$3:$N$196,11,FALSE) -> 도약 | AN38: =VLOOKUP(AJ38,[1]데이터시트!$B$3:$N$196,6,FALSE) -> 지역기반 | AO38: 20421952 | AP38: =VLOOKUP(AO38,[1]데이터시트!$B$3:$N$196,2,FALSE) -> 박진형 | AQ38: =VLOOKUP(AO38,[1]데이터시트!$B$3:$N$196,4,FALSE) -> 전임교원 | AR38: =VLOOKUP(AO38,[1]데이터시트!$B$3:$N$196,11,FALSE) -> 초기 | AS38: =VLOOKUP(AO38,[1]데이터시트!$B$3:$N$196,6,FALSE) -> 실험실 | AT38: 20426411 | AU38: =VLOOKUP(AT38,[1]데이터시트!$B$3:$N$196,2,FALSE) -> 봉민균 | AV38: =VLOOKUP(AT38,[1]데이터시트!$B$3:$N$196,4,FALSE) -> 0 | AW38: =VLOOKUP(AT38,[1]데이터시트!$B$3:$N$196,11,FALSE) -> 초기 | AX38: =VLOOKUP(AT38,[1]데이터시트!$B$3:$N$196,6,FALSE) -> 지역기반 | AY38: 20404406 | AZ38: =VLOOKUP(AY38,[1]데이터시트!$B$3:$N$196,2,FALSE) -> 김진혁 | BA38: =VLOOKUP(AY38,[1]데이터시트!$B$3:$N$196,4,FALSE) -> 0 | BB38: =VLOOKUP(AY38,[1]데이터시트!$B$3:$N$196,11,FALSE) -> 도약 | BC38: =VLOOKUP(AY38,[1]데이터시트!$B$3:$N$196,6,FALSE) -> 지역기반 | BD38: 20419206 | BE38: =VLOOKUP(BD38,[1]데이터시트!$B$3:$N$196,2,FALSE) -> 민경국 | BF38: =VLOOKUP(BD38,[1]데이터시트!$B$3:$N$196,4,FALSE) -> 0 | BG38: =VLOOKUP(BD38,[1]데이터시트!$B$3:$N$196,11,FALSE) -> 도약 | BH38: =VLOOKUP(BD38,[1]데이터시트!$B$3:$N$196,6,FALSE) -> 지역기반
A39: =SUBTOTAL(103,$B$29:B39) -> 10 | B39: 2일차 | C39: =D38+5 -> 1440 | D39: 1500 | E39: 20 | F39: 20417617 | G39: =VLOOKUP(F39,[1]데이터시트!$B$3:$N$196,2,FALSE) -> 서진원 | H39: =VLOOKUP(F39,[1]데이터시트!$B$3:$N$196,4,FALSE) -> 0 | I39: =VLOOKUP(F39,[1]데이터시트!$B$3:$N$196,11,FALSE) -> 도약 | J39: =VLOOKUP(F39,[1]데이터시트!$B$3:$N$196,6,FALSE) -> 지역기반 | K39: 20415870 | L39: =VLOOKUP(K39,[1]데이터시트!$B$3:$N$196,2,FALSE) -> 이민규 | M39: =VLOOKUP(K39,[1]데이터시트!$B$3:$N$196,4,FALSE) -> 0 | N39: =VLOOKUP(K39,[1]데이터시트!$B$3:$N$196,11,FALSE) -> 도약 | O39: =VLOOKUP(K39,[1]데이터시트!$B$3:$N$196,6,FALSE) -> 지역기반 | P39: 20417697 | Q39: =VLOOKUP(P39,[1]데이터시트!$B$3:$N$196,2,FALSE) -> 신완선 | R39: =VLOOKUP(P39,[1]데이터시트!$B$3:$N$196,4,FALSE) -> 전임교원 | S39: =VLOOKUP(P39,[1]데이터시트!$B$3:$N$196,11,FALSE) -> 초기 | T39: =VLOOKUP(P39,[1]데이터시트!$B$3:$N$196,6,FALSE) -> 실험실 | U39: 20427590 | V39: =VLOOKUP(U39,[1]데이터시트!$B$3:$N$196,2,FALSE) -> 한진영 | W39: =VLOOKUP(U39,[1]데이터시트!$B$3:$N$196,4,FALSE) -> 전임교원 | X39: =VLOOKUP(U39,[1]데이터시트!$B$3:$N$196,11,FALSE) -> 초기 | Y39: =VLOOKUP(U39,[1]데이터시트!$B$3:$N$196,6,FALSE) -> 대학발 | Z39: 20419110 | AA39: =VLOOKUP(Z39,[1]데이터시트!$B$3:$N$196,2,FALSE) -> 서준호 | AB39: =VLOOKUP(Z39,[1]데이터시트!$B$3:$N$196,4,FALSE) -> 0 | AC39: =VLOOKUP(Z39,[1]데이터시트!$B$3:$N$196,11,FALSE) -> 초기 | AD39: =VLOOKUP(Z39,[1]데이터시트!$B$3:$N$196,6,FALSE) -> 실험실 | AE39: 20427490 | AF39: =VLOOKUP(AE39,[1]데이터시트!$B$3:$N$196,2,FALSE) -> 전정배 | AG39: =VLOOKUP(AE39,[1]데이터시트!$B$3:$N$196,4,FALSE) -> 0 | AH39: =VLOOKUP(AE39,[1]데이터시트!$B$3:$N$196,11,FALSE) -> 초기 | AI39: =VLOOKUP(AE39,[1]데이터시트!$B$3:$N$196,6,FALSE) -> 대학발 | AJ39: 20416502 | AK39: =VLOOKUP(AJ39,[1]데이터시트!$B$3:$N$196,2,FALSE) -> 이상근 | AL39: =VLOOKUP(AJ39,[1]데이터시트!$B$3:$N$196,4,FALSE) -> 0 | AM39: =VLOOKUP(AJ39,[1]데이터시트!$B$3:$N$196,11,FALSE) -> 도약 | AN39: =VLOOKUP(AJ39,[1]데이터시트!$B$3:$N$196,6,FALSE) -> 지역기반 | AO39: 20423821 | AP39: =VLOOKUP(AO39,[1]데이터시트!$B$3:$N$196,2,FALSE) -> 장희수 | AQ39: =VLOOKUP(AO39,[1]데이터시트!$B$3:$N$196,4,FALSE) -> 0 | AR39: =VLOOKUP(AO39,[1]데이터시트!$B$3:$N$196,11,FALSE) -> 초기 | AS39: =VLOOKUP(AO39,[1]데이터시트!$B$3:$N$196,6,FALSE) -> 실험실 | AT39: 20426887 | AU39: =VLOOKUP(AT39,[1]데이터시트!$B$3:$N$196,2,FALSE) -> 김희중 | AV39: =VLOOKUP(AT39,[1]데이터시트!$B$3:$N$196,4,FALSE) -> 0 | AW39: =VLOOKUP(AT39,[1]데이터시트!$B$3:$N$196,11,FALSE) -> 초기 | AX39: =VLOOKUP(AT39,[1]데이터시트!$B$3:$N$196,6,FALSE) -> 지역기반 | AY39: 20406463 | AZ39: =VLOOKUP(AY39,[1]데이터시트!$B$3:$N$196,2,FALSE) -> 유영진 | BA39: =VLOOKUP(AY39,[1]데이터시트!$B$3:$N$196,4,FALSE) -> 0 | BB39: =VLOOKUP(AY39,[1]데이터시트!$B$3:$N$196,11,FALSE) -> 도약 | BC39: =VLOOKUP(AY39,[1]데이터시트!$B$3:$N$196,6,FALSE) -> 지역기반 | BD39: 20424544 | BE39: =VLOOKUP(BD39,[1]데이터시트!$B$3:$N$196,2,FALSE) -> 주태경 | BF39: =VLOOKUP(BD39,[1]데이터시트!$B$3:$N$196,4,FALSE) -> 0 | BG39: =VLOOKUP(BD39,[1]데이터시트!$B$3:$N$196,11,FALSE) -> 도약 | BH39: =VLOOKUP(BD39,[1]데이터시트!$B$3:$N$196,6,FALSE) -> 지역기반
A40: =SUBTOTAL(103,$B$29:B40) -> 11 | B40: 2일차 | C40: =D39+5 -> 1505 | D40: 1525 | E40: 20 | F40: 20430125 | G40: =VLOOKUP(F40,[1]데이터시트!$B$3:$N$196,2,FALSE) -> 이진식 | H40: =VLOOKUP(F40,[1]데이터시트!$B$3:$N$196,4,FALSE) -> 0 | I40: =VLOOKUP(F40,[1]데이터시트!$B$3:$N$196,11,FALSE) -> 도약 | J40: =VLOOKUP(F40,[1]데이터시트!$B$3:$N$196,6,FALSE) -> 지역기반 | K40: 20429144 | L40: =VLOOKUP(K40,[1]데이터시트!$B$3:$N$196,2,FALSE) -> 이현민 | M40: =VLOOKUP(K40,[1]데이터시트!$B$3:$N$196,4,FALSE) -> 매출실적우수 | N40: =VLOOKUP(K40,[1]데이터시트!$B$3:$N$196,11,FALSE) -> 도약 | O40: =VLOOKUP(K40,[1]데이터시트!$B$3:$N$196,6,FALSE) -> 지역기반 | P40: 20419387 | Q40: =VLOOKUP(P40,[1]데이터시트!$B$3:$N$196,2,FALSE) -> WOO SIMON SUNGIL | R40: =VLOOKUP(P40,[1]데이터시트!$B$3:$N$196,4,FALSE) -> 전임교원 | S40: =VLOOKUP(P40,[1]데이터시트!$B$3:$N$196,11,FALSE) -> 초기 | T40: =VLOOKUP(P40,[1]데이터시트!$B$3:$N$196,6,FALSE) -> 실험실 | U40: 20433135 | V40: =VLOOKUP(U40,[1]데이터시트!$B$3:$N$196,2,FALSE) -> 이예린 | W40: =VLOOKUP(U40,[1]데이터시트!$B$3:$N$196,4,FALSE) -> 0 | X40: =VLOOKUP(U40,[1]데이터시트!$B$3:$N$196,11,FALSE) -> 도약 | Y40: =VLOOKUP(U40,[1]데이터시트!$B$3:$N$196,6,FALSE) -> 대학발 | Z40: 20418471 | AA40: =VLOOKUP(Z40,[1]데이터시트!$B$3:$N$196,2,FALSE) -> 김도년 | AB40: =VLOOKUP(Z40,[1]데이터시트!$B$3:$N$196,4,FALSE) -> 0 | AC40: =VLOOKUP(Z40,[1]데이터시트!$B$3:$N$196,11,FALSE) -> 초기 | AD40: =VLOOKUP(Z40,[1]데이터시트!$B$3:$N$196,6,FALSE) -> 대학발 | AE40: 20416208 | AF40: =VLOOKUP(AE40,[1]데이터시트!$B$3:$N$196,2,FALSE) -> 이동욱 | AG40: =VLOOKUP(AE40,[1]데이터시트!$B$3:$N$196,4,FALSE) -> 0 | AH40: =VLOOKUP(AE40,[1]데이터시트!$B$3:$N$196,11,FALSE) -> 도약 | AI40: =VLOOKUP(AE40,[1]데이터시트!$B$3:$N$196,6,FALSE) -> 대학발 | AJ40: 20430556 | AK40: =VLOOKUP(AJ40,[1]데이터시트!$B$3:$N$196,2,FALSE) -> 홍준호 | AL40: =VLOOKUP(AJ40,[1]데이터시트!$B$3:$N$196,4,FALSE) -> 0 | AM40: =VLOOKUP(AJ40,[1]데이터시트!$B$3:$N$196,11,FALSE) -> 도약 | AN40: =VLOOKUP(AJ40,[1]데이터시트!$B$3:$N$196,6,FALSE) -> 지역기반 | AO40: 20426680 | AP40: =VLOOKUP(AO40,[1]데이터시트!$B$3:$N$196,2,FALSE) -> 이승원 | AQ40: =VLOOKUP(AO40,[1]데이터시트!$B$3:$N$196,4,FALSE) -> 전임교원 | AR40: =VLOOKUP(AO40,[1]데이터시트!$B$3:$N$196,11,FALSE) -> 초기 | AS40: =VLOOKUP(AO40,[1]데이터시트!$B$3:$N$196,6,FALSE) -> 실험실 | AT40: 20416668 | AU40: =VLOOKUP(AT40,[1]데이터시트!$B$3:$N$196,2,FALSE) -> 박규근 | AV40: =VLOOKUP(AT40,[1]데이터시트!$B$3:$N$196,4,FALSE) -> 0 | AW40: =VLOOKUP(AT40,[1]데이터시트!$B$3:$N$196,11,FALSE) -> 초기 | AX40: =VLOOKUP(AT40,[1]데이터시트!$B$3:$N$196,6,FALSE) -> 대학발 | AY40: 20414728 | AZ40: =VLOOKUP(AY40,[1]데이터시트!$B$3:$N$196,2,FALSE) -> 황해주 | BA40: =VLOOKUP(AY40,[1]데이터시트!$B$3:$N$196,4,FALSE) -> 0 | BB40: =VLOOKUP(AY40,[1]데이터시트!$B$3:$N$196,11,FALSE) -> 도약 | BC40: =VLOOKUP(AY40,[1]데이터시트!$B$3:$N$196,6,FALSE) -> 지역기반 | BD40: 20425527 | BE40: =VLOOKUP(BD40,[1]데이터시트!$B$3:$N$196,2,FALSE) -> 황정은 | BF40: =VLOOKUP(BD40,[1]데이터시트!$B$3:$N$196,4,FALSE) -> 0 | BG40: =VLOOKUP(BD40,[1]데이터시트!$B$3:$N$196,11,FALSE) -> 도약 | BH40: =VLOOKUP(BD40,[1]데이터시트!$B$3:$N$196,6,FALSE) -> 지역기반
A41: =SUBTOTAL(103,$B$29:B41) -> 12 | B41: 2일차 | C41: =D40+5 -> 1530 | D41: 1550 | E41: 20 | F41: 20418598 | G41: =VLOOKUP(F41,[1]데이터시트!$B$3:$N$196,2,FALSE) -> 박윤범 | H41: =VLOOKUP(F41,[1]데이터시트!$B$3:$N$196,4,FALSE) -> 0 | I41: =VLOOKUP(F41,[1]데이터시트!$B$3:$N$196,11,FALSE) -> 도약 | J41: =VLOOKUP(F41,[1]데이터시트!$B$3:$N$196,6,FALSE) -> 지역기반 | K41: 20430558 | L41: =VLOOKUP(K41,[1]데이터시트!$B$3:$N$196,2,FALSE) -> 이승훈 | M41: =VLOOKUP(K41,[1]데이터시트!$B$3:$N$196,4,FALSE) -> 0 | N41: =VLOOKUP(K41,[1]데이터시트!$B$3:$N$196,11,FALSE) -> 도약 | O41: =VLOOKUP(K41,[1]데이터시트!$B$3:$N$196,6,FALSE) -> 지역기반 | P41: 20402754 | Q41: =VLOOKUP(P41,[1]데이터시트!$B$3:$N$196,2,FALSE) -> 최하진 | R41: =VLOOKUP(P41,[1]데이터시트!$B$3:$N$196,4,FALSE) -> 0 | S41: =VLOOKUP(P41,[1]데이터시트!$B$3:$N$196,11,FALSE) -> 초기 | T41: =VLOOKUP(P41,[1]데이터시트!$B$3:$N$196,6,FALSE) -> 실험실 | Z41: 20439651 | AA41: =VLOOKUP(Z41,[1]데이터시트!$B$3:$N$196,2,FALSE) -> 박장호 | AB41: =VLOOKUP(Z41,[1]데이터시트!$B$3:$N$196,4,FALSE) -> 전임교원 | AC41: =VLOOKUP(Z41,[1]데이터시트!$B$3:$N$196,11,FALSE) -> 예비 | AD41: =VLOOKUP(Z41,[1]데이터시트!$B$3:$N$196,6,FALSE) -> 대학발 | AE41: 20428674 | AF41: =VLOOKUP(AE41,[1]데이터시트!$B$3:$N$196,2,FALSE) -> 박성준 | AG41: =VLOOKUP(AE41,[1]데이터시트!$B$3:$N$196,4,FALSE) -> 잠재력 확인 팀 | AH41: =VLOOKUP(AE41,[1]데이터시트!$B$3:$N$196,11,FALSE) -> 도약 | AI41: =VLOOKUP(AE41,[1]데이터시트!$B$3:$N$196,6,FALSE) -> 대학발 | AJ41: 20431117 | AK41: =VLOOKUP(AJ41,[1]데이터시트!$B$3:$N$196,2,FALSE) -> 우성호 | AL41: =VLOOKUP(AJ41,[1]데이터시트!$B$3:$N$196,4,FALSE) -> 매출실적우수 | AM41: =VLOOKUP(AJ41,[1]데이터시트!$B$3:$N$196,11,FALSE) -> 도약 | AN41: =VLOOKUP(AJ41,[1]데이터시트!$B$3:$N$196,6,FALSE) -> 지역기반 | AO41: 20419166 | AP41: =VLOOKUP(AO41,[1]데이터시트!$B$3:$N$196,2,FALSE) -> 강기운 | AQ41: =VLOOKUP(AO41,[1]데이터시트!$B$3:$N$196,4,FALSE) -> 0 | AR41: =VLOOKUP(AO41,[1]데이터시트!$B$3:$N$196,11,FALSE) -> 초기 | AS41: =VLOOKUP(AO41,[1]데이터시트!$B$3:$N$196,6,FALSE) -> 실험실 | AT41: 20421742 | AU41: =VLOOKUP(AT41,[1]데이터시트!$B$3:$N$196,2,FALSE) -> 이원철 | AV41: =VLOOKUP(AT41,[1]데이터시트!$B$3:$N$196,4,FALSE) -> 0 | AW41: =VLOOKUP(AT41,[1]데이터시트!$B$3:$N$196,11,FALSE) -> 초기 | AX41: =VLOOKUP(AT41,[1]데이터시트!$B$3:$N$196,6,FALSE) -> 실험실 | AY41: 20425350 | AZ41: =VLOOKUP(AY41,[1]데이터시트!$B$3:$N$196,2,FALSE) -> 정승호 | BA41: =VLOOKUP(AY41,[1]데이터시트!$B$3:$N$196,4,FALSE) -> 전임교원 | BB41: =VLOOKUP(AY41,[1]데이터시트!$B$3:$N$196,11,FALSE) -> 도약 | BC41: =VLOOKUP(AY41,[1]데이터시트!$B$3:$N$196,6,FALSE) -> 지역기반 | BD41: 20429004 | BE41: =VLOOKUP(BD41,[1]데이터시트!$B$3:$N$196,2,FALSE) -> 조용일 | BF41: =VLOOKUP(BD41,[1]데이터시트!$B$3:$N$196,4,FALSE) -> 매출실적우수 | BG41: =VLOOKUP(BD41,[1]데이터시트!$B$3:$N$196,11,FALSE) -> 도약 | BH41: =VLOOKUP(BD41,[1]데이터시트!$B$3:$N$196,6,FALSE) -> 지역기반
A42: =SUBTOTAL(103,$B$29:B42) -> 13 | B42: 2일차 | C42: =D41+5 -> 1555 | D42: 1615 | E42: 20 | AE42: 20415322 | AF42: =VLOOKUP(AE42,[1]데이터시트!$B$3:$N$196,2,FALSE) -> 김건형 | AG42: =VLOOKUP(AE42,[1]데이터시트!$B$3:$N$196,4,FALSE) -> 0 | AH42: =VLOOKUP(AE42,[1]데이터시트!$B$3:$N$196,11,FALSE) -> 예비 | AI42: =VLOOKUP(AE42,[1]데이터시트!$B$3:$N$196,6,FALSE) -> 대학발 | AO42: 20414230 | AP42: =VLOOKUP(AO42,[1]데이터시트!$B$3:$N$196,2,FALSE) -> 전영준 | AQ42: =VLOOKUP(AO42,[1]데이터시트!$B$3:$N$196,4,FALSE) -> 전임교원 | AR42: =VLOOKUP(AO42,[1]데이터시트!$B$3:$N$196,11,FALSE) -> 초기 | AS42: =VLOOKUP(AO42,[1]데이터시트!$B$3:$N$196,6,FALSE) -> 대학발
A43: =SUBTOTAL(103,$B$29:B43) -> 14 | B43: 2일차 | C43: =D42+5 -> 1620 | D43: 1640 | E43: 20
...
