Workbook

Sheet 대상
A1: 순번 | B1: 과제번호 | C1: 공고 | D1: 공고구분 | E1: 대표자명 | F1: 성별 | G1: 생년월일 | H1: 청/중장년 | I1: 매출액 | J1: 사원수(명) | K1: 과제명 | L1: 창업(희망)지역 | M1: 지원분야 | N1: 전문기술분야 | O1: 평가기준 | P1: 분과 | Q1: 평가일자 | R1: 요건검토 | S1: 재창업 청년 창업기업 | T1: 25년 린스타트업 우수자 | U1: 25년 창업중심대학 최우수 판정기업 | V1: 가점 | W1: 25년 대학창업 아이디어 챌린지(대상, 최우수상) | X1: 25년 린스타트업 우수자 | Y1: 도전!k-스타트업 왕중왕전 | Z1: 협력기관 추천(10개) | AA1: 지역특화 레전드50+ | AB1: 사전검토 | AC1: 특이사항
A2: 1 | B2: 20396065 | C2: 2026년도 창업중심대학 지역기반 (예비)창업기업 모집 공고 | D2: 지역기반 | E2: 심성진 | F2: 남 | G2: 1989-11-11 | H2: 청년 | I2: 0 | J2: 0 | K2: AI경대 미용실 | L2: 서울 | M2: 제조 | N2: 공예ㆍ디자인 | O2: 예비 | P2: 공예ㆍ디자인 | Q2: =TODAY() -> 46120 | R2: 요건탈락 | S2: 0 | T2: 0 | U2: 0 | V2: =IF(OR(S2="○",T2="○",U2="○"),2,0) -> 0 | W2: 0 | X2: 0 | Y2: 0 | Z2: 0 | AA2: 0 | AB2: =IF(OR(W2="○",X2="○",Y2="○",Z2="○",AA2="○"),"면제",$R2) -> 요건탈락
A3: 2 | B3: 20399405 | C3: 2026년도 창업중심대학 지역기반 (예비)창업기업 모집 공고 | D3: 지역기반 | E3: 박준용 | F3: 남 | G3: 1983-03-25 | H3: 중장년 | I3: 101,000,000 | J3: 4 | K3: AI Agent 기술을 활용한 CFM(고객 피드백 관리) 서비스 | L3: 경기 | M3: 지식서비스 | N3: 정보ㆍ통신 | O3: 초기 | P3: 정보ㆍ통신5 | Q3: =TODAY() -> 46120 | R3: 0 | S3: 0 | T3: 0 | U3: 0 | V3: =IF(OR(S3="○",T3="○",U3="○"),2,0) -> 0 | W3: 0 | X3: 0 | Y3: 0 | Z3: 0 | AA3: 0 | AB3: =IF(OR(W3="○",X3="○",Y3="○",Z3="○",AA3="○"),"면제",$R3) -> 0
A4: 3 | B4: 20399435 | C4: 2026년도 창업중심대학 지역기반 (예비)창업기업 모집 공고 | D4: 지역기반 | E4: 이희정 | F4: 여 | G4: 1968-07-11 | H4: 중장년 | I4: 7,600 | J4: 0 | K4: IHI(상호작용 건전성 지수) 기반 AI 부모코칭 SaaS 플랫폼 | L4: 경기 | M4: 지식서비스 | N4: 정보ㆍ통신 | O4: 초기 | P4: 정보ㆍ통신6 | Q4: =TODAY() -> 46120 | R4: 0 | S4: 0 | T4: 0 | U4: 0 | V4: =IF(OR(S4="○",T4="○",U4="○"),2,0) -> 0 | W4: 0 | X4: 0 | Y4: 0 | Z4: 0 | AA4: 0 | AB4: =IF(OR(W4="○",X4="○",Y4="○",Z4="○",AA4="○"),"면제",$R4) -> 0
A5: 4 | B5: 20399536 | C5: 2026년도 창업중심대학 지역기반 (예비)창업기업 모집 공고 | D5: 지역기반 | E5: 김지형 | F5: 여 | G5: 1999-09-06 | H5: 청년 | I5: 0 | J5: 0 | K5: 웹에서 디자인하고 실시간으로 주문하는 레터링 케이크 플랫폼 ‘케끄’ | L5: 서울 | M5: 지식서비스 | N5: 정보ㆍ통신 | O5: 예비 | P5: 정보ㆍ통신3 | Q5: =TODAY() -> 46120 | R5: 0 | S5: 0 | T5: 0 | U5: 0 | V5: =IF(OR(S5="○",T5="○",U5="○"),2,0) -> 0 | W5: 0 | X5: 0 | Y5: 0 | Z5: 0 | AA5: 0 | AB5: =IF(OR(W5="○",X5="○",Y5="○",Z5="○",AA5="○"),"면제",$R5) -> 0
A6: 5 | B6: 20399570 | C6: 2026년도 창업중심대학 지역기반 (예비)창업기업 모집 공고 | D6: 지역기반 | E6: 전준형 | F6: 남 | G6: 2001-08-06 | H6: 청년 | I6: 0 | J6: 0 | K6: 실시간 감정 공유 기능으로 콘텐츠를 200% 더 재미있게 시청할 수 있는 동시시청 플랫폼 ‘비욘드’ | L6: 경기 | M6: 지식서비스 | N6: 정보ㆍ통신 | O6: 예비 | P6: 정보ㆍ통신2 | Q6: =TODAY() -> 46120 | R6: 0 | S6: 0 | T6: 0 | U6: 0 | V6: =IF(OR(S6="○",T6="○",U6="○"),2,0) -> 0 | W6: 0 | X6: 0 | Y6: 0 | Z6: 0 | AA6: 0 | AB6: =IF(OR(W6="○",X6="○",Y6="○",Z6="○",AA6="○"),"면제",$R6) -> 0
A7: 6 | B7: 20399602 | C7: 2026년도 창업중심대학 지역기반 (예비)창업기업 모집 공고 | D7: 지역기반 | E7: 황명희 | F7: 여 | G7: 1975-08-26 | H7: 중장년 | I7: 0 | J7: 0 | K7: 임상 기반 기능성 아로마 바디케어 제품 개발 및 브랜드 사업화 | L7: 경기 | M7: 제조 | N7: 화공ㆍ섬유 | O7: 예비 | P7: 화공ㆍ섬유 | Q7: =TODAY() -> 46120 | R7: 0 | S7: 0 | T7: 0 | U7: 0 | V7: =IF(OR(S7="○",T7="○",U7="○"),2,0) -> 0 | W7: 0 | X7: 0 | Y7: 0 | Z7: 0 | AA7: 0 | AB7: =IF(OR(W7="○",X7="○",Y7="○",Z7="○",AA7="○"),"면제",$R7) -> 0
A8: 7 | B8: 20399632 | C8: 2026년도 창업중심대학 지역기반 (예비)창업기업 모집 공고 | D8: 지역기반 | E8: 최겸 | F8: 남 | G8: 2000-10-04 | H8: 청년 | I8: 0 | J8: 0 | K8: AI(LLM) 기반 시니어 음성 인터랙티브 자서전 자동 제작 플랫폼 | L8: 경기 | M8: 제조 | N8: 정보ㆍ통신 | O8: 예비 | P8: 정보ㆍ통신4 | Q8: =TODAY() -> 46120 | R8: 0 | S8: ○ | T8: 0 | U8: 0 | V8: =IF(OR(S8="○",T8="○",U8="○"),2,0) -> 2 | W8: 0 | X8: 0 | Y8: 0 | Z8: 0 | AA8: 0 | AB8: =IF(OR(W8="○",X8="○",Y8="○",Z8="○",AA8="○"),"면제",$R8) -> 0
A9: 8 | B9: 20399678 | C9: 2026년도 창업중심대학 지역기반 (예비)창업기업 모집 공고 | D9: 지역기반 | E9: 박영찬 | F9: 남 | G9: 1981-07-16 | H9: 중장년 | I9: 0 | J9: 0 | K9: AI 기술이 적용된 기술자 중심 하이퍼 로컬 시공 중개 플랫폼, 우리동네기술자(WOOGI) | L9: 경기 | M9: 지식서비스 | N9: 정보ㆍ통신 | O9: 예비 | P9: 정보ㆍ통신4 | Q9: =TODAY() -> 46120 | R9: 0 | S9: 0 | T9: 0 | U9: 0 | V9: =IF(OR(S9="○",T9="○",U9="○"),2,0) -> 0 | W9: 0 | X9: 0 | Y9: 0 | Z9: 0 | AA9: 0 | AB9: =IF(OR(W9="○",X9="○",Y9="○",Z9="○",AA9="○"),"면제",$R9) -> 0
A10: 9 | B10: 20399729 | C10: 2026년도 창업중심대학 지역기반 (예비)창업기업 모집 공고 | D10: 지역기반 | E10: 심명훈 | F10: 남 | G10: 1994-05-20 | H10: 청년 | I10: 0 | J10: 0 | K10: 연 1,894만 명 방한 외래관광객 시장에서, 현지인과의 로컬 경험의 신뢰·탐색·언어 장벽 문제를 LLM 기반 AI 코스 추천과 역경매 호스트 매칭으로 해결하는 초개인화 여행 경험 커머스 (MVP지표: 파일럿 매출 48만원, 사용자 277명) | L10: 인천 | M10: 지식서비스 | N10: 정보ㆍ통신 | O10: 예비 | P10: 정보ㆍ통신6 | Q10: =TODAY() -> 46120 | R10: 0 | S10: ○ | T10: 0 | U10: 0 | V10: =IF(OR(S10="○",T10="○",U10="○"),2,0) -> 2 | W10: 0 | X10: 0 | Y10: 0 | Z10: 0 | AA10: 0 | AB10: =IF(OR(W10="○",X10="○",Y10="○",Z10="○",AA10="○"),"면제",$R10) -> 0
A11: 10 | B11: 20399730 | C11: 2026년도 창업중심대학 지역기반 (예비)창업기업 모집 공고 | D11: 지역기반 | E11: 심우정 | F11: 여 | G11: 1990-01-30 | H11: 청년 | I11: 0 | J11: 0 | K11: 위험도 산출 알고리즘 기술이 적용된 임신·수유부의 개인맞춤형(임신주수 및 월령별) 복약 안전 정보 모바일 앱 ‘필버스’ | L11: 경기 | M11: 지식서비스 | N11: 정보ㆍ통신 | O11: 예비 | P11: 정보ㆍ통신5 | Q11: =TODAY() -> 46120 | R11: 0 | S11: ○ | T11: 0 | U11: 0 | V11: =IF(OR(S11="○",T11="○",U11="○"),2,0) -> 2 | W11: 0 | X11: 0 | Y11: 0 | Z11: 0 | AA11: 0 | AB11: =IF(OR(W11="○",X11="○",Y11="○",Z11="○",AA11="○"),"면제",$R11) -> 0
A12: 11 | B12: 20399860 | C12: 2026년도 창업중심대학 지역기반 (예비)창업기업 모집 공고 | D12: 지역기반 | E12: 김승영 | F12: 남 | G12: 1987-06-26 | H12: 청년 | I12: 0 | J12: 0 | K12: 예비창업자의 시장 수요 검증을 위한 신뢰도 기반 타겟 매칭·AI 분석 시장검증 서비스 개발 | L12: 서울 | M12: 지식서비스 | N12: 정보ㆍ통신 | O12: 예비 | P12: 정보ㆍ통신5 | Q12: =TODAY() -> 46120 | R12: 0 | S12: 0 | T12: 0 | U12: 0 | V12: =IF(OR(S12="○",T12="○",U12="○"),2,0) -> 0 | W12: 0 | X12: 0 | Y12: 0 | Z12: 0 | AA12: 0 | AB12: =IF(OR(W12="○",X12="○",Y12="○",Z12="○",AA12="○"),"면제",$R12) -> 0
A13: 12 | B13: 20399910 | C13: 2026년도 창업중심대학 지역기반 (예비)창업기업 모집 공고 | D13: 지역기반 | E13: 윤여준 | F13: 남 | G13: 1985-07-24 | H13: 중장년 | I13: 267,181,182 | J13: 2 | K13: 심박데이터 기반 개인 맞춤형 운동결과 분석·추천 서비스 고도화 및 상용화 | L13: 서울 | M13: 지식서비스 | N13: 정보ㆍ통신 | O13: 초기 | P13: 정보ㆍ통신3 | Q13: =TODAY() -> 46120 | R13: 0 | S13: 0 | T13: 0 | U13: 0 | V13: =IF(OR(S13="○",T13="○",U13="○"),2,0) -> 0 | W13: 0 | X13: 0 | Y13: 0 | Z13: 0 | AA13: 0 | AB13: =IF(OR(W13="○",X13="○",Y13="○",Z13="○",AA13="○"),"면제",$R13) -> 0
A14: 13 | B14: 20400081 | C14: 2026년도 창업중심대학 지역기반 (예비)창업기업 모집 공고 | D14: 지역기반 | E14: 임성현 | F14: 남 | G14: 1981-09-20 | H14: 중장년 | I14: 0 | J14: 0 | K14: 나들목 | L14: 경기 | M14: 지식서비스 | N14: 정보ㆍ통신 | O14: 초기 | P14: 정보ㆍ통신6 | Q14: =TODAY() -> 46120 | R14: 0 | S14: 0 | T14: 0 | U14: 0 | V14: =IF(OR(S14="○",T14="○",U14="○"),2,0) -> 0 | W14: 0 | X14: 0 | Y14: 0 | Z14: 0 | AA14: 0 | AB14: =IF(OR(W14="○",X14="○",Y14="○",Z14="○",AA14="○"),"면제",$R14) -> 0
A15: 14 | B15: 20400184 | C15: 2026년도 창업중심대학 지역기반 (예비)창업기업 모집 공고 | D15: 지역기반 | E15: 신주일 | F15: 남 | G15: 1984-10-14 | H15: 중장년 | I15: 2,101,282,727 | J15: 11 | K15: 디지털 스컬핑 기술을 활용한 조형 기반 웨어러블 스컬프처 브랜드 'VAXINE' | L15: 경기 | M15: 제조 | N15: 공예ㆍ디자인 | O15: 초기 | P15: 공예ㆍ디자인 | Q15: =TODAY() -> 46120 | R15: 0 | S15: 0 | T15: 0 | U15: 0 | V15: =IF(OR(S15="○",T15="○",U15="○"),2,0) -> 0 | W15: 0 | X15: 0 | Y15: 0 | Z15: 0 | AA15: 0 | AB15: =IF(OR(W15="○",X15="○",Y15="○",Z15="○",AA15="○"),"면제",$R15) -> 0
A16: 15 | B16: 20400322 | C16: 2026년도 창업중심대학 지역기반 (예비)창업기업 모집 공고 | D16: 지역기반 | E16: 주이나 | F16: 여 | G16: 1991-11-27 | H16: 청년 | I16: 138,076,812 | J16: 2 | K16: AI 비전 인식 기반 시니어 신체 데이터 분석을 통한 개인 맞춤형 방문 이미용 케어 플랫폼 | L16: 경기 | M16: 지식서비스 | N16: 정보ㆍ통신 | O16: 도약 | P16: 정보ㆍ통신3 | Q16: =TODAY() -> 46120 | R16: 0 | S16: 0 | T16: 0 | U16: 0 | V16: =IF(OR(S16="○",T16="○",U16="○"),2,0) -> 0 | W16: 0 | X16: 0 | Y16: 0 | Z16: 0 | AA16: 0 | AB16: =IF(OR(W16="○",X16="○",Y16="○",Z16="○",AA16="○"),"면제",$R16) -> 0
A17: 16 | B17: 20400325 | C17: 2026년도 창업중심대학 지역기반 (예비)창업기업 모집 공고 | D17: 지역기반 | E17: 이언봉 | F17: 남 | G17: 1983-06-20 | H17: 중장년 | I17: 0 | J17: 0 | K17: AI 데이터센터용 고성능 반도체 신뢰성 확보를 위한 실시간 수명 예측 온칩 모니터링 프로토타입 개발 | L17: 경기 | M17: 제조 | N17: 전기ㆍ전자 | O17: 예비 | P17: 전기ㆍ전자 | Q17: =TODAY() -> 46120 | R17: 0 | S17: 0 | T17: 0 | U17: 0 | V17: =IF(OR(S17="○",T17="○",U17="○"),2,0) -> 0 | W17: 0 | X17: 0 | Y17: 0 | Z17: 0 | AA17: 0 | AB17: =IF(OR(W17="○",X17="○",Y17="○",Z17="○",AA17="○"),"면제",$R17) -> 0
A18: 17 | B18: 20400332 | C18: 2026년도 창업중심대학 지역기반 (예비)창업기업 모집 공고 | D18: 지역기반 | E18: 이상달 | F18: 남 | G18: 1965-03-22 | H18: 중장년 | I18: 94,328,000 | J18: 2 | K18: AI 기반 병원동행 서비스 플랫폼(MD에스코트) | L18: 서울 | M18: 지식서비스 | N18: 정보ㆍ통신 | O18: 도약 | P18: 정보ㆍ통신7 | Q18: =TODAY() -> 46120 | R18: 0 | S18: 0 | T18: 0 | U18: 0 | V18: =IF(OR(S18="○",T18="○",U18="○"),2,0) -> 0 | W18: 0 | X18: 0 | Y18: 0 | Z18: 0 | AA18: 0 | AB18: =IF(OR(W18="○",X18="○",Y18="○",Z18="○",AA18="○"),"면제",$R18) -> 0
A19: 18 | B19: 20400348 | C19: 2026년도 창업중심대학 지역기반 (예비)창업기업 모집 공고 | D19: 지역기반 | E19: 이학용 | F19: 남 | G19: 1989-07-12 | H19: 청년 | I19: 287,324,936 | J19: 1 | K19: 출산 후 아이의 성장과 함께하는 육아 라이프사이클 렌탈 플랫폼 | L19: 서울 | M19: 지식서비스 | N19: 정보ㆍ통신 | O19: 초기 | P19: 정보ㆍ통신2 | Q19: =TODAY() -> 46120 | R19: 0 | S19: 0 | T19: 0 | U19: 0 | V19: =IF(OR(S19="○",T19="○",U19="○"),2,0) -> 0 | W19: 0 | X19: 0 | Y19: 0 | Z19: 0 | AA19: 0 | AB19: =IF(OR(W19="○",X19="○",Y19="○",Z19="○",AA19="○"),"면제",$R19) -> 0
A20: 19 | B20: 20400362 | C20: 2026년도 창업중심대학 지역기반 (예비)창업기업 모집 공고 | D20: 지역기반 | E20: 이승주 | F20: 남 | G20: 1997-05-21 | H20: 청년 | I20: 1,600 | J20: 1 | K20: 고기능성 반려견 퀵-레이스 하네스 | L20: 경기 | M20: 제조 | N20: 화공ㆍ섬유 | O20: 초기 | P20: 화공ㆍ섬유 | Q20: =TODAY() -> 46120 | R20: 0 | S20: 0 | T20: 0 | U20: 0 | V20: =IF(OR(S20="○",T20="○",U20="○"),2,0) -> 0 | W20: 0 | X20: 0 | Y20: 0 | Z20: 0 | AA20: 0 | AB20: =IF(OR(W20="○",X20="○",Y20="○",Z20="○",AA20="○"),"면제",$R20) -> 0
A21: 20 | B21: 20400729 | C21: 2026년도 창업중심대학 지역기반 (예비)창업기업 모집 공고 | D21: 지역기반 | E21: 김수빈 | F21: 여 | G21: 1995-08-29 | H21: 청년 | I21: 0 | J21: 0 | K21: 1인 기업가의 매출 및 생산성 극대화를 위한 업무 시간 최적화 SaaS | L21: 경기 | M21: 지식서비스 | N21: 정보ㆍ통신 | O21: 예비 | P21: 정보ㆍ통신2 | Q21: =TODAY() -> 46120 | R21: 요건탈락 | S21: 0 | T21: 0 | U21: 0 | V21: =IF(OR(S21="○",T21="○",U21="○"),2,0) -> 0 | W21: 0 | X21: 0 | Y21: 0 | Z21: 0 | AA21: 0 | AB21: =IF(OR(W21="○",X21="○",Y21="○",Z21="○",AA21="○"),"면제",$R21) -> 요건탈락
A22: 21 | B22: 20400898 | C22: 2026년도 창업중심대학 지역기반 (예비)창업기업 모집 공고 | D22: 지역기반 | E22: 고윤제 | F22: 남 | G22: 1994-05-09 | H22: 청년 | I22: 33,716,363 | J22: 0 | K22: 기업의 SaaS 도입비용을 개선하는 SaaS 온보딩 서비스(RAG/커뮤니티 데이터 기반) | L22: 서울 | M22: 지식서비스 | N22: 정보ㆍ통신 | O22: 초기 | P22: 정보ㆍ통신3 | Q22: =TODAY() -> 46120 | R22: 0 | S22: ○ | T22: 0 | U22: 0 | V22: =IF(OR(S22="○",T22="○",U22="○"),2,0) -> 2 | W22: 0 | X22: 0 | Y22: 0 | Z22: 0 | AA22: 0 | AB22: =IF(OR(W22="○",X22="○",Y22="○",Z22="○",AA22="○"),"면제",$R22) -> 0
A23: 22 | B23: 20400906 | C23: 2026년도 창업중심대학 지역기반 (예비)창업기업 모집 공고 | D23: 지역기반 | E23: 김민선 | F23: 여 | G23: 1991-01-15 | H23: 청년 | I23: 0 | J23: 0 | K23: 평택 주한미군 및 가족 5만 명 대상 지역 특산 쌀·배 전통주 체험존 | L23: 경기 | M23: 제조 | N23: 공예ㆍ디자인 | O23: 예비 | P23: 공예ㆍ디자인 | Q23: =TODAY() -> 46120 | R23: 0 | S23: ○ | T23: 0 | U23: 0 | V23: =IF(OR(S23="○",T23="○",U23="○"),2,0) -> 2 | W23: 0 | X23: 0 | Y23: 0 | Z23: 0 | AA23: 0 | AB23: =IF(OR(W23="○",X23="○",Y23="○",Z23="○",AA23="○"),"면제",$R23) -> 0
A24: 23 | B24: 20401026 | C24: 2026년도 창업중심대학 지역기반 (예비)창업기업 모집 공고 | D24: 지역기반 | E24: 이동권 | F24: 남 | G24: 1989-01-28 | H24: 청년 | I24: 5,000,000,000 | J24: 3 | K24: 대규모 진료데이터 활용한 병원 운영 AI 플랫폼 구축 : 포텐셜부터 개선방안 제안까지 | L24: 경기 | M24: 지식서비스 | N24: 정보ㆍ통신 | O24: 도약 | P24: 정보ㆍ통신4 | Q24: =TODAY() -> 46120 | R24: 0 | S24: 0 | T24: 0 | U24: 0 | V24: =IF(OR(S24="○",T24="○",U24="○"),2,0) -> 0 | W24: 0 | X24: 0 | Y24: 0 | Z24: 0 | AA24: 0 | AB24: =IF(OR(W24="○",X24="○",Y24="○",Z24="○",AA24="○"),"면제",$R24) -> 0
A25: 24 | B25: 20401050 | C25: 2026년도 창업중심대학 지역기반 (예비)창업기업 모집 공고 | D25: 지역기반 | E25: 황설아 | F25: 여 | G25: 1993-05-02 | H25: 청년 | I25: 0 | J25: 0 | K25: AI 기반 환자맞춤형 글로벌 의료관광 원스톱 플랫폼, 메디럭스AI(MediLuxeAI) | L25: 서울 | M25: 지식서비스 | N25: 바이오ㆍ의료ㆍ생명 | O25: 예비 | P25: 바이오ㆍ의료ㆍ생명1 | Q25: =TODAY() -> 46120 | R25: 0 | S25: ○ | T25: 0 | U25: 0 | V25: =IF(OR(S25="○",T25="○",U25="○"),2,0) -> 2 | W25: 0 | X25: 0 | Y25: 0 | Z25: 0 | AA25: 0 | AB25: =IF(OR(W25="○",X25="○",Y25="○",Z25="○",AA25="○"),"면제",$R25) -> 0
A26: 25 | B26: 20401269 | C26: 2026년도 창업중심대학 지역기반 (예비)창업기업 모집 공고 | D26: 지역기반 | E26: 윤수정 | F26: 여 | G26: 1992-02-17 | H26: 청년 | I26: 41,352,356 | J26: 0 | K26: 수상 스포츠 이후 아로마테라피를 활용한 ‘After-Water Ritual’ 스킨케어 브랜드 | L26: 서울 | M26: 제조 | N26: 화공ㆍ섬유 | O26: 초기 | P26: 화공ㆍ섬유 | Q26: =TODAY() -> 46120 | R26: 0 | S26: 0 | T26: 0 | U26: 0 | V26: =IF(OR(S26="○",T26="○",U26="○"),2,0) -> 0 | W26: 0 | X26: 0 | Y26: 0 | Z26: 0 | AA26: ○ | AB26: =IF(OR(W26="○",X26="○",Y26="○",Z26="○",AA26="○"),"면제",$R26) -> 면제
A27: 26 | B27: 20401280 | C27: 2026년도 창업중심대학 지역기반 (예비)창업기업 모집 공고 | D27: 지역기반 | E27: 변윤경 | F27: 여 | G27: 1987-04-28 | H27: 청년 | I27: 5,600,000 | J27: 3 | K27: 한국 전통 문양(IP) 기반 하이엔드 텍스타일 PB상품 제조·판매 | L27: 서울 | M27: 제조 | N27: 공예ㆍ디자인 | O27: 초기 | P27: 공예ㆍ디자인 | Q27: =TODAY() -> 46120 | R27: 0 | S27: ○ | T27: 0 | U27: 0 | V27: =IF(OR(S27="○",T27="○",U27="○"),2,0) -> 2 | W27: 0 | X27: 0 | Y27: 0 | Z27: 0 | AA27: 0 | AB27: =IF(OR(W27="○",X27="○",Y27="○",Z27="○",AA27="○"),"면제",$R27) -> 0
A28: 27 | B28: 20401288 | C28: 2026년도 창업중심대학 지역기반 (예비)창업기업 모집 공고 | D28: 지역기반 | E28: 이강민 | F28: 남 | G28: 1970-01-28 | H28: 중장년 | I28: 0 | J28: 0 | K28: 중소 제조기업 기술자산 기반 기술질의·애로 처리시간 단축 AX 솔루션 | L28: 경기 | M28: 지식서비스 | N28: 정보ㆍ통신 | O28: 예비 | P28: 정보ㆍ통신3 | Q28: =TODAY() -> 46120 | R28: 0 | S28: 0 | T28: 0 | U28: 0 | V28: =IF(OR(S28="○",T28="○",U28="○"),2,0) -> 0 | W28: 0 | X28: 0 | Y28: 0 | Z28: 0 | AA28: 0 | AB28: =IF(OR(W28="○",X28="○",Y28="○",Z28="○",AA28="○"),"면제",$R28) -> 0
A29: 28 | B29: 20401289 | C29: 2026년도 창업중심대학 지역기반 (예비)창업기업 모집 공고 | D29: 지역기반 | E29: 유승훈 | F29: 남 | G29: 1996-07-30 | H29: 청년 | I29: 0 | J29: 0 | K29: 커피박(커피찌꺼기) 수거-제조-판매 통합 밸류체인 구축을 통한 바이오매스 연료탄 생산 및 순환경제 플랫폼 운영 | L29: 서울 | M29: 제조 | N29: 정보ㆍ통신 | O29: 초기 | P29: 정보ㆍ통신7 | Q29: =TODAY() -> 46120 | R29: 0 | S29: 0 | T29: 0 | U29: 0 | V29: =IF(OR(S29="○",T29="○",U29="○"),2,0) -> 0 | W29: 0 | X29: 0 | Y29: 0 | Z29: 0 | AA29: 0 | AB29: =IF(OR(W29="○",X29="○",Y29="○",Z29="○",AA29="○"),"면제",$R29) -> 0
A30: 29 | B30: 20401317 | C30: 2026년도 창업중심대학 지역기반 (예비)창업기업 모집 공고 | D30: 지역기반 | E30: 신유경 | F30: 여 | G30: 1998-09-01 | H30: 청년 | I30: 0 | J30: 0 | K30: 한글 자음 • 모음 조형 구조 기반 패션 디자인 시스템 개발 및 의류 제품 사업화 | L30: 서울 | M30: 제조 | N30: 공예ㆍ디자인 | O30: 예비 | P30: 공예ㆍ디자인 | Q30: =TODAY() -> 46120 | R30: 요건탈락 | S30: 0 | T30: 0 | U30: 0 | V30: =IF(OR(S30="○",T30="○",U30="○"),2,0) -> 0 | W30: 0 | X30: 0 | Y30: 0 | Z30: 0 | AA30: 0 | AB30: =IF(OR(W30="○",X30="○",Y30="○",Z30="○",AA30="○"),"면제",$R30) -> 요건탈락
A31: 30 | B31: 20401337 | C31: 2026년도 창업중심대학 지역기반 (예비)창업기업 모집 공고 | D31: 지역기반 | E31: 박미란 | F31: 여 | G31: 1985-01-23 | H31: 중장년 | I31: 53,200,000 | J31: 0 | K31: 햇썹?왓썹! : 식품 위생과 안전을 위한 AI 기반 디지털 전산화 플랫폼 | L31: 경기 | M31: 지식서비스 | N31: 정보ㆍ통신 | O31: 초기 | P31: 정보ㆍ통신7 | Q31: =TODAY() -> 46120 | R31: 0 | S31: 0 | T31: 0 | U31: 0 | V31: =IF(OR(S31="○",T31="○",U31="○"),2,0) -> 0 | W31: 0 | X31: 0 | Y31: 0 | Z31: 0 | AA31: 0 | AB31: =IF(OR(W31="○",X31="○",Y31="○",Z31="○",AA31="○"),"면제",$R31) -> 0
A32: 31 | B32: 20401363 | C32: 2026년도 창업중심대학 지역기반 (예비)창업기업 모집 공고 | D32: 지역기반 | E32: 김양아 | F32: 여 | G32: 1977-01-11 | H32: 중장년 | I32: 537,669,966 | J32: 1 | K32: AI·데이터 기반 K-브랜드 글로벌 진출 통합 플랫폼 (AMAZE GLOBAL INNOVATING SOLUTION) | L32: 서울 | M32: 지식서비스 | N32: 정보ㆍ통신 | O32: 초기 | P32: 정보ㆍ통신7 | Q32: =TODAY() -> 46120 | R32: 0 | S32: 0 | T32: 0 | U32: 0 | V32: =IF(OR(S32="○",T32="○",U32="○"),2,0) -> 0 | W32: 0 | X32: 0 | Y32: 0 | Z32: 0 | AA32: 0 | AB32: =IF(OR(W32="○",X32="○",Y32="○",Z32="○",AA32="○"),"면제",$R32) -> 0
A33: 32 | B33: 20401381 | C33: 2026년도 창업중심대학 지역기반 (예비)창업기업 모집 공고 | D33: 지역기반 | E33: 김영성 | F33: 남 | G33: 1994-04-19 | H33: 청년 | I33: 9,080,000 | J33: 0 | K33: AI SyncBoard[온디바이스 AI 기반 스마트에듀 실시간 양방향 판서솔루션] | L33: 인천 | M33: 지식서비스 | N33: 정보ㆍ통신 | O33: 초기 | P33: 정보ㆍ통신5 | Q33: =TODAY() -> 46120 | R33: 0 | S33: ○ | T33: 0 | U33: 0 | V33: =IF(OR(S33="○",T33="○",U33="○"),2,0) -> 2 | W33: 0 | X33: 0 | Y33: 0 | Z33: 0 | AA33: 0 | AB33: =IF(OR(W33="○",X33="○",Y33="○",Z33="○",AA33="○"),"면제",$R33) -> 0
A34: 33 | B34: 20401390 | C34: 2026년도 창업중심대학 지역기반 (예비)창업기업 모집 공고 | D34: 지역기반 | E34: 한동용 | F34: 남 | G34: 1989-05-29 | H34: 청년 | I34: 436,000,000 | J34: 2 | K34: 서술형 학습데이터 기반 개념 이해 판별 AI 분석엔진(Concept Note Lab) 개발 및 교육기관 확산(B2B SaaS) | L34: 경기 | M34: 지식서비스 | N34: 정보ㆍ통신 | O34: 초기 | P34: 정보ㆍ통신5 | Q34: =TODAY() -> 46120 | R34: 0 | S34: 0 | T34: 0 | U34: 0 | V34: =IF(OR(S34="○",T34="○",U34="○"),2,0) -> 0 | W34: 0 | X34: 0 | Y34: 0 | Z34: 0 | AA34: 0 | AB34: =IF(OR(W34="○",X34="○",Y34="○",Z34="○",AA34="○"),"면제",$R34) -> 0
A35: 34 | B35: 20401396 | C35: 2026년도 창업중심대학 지역기반 (예비)창업기업 모집 공고 | D35: 지역기반 | E35: 장용원 | F35: 남 | G35: 1990-05-19 | H35: 청년 | I35: 30,000,000 | J35: 2 | K35: 제작사 브랜딩 기반 B2C 콘텐츠 제작사 | L35: 경기 | M35: 지식서비스 | N35: 정보ㆍ통신 | O35: 초기 | P35: 정보ㆍ통신6 | Q35: =TODAY() -> 46120 | R35: 0 | S35: 0 | T35: 0 | U35: 0 | V35: =IF(OR(S35="○",T35="○",U35="○"),2,0) -> 0 | W35: 0 | X35: 0 | Y35: 0 | Z35: 0 | AA35: 0 | AB35: =IF(OR(W35="○",X35="○",Y35="○",Z35="○",AA35="○"),"면제",$R35) -> 0
A36: 35 | B36: 20401399 | C36: 2026년도 창업중심대학 지역기반 (예비)창업기업 모집 공고 | D36: 지역기반 | E36: 이진 | F36: 여 | G36: 1993-05-31 | H36: 청년 | I36: 0 | J36: 0 | K36: 당뇨인들을 위한 병아리콩 앙금과 못난이 고구마 기반의 밀가루 없는 고단백·저당 구움과자 | L36: 경기 | M36: 제조 | N36: 에너지ㆍ자원 | O36: 예비 | P36: 에너지ㆍ자원 | Q36: =TODAY() -> 46120 | R36: 0 | S36: 0 | T36: 0 | U36: 0 | V36: =IF(OR(S36="○",T36="○",U36="○"),2,0) -> 0 | W36: 0 | X36: 0 | Y36: 0 | Z36: 0 | AA36: 0 | AB36: =IF(OR(W36="○",X36="○",Y36="○",Z36="○",AA36="○"),"면제",$R36) -> 0
A37: 36 | B37: 20401505 | C37: 2026년도 창업중심대학 지역기반 (예비)창업기업 모집 공고 | D37: 지역기반 | E37: 이장우 | F37: 남 | G37: 1973-08-30 | H37: 중장년 | I37: 0 | J37: 0 | K37: 명당AI | L37: 서울 | M37: 지식서비스 | N37: 정보ㆍ통신 | O37: 예비 | P37: 정보ㆍ통신4 | Q37: =TODAY() -> 46120 | R37: 0 | S37: 0 | T37: 0 | U37: 0 | V37: =IF(OR(S37="○",T37="○",U37="○"),2,0) -> 0 | W37: 0 | X37: 0 | Y37: 0 | Z37: 0 | AA37: 0 | AB37: =IF(OR(W37="○",X37="○",Y37="○",Z37="○",AA37="○"),"면제",$R37) -> 0
A38: 37 | B38: 20401527 | C38: 2026년도 창업중심대학 지역기반 (예비)창업기업 모집 공고 | D38: 지역기반 | E38: 유현욱 | F38: 남 | G38: 1995-02-13 | H38: 청년 | I38: 0 | J38: 0 | K38: 대화가 곧 일기가 되는 자동 라이프로깅 메신저, ‘라타톡(Ratatoc)‘ 상용화 | L38: 경기 | M38: 지식서비스 | N38: 정보ㆍ통신 | O38: 예비 | P38: 정보ㆍ통신6 | Q38: =TODAY() -> 46120 | R38: 0 | S38: 0 | T38: 0 | U38: 0 | V38: =IF(OR(S38="○",T38="○",U38="○"),2,0) -> 0 | W38: 0 | X38: 0 | Y38: 0 | Z38: 0 | AA38: 0 | AB38: =IF(OR(W38="○",X38="○",Y38="○",Z38="○",AA38="○"),"면제",$R38) -> 0
A39: 38 | B39: 20401528 | C39: 2026년도 창업중심대학 지역기반 (예비)창업기업 모집 공고 | D39: 지역기반 | E39: 고태욱 | F39: 남 | G39: 1993-01-05 | H39: 청년 | I39: 0 | J39: 0 | K39: 자율 비행 및 AI 꽃 인식 기술이 적용된 초소형 드론 기반 인공수분 서비스 | L39: 경기 | M39: 제조 | N39: 전기ㆍ전자 | O39: 예비 | P39: 전기ㆍ전자 | Q39: =TODAY() -> 46120 | R39: 0 | S39: 0 | T39: 0 | U39: 0 | V39: =IF(OR(S39="○",T39="○",U39="○"),2,0) -> 0 | W39: 0 | X39: 0 | Y39: 0 | Z39: 0 | AA39: 0 | AB39: =IF(OR(W39="○",X39="○",Y39="○",Z39="○",AA39="○"),"면제",$R39) -> 0
A40: 39 | B40: 20401529 | C40: 2026년도 창업중심대학 지역기반 (예비)창업기업 모집 공고 | D40: 지역기반 | E40: 이수연 | F40: 여 | G40: 1995-07-23 | H40: 청년 | I40: 0 | J40: 0 | K40: AI 패턴 분석 기술이 적용된 게이미피케이션 자기탐색 기능의 (비치료적 자기이해 경험을 제공하는) 나로소 AI 앱 서비스 | L40: 서울 | M40: 지식서비스 | N40: 정보ㆍ통신 | O40: 예비 | P40: 정보ㆍ통신6 | Q40: =TODAY() -> 46120 | R40: 0 | S40: 0 | T40: 0 | U40: 0 | V40: =IF(OR(S40="○",T40="○",U40="○"),2,0) -> 0 | W40: 0 | X40: 0 | Y40: 0 | Z40: 0 | AA40: 0 | AB40: =IF(OR(W40="○",X40="○",Y40="○",Z40="○",AA40="○"),"면제",$R40) -> 0
...

Sheet 집계
A1: 평가대상 | H1: 1 | I1: 1 | J1: 1 | K1: 2 | N1: 3 | Q1: 4 | T1: 5 | W1: 평가종합 | AE1: 대학발 지역주력 | AF1: 지역주력 일치의견
A2: 순번 | B2: 과제번호 | C2: 공고구분 | D2: 대표자명 | E2: 분과 | F2: 과제명 | G2: 특이사항 | H2: ="검토"&H1 -> 검토1 | I2: ="위원"&H1 -> 위원1 | J2: ="순위"&H1 -> 순위1 | K2: ="검토"&K1 -> 검토2 | L2: ="위원"&K1 -> 위원2 | M2: ="순위"&K1 -> 순위2 | N2: ="검토"&N1 -> 검토3 | O2: ="위원"&N1 -> 위원3 | P2: ="순위"&N1 -> 순위3 | Q2: ="검토"&Q1 -> 검토4 | R2: ="위원"&Q1 -> 위원4 | S2: ="순위"&Q1 -> 순위4 | T2: ="검토"&T1 -> 검토5 | U2: ="위원"&T1 -> 위원5 | V2: ="순위"&T1 -> 순위5 | W2: 사전검토 | X2: 평가자수 | Y2: 평점 | Z2: 가점 | AA2: 점수 | AB2: 과락 | AC2: 순위 | AD2: 평가의견 | AE2: 일치여부 | AF2: 지역주력 일치의견
A3: 135 | B3: 20427563 | C3: =IFERROR(VLOOKUP($B3,대상!$B:$AC,MATCH(C$2,대상!$1:$1,0)-1,FALSE),"") -> 지역기반 | D3: =IFERROR(VLOOKUP($B3,대상!$B$1:$AC$2756,MATCH(D$2,대상!$1:$1,0)-1,FALSE),"") -> 김성욱 | E3: =IFERROR(VLOOKUP($B3,대상!$B:$AC,MATCH(E$2,대상!$1:$1,0)-1,FALSE),"") -> 기계ㆍ소재 | F3: =IFERROR(VLOOKUP($B3,대상!$B:$AC,MATCH(F$2,대상!$1:$1,0)-1,FALSE),"") -> 기후위기 재해예방 대응형 지하주차장 침수예방 무동력 배수 필터 | G3: =IFERROR(VLOOKUP($B3,대상!$B:$AC,MATCH(G$2,대상!$1:$1,0)-1,FALSE),"") | H3: =IFERROR(VLOOKUP($B3,[1]평가!$B:$Z,MATCH(LEFT(H$2,2),[1]평가!$7:$7,0)-1,FALSE),"") -> 면제 | I3: =IFERROR(VLOOKUP($B3,[1]평가!$B:$Z,MATCH(LEFT(I$2,2),[1]평가!$7:$7,0)-1,FALSE),"") | J3: =IFERROR(VLOOKUP($B3,[1]평가!$B:$Z,MATCH(LEFT(J$2,2),[1]평가!$7:$7,0)-1,FALSE),"") | K3: =IFERROR(VLOOKUP($B3,[2]평가!$B:$Z,MATCH(LEFT(K$2,2),[2]평가!$7:$7,0)-1,FALSE),"") -> 면제 | L3: =IFERROR(VLOOKUP($B3,[2]평가!$B:$Z,MATCH(LEFT(L$2,2),[2]평가!$7:$7,0)-1,FALSE),"") | M3: =IFERROR(VLOOKUP($B3,[2]평가!$B:$Z,MATCH(LEFT(M$2,2),[2]평가!$7:$7,0)-1,FALSE),"") | N3: =IFERROR(VLOOKUP($B3,[3]평가!$B:$Z,MATCH(LEFT(N$2,2),[3]평가!$7:$7,0)-1,FALSE),"") -> 면제 | O3: =IFERROR(VLOOKUP($B3,[3]평가!$B:$Z,MATCH(LEFT(O$2,2),[3]평가!$7:$7,0)-1,FALSE),"") | P3: =IFERROR(VLOOKUP($B3,[3]평가!$B:$Z,MATCH(LEFT(P$2,2),[3]평가!$7:$7,0)-1,FALSE),"") | Q3: =IFERROR(VLOOKUP($B3,[4]평가!$B:$Z,MATCH(LEFT(Q$2,2),[4]평가!$7:$7,0)-1,FALSE),"") -> 면제 | R3: =IFERROR(VLOOKUP($B3,[4]평가!$B:$Z,MATCH(LEFT(R$2,2),[4]평가!$7:$7,0)-1,FALSE),"") | S3: =IFERROR(VLOOKUP($B3,[4]평가!$B:$Z,MATCH(LEFT(S$2,2),[4]평가!$7:$7,0)-1,FALSE),"") | T3: =IFERROR(VLOOKUP($B3,[5]평가!$B:$Z,MATCH(LEFT(T$2,2),[5]평가!$7:$7,0)-1,FALSE),"") -> 면제 | U3: =IFERROR(VLOOKUP($B3,[5]평가!$B:$Z,MATCH(LEFT(U$2,2),[5]평가!$7:$7,0)-1,FALSE),"") | V3: =IFERROR(VLOOKUP($B3,[5]평가!$B:$Z,MATCH(LEFT(V$2,2),[5]평가!$7:$7,0)-1,FALSE),"") | W3: =IFERROR(VLOOKUP($B3,대상!$B:$AD,MATCH(W$2,대상!$1:$1,0)-1,FALSE),"") -> 면제 | X3: =IF(ISBLANK(B3),"",T$1-COUNTIF(H3:V3,"회피")) -> 5 | Y3: =IF($T$1=X3,(SUM(I3,L3,O3,R3,U3)-MIN(I3,L3,O3,R3,U3)-MAX(I3,L3,O3,R3,U3))/($T$1-2),SUM(I3,L3,O3,R3,U3/X3)) -> 0 | Z3: =IFERROR(VLOOKUP($B3,대상!$B:$AD,MATCH(Z$2,대상!$1:$1,0)-1,FALSE),0) -> 0 | AA3: =IFERROR(IF(W3="면제","100"+Z3,Y3+Z3),"") -> 100 | AB3: =IF(OR(W3="면제",N(Y3)=0),"",IF(AA3<60,"과락","")) | AC3: =IF(N(AA3)=0,"",RANK(AA3,AA$3:AA$202)) -> 1 | AD3: =IFERROR(TEXT(VLOOKUP($B3,[1]평가!$B:$Z,MATCH(AD$2,[1]평가!$6:$6,0)-1,FALSE),"①@ ") & CHAR(13) & TEXT(VLOOKUP($B3,[2]평가!$B:$Z,MATCH(AD$2,[2]평가!$6:$6,0)-1,FALSE),"②@ ") & CHAR(13) & TEXT(VLOOKUP($B3,[3]평가!$B:$Z,MATCH(AD$2,[3]평가!$6:$6,0)-1,FALSE),"③@ ") & CHAR(13) & TEXT(VLOOKUP($B3,[4]평가!$B:$Z,MATCH(AD$2,[4]평가!$6:$6,0)-1,FALSE),"④@ ") & CHAR(13) & TEXT(VLOOKUP($B3,[5]평가!$B:$Z,MATCH(AD$2,[5]평가!$6:$6,0)-1,FALSE),"⑤@ "),"") -> ①기존시장에 대한 진입 전략과 경쟁력확보에 관한 세부적인 전략이 필요함 _x000D_②. _x000D_0_x000D_0_x000D_0 | AE3: =IFERROR(TEXT(VLOOKUP($B3,[1]평가!$B:$Z,MATCH(AE$2,[1]평가!$7:$7,0)-1,FALSE),"①@ ") & CHAR(13) & TEXT(VLOOKUP($B3,[2]평가!$B:$Z,MATCH(AE$2,[2]평가!$7:$7,0)-1,FALSE),"②@ ") & CHAR(13) & TEXT(VLOOKUP($B3,[3]평가!$B:$Z,MATCH(AE$2,[3]평가!$7:$7,0)-1,FALSE),"③@ ") & CHAR(13) & TEXT(VLOOKUP($B3,[4]평가!$B:$Z,MATCH(AE$2,[4]평가!$7:$7,0)-1,FALSE),"④@ ") & CHAR(13) & TEXT(VLOOKUP($B3,[5]평가!$B:$Z,MATCH(AE$2,[5]평가!$7:$7,0)-1,FALSE),"⑤@ "),"") -> 0_x000D_0_x000D_0_x000D_0_x000D_0 | AF3: =IFERROR(TEXT(VLOOKUP($B3,[1]평가!$B:$Z,MATCH(AF$2,[1]평가!$6:$6,0)-1,FALSE),"①@ ") & CHAR(13) & TEXT(VLOOKUP($B3,[2]평가!$B:$Z,MATCH(AF$2,[2]평가!$6:$6,0)-1,FALSE),"②@ ") & CHAR(13) & TEXT(VLOOKUP($B3,[3]평가!$B:$Z,MATCH(AF$2,[3]평가!$6:$6,0)-1,FALSE),"③@ ") & CHAR(13) & TEXT(VLOOKUP($B3,[4]평가!$B:$Z,MATCH(AF$2,[4]평가!$6:$6,0)-1,FALSE),"④@ ") & CHAR(13) & TEXT(VLOOKUP($B3,[5]평가!$B:$Z,MATCH(AF$2,[5]평가!$6:$6,0)-1,FALSE),"⑤@ "),"") -> 0_x000D_0_x000D_0_x000D_0_x000D_0
A4: 195 | B4: 20428674 | C4: =IFERROR(VLOOKUP($B4,대상!$B:$AC,MATCH(C$2,대상!$1:$1,0)-1,FALSE),"") -> 대학발 | D4: =IFERROR(VLOOKUP($B4,대상!$B$1:$AC$2756,MATCH(D$2,대상!$1:$1,0)-1,FALSE),"") -> 박성준 | E4: =IFERROR(VLOOKUP($B4,대상!$B:$AC,MATCH(E$2,대상!$1:$1,0)-1,FALSE),"") -> 기계ㆍ소재 | F4: =IFERROR(VLOOKUP($B4,대상!$B:$AC,MATCH(F$2,대상!$1:$1,0)-1,FALSE),"") -> AI 데이터센터 고발열 대응을 위한 액체냉각용 고방열 냉각유체 개발 및 사업화 | G4: =IFERROR(VLOOKUP($B4,대상!$B:$AC,MATCH(G$2,대상!$1:$1,0)-1,FALSE),"") -> 잠재력 확인 팀 | H4: =IFERROR(VLOOKUP($B4,[1]평가!$B:$Z,MATCH(LEFT(H$2,2),[1]평가!$7:$7,0)-1,FALSE),"") -> 0 | I4: =IFERROR(VLOOKUP($B4,[1]평가!$B:$Z,MATCH(LEFT(I$2,2),[1]평가!$7:$7,0)-1,FALSE),"") -> 97 | J4: =IFERROR(VLOOKUP($B4,[1]평가!$B:$Z,MATCH(LEFT(J$2,2),[1]평가!$7:$7,0)-1,FALSE),"") -> 1 | K4: =IFERROR(VLOOKUP($B4,[2]평가!$B:$Z,MATCH(LEFT(K$2,2),[2]평가!$7:$7,0)-1,FALSE),"") -> 0 | L4: =IFERROR(VLOOKUP($B4,[2]평가!$B:$Z,MATCH(LEFT(L$2,2),[2]평가!$7:$7,0)-1,FALSE),"") -> 97 | M4: =IFERROR(VLOOKUP($B4,[2]평가!$B:$Z,MATCH(LEFT(M$2,2),[2]평가!$7:$7,0)-1,FALSE),"") -> 4 | N4: =IFERROR(VLOOKUP($B4,[3]평가!$B:$Z,MATCH(LEFT(N$2,2),[3]평가!$7:$7,0)-1,FALSE),"") -> 0 | O4: =IFERROR(VLOOKUP($B4,[3]평가!$B:$Z,MATCH(LEFT(O$2,2),[3]평가!$7:$7,0)-1,FALSE),"") -> 97 | P4: =IFERROR(VLOOKUP($B4,[3]평가!$B:$Z,MATCH(LEFT(P$2,2),[3]평가!$7:$7,0)-1,FALSE),"") -> 2 | Q4: =IFERROR(VLOOKUP($B4,[4]평가!$B:$Z,MATCH(LEFT(Q$2,2),[4]평가!$7:$7,0)-1,FALSE),"") -> 0 | R4: =IFERROR(VLOOKUP($B4,[4]평가!$B:$Z,MATCH(LEFT(R$2,2),[4]평가!$7:$7,0)-1,FALSE),"") -> 97 | S4: =IFERROR(VLOOKUP($B4,[4]평가!$B:$Z,MATCH(LEFT(S$2,2),[4]평가!$7:$7,0)-1,FALSE),"") -> 1 | T4: =IFERROR(VLOOKUP($B4,[5]평가!$B:$Z,MATCH(LEFT(T$2,2),[5]평가!$7:$7,0)-1,FALSE),"") -> 0 | U4: =IFERROR(VLOOKUP($B4,[5]평가!$B:$Z,MATCH(LEFT(U$2,2),[5]평가!$7:$7,0)-1,FALSE),"") -> 97 | V4: =IFERROR(VLOOKUP($B4,[5]평가!$B:$Z,MATCH(LEFT(V$2,2),[5]평가!$7:$7,0)-1,FALSE),"") -> 1 | W4: =IFERROR(VLOOKUP($B4,대상!$B:$AD,MATCH(W$2,대상!$1:$1,0)-1,FALSE),"") -> 0 | X4: =IF(ISBLANK(B4),"",T$1-COUNTIF(H4:V4,"회피")) -> 5 | Y4: =IF($T$1=X4,(SUM(I4,L4,O4,R4,U4)-MIN(I4,L4,O4,R4,U4)-MAX(I4,L4,O4,R4,U4))/($T$1-2),SUM(I4,L4,O4,R4,U4/X4)) -> 97 | Z4: =IFERROR(VLOOKUP($B4,대상!$B:$AD,MATCH(Z$2,대상!$1:$1,0)-1,FALSE),0) -> 0 | AA4: =IFERROR(IF(W4="면제","100"+Z4,Y4+Z4),"") -> 97 | AB4: =IF(OR(W4="면제",N(Y4)=0),"",IF(AA4<60,"과락","")) | AC4: =IF(N(AA4)=0,"",RANK(AA4,AA$3:AA$202)) -> 2 | AD4: =IFERROR(TEXT(VLOOKUP($B4,[1]평가!$B:$Z,MATCH(AD$2,[1]평가!$6:$6,0)-1,FALSE),"①@ ") & CHAR(13) & TEXT(VLOOKUP($B4,[2]평가!$B:$Z,MATCH(AD$2,[2]평가!$6:$6,0)-1,FALSE),"②@ ") & CHAR(13) & TEXT(VLOOKUP($B4,[3]평가!$B:$Z,MATCH(AD$2,[3]평가!$6:$6,0)-1,FALSE),"③@ ") & CHAR(13) & TEXT(VLOOKUP($B4,[4]평가!$B:$Z,MATCH(AD$2,[4]평가!$6:$6,0)-1,FALSE),"④@ ") & CHAR(13) & TEXT(VLOOKUP($B4,[5]평가!$B:$Z,MATCH(AD$2,[5]평가!$6:$6,0)-1,FALSE),"⑤@ "),"") -> ①사회적으러 주목받는 기술이나 기슬적인 소개가 부족함 후발 진입자에 대한 방어 대첵이 필요함 _x000D_②사업게획은 우수하며 비즈니스 모델이 구체적이며 기술 차별성 및 목표시장에 대한 접근방법이 우수하여 사업성이 충분함.. _x000D_③- 아이템 배경 및 필요성에 대해 구체적으로 작성됨 - 사업화 로드맵이 미흡하여 보완이 필요함 _x000D_④사업 영역에 대한 문제 인식 및 관련된 대표자 역량이 우수함. 현재 제품 개발 상황에 따른 계획이 설정되어있음. _x000D_⑤기존 냉각유체의 문제점을 개선하는 과제임. 기술개발이 완료되면 시장 진입이 가능할것으로 판단됨. | AE4: =IFERROR(TEXT(VLOOKUP($B4,[1]평가!$B:$Z,MATCH(AE$2,[1]평가!$7:$7,0)-1,FALSE),"①@ ") & CHAR(13) & TEXT(VLOOKUP($B4,[2]평가!$B:$Z,MATCH(AE$2,[2]평가!$7:$7,0)-1,FALSE),"②@ ") & CHAR(13) & TEXT(VLOOKUP($B4,[3]평가!$B:$Z,MATCH(AE$2,[3]평가!$7:$7,0)-1,FALSE),"③@ ") & CHAR(13) & TEXT(VLOOKUP($B4,[4]평가!$B:$Z,MATCH(AE$2,[4]평가!$7:$7,0)-1,FALSE),"④@ ") & CHAR(13) & TEXT(VLOOKUP($B4,[5]평가!$B:$Z,MATCH(AE$2,[5]평가!$7:$7,0)-1,FALSE),"⑤@ "),"") -> ①일치 _x000D_②불일치 _x000D_③불일치 _x000D_④일치 _x000D_0 | AF4: =IFERROR(TEXT(VLOOKUP($B4,[1]평가!$B:$Z,MATCH(AF$2,[1]평가!$6:$6,0)-1,FALSE),"①@ ") & CHAR(13) & TEXT(VLOOKUP($B4,[2]평가!$B:$Z,MATCH(AF$2,[2]평가!$6:$6,0)-1,FALSE),"②@ ") & CHAR(13) & TEXT(VLOOKUP($B4,[3]평가!$B:$Z,MATCH(AF$2,[3]평가!$6:$6,0)-1,FALSE),"③@ ") & CHAR(13) & TEXT(VLOOKUP($B4,[4]평가!$B:$Z,MATCH(AF$2,[4]평가!$6:$6,0)-1,FALSE),"④@ ") & CHAR(13) & TEXT(VLOOKUP($B4,[5]평가!$B:$Z,MATCH(AF$2,[5]평가!$6:$6,0)-1,FALSE),"⑤@ "),"") -> ①계면활성제 기반 분산 안정화 기술로서 지역주력산업과 불일치함 _x000D_②본 사업의 지역 주력 산업인 시스템반도체, 인공지능, 바이오, 지능형 로봇에 일치하지 않음 _x000D_③ 화학 분야로 불일치함. _x000D_④반도체 소재 기술에 관한 것으로, 지역주력산업 일치함 _x000D_0
A5: 159 | B5: 20417596 | C5: =IFERROR(VLOOKUP($B5,대상!$B:$AC,MATCH(C$2,대상!$1:$1,0)-1,FALSE),"") -> 대학발 | D5: =IFERROR(VLOOKUP($B5,대상!$B$1:$AC$2756,MATCH(D$2,대상!$1:$1,0)-1,FALSE),"") -> 전일 | E5: =IFERROR(VLOOKUP($B5,대상!$B:$AC,MATCH(E$2,대상!$1:$1,0)-1,FALSE),"") -> 기계ㆍ소재 | F5: =IFERROR(VLOOKUP($B5,대상!$B:$AC,MATCH(F$2,대상!$1:$1,0)-1,FALSE),"") -> 차세대 600W급 반도체 EUV 노광 공정용 고투과 친환경 펠리클 | G5: =IFERROR(VLOOKUP($B5,대상!$B:$AC,MATCH(G$2,대상!$1:$1,0)-1,FALSE),"") -> 전임교원 | H5: =IFERROR(VLOOKUP($B5,[1]평가!$B:$Z,MATCH(LEFT(H$2,2),[1]평가!$7:$7,0)-1,FALSE),"") -> 0 | I5: =IFERROR(VLOOKUP($B5,[1]평가!$B:$Z,MATCH(LEFT(I$2,2),[1]평가!$7:$7,0)-1,FALSE),"") -> 94 | J5: =IFERROR(VLOOKUP($B5,[1]평가!$B:$Z,MATCH(LEFT(J$2,2),[1]평가!$7:$7,0)-1,FALSE),"") -> 3 | K5: =IFERROR(VLOOKUP($B5,[2]평가!$B:$Z,MATCH(LEFT(K$2,2),[2]평가!$7:$7,0)-1,FALSE),"") -> 0 | L5: =IFERROR(VLOOKUP($B5,[2]평가!$B:$Z,MATCH(LEFT(L$2,2),[2]평가!$7:$7,0)-1,FALSE),"") -> 94 | M5: =IFERROR(VLOOKUP($B5,[2]평가!$B:$Z,MATCH(LEFT(M$2,2),[2]평가!$7:$7,0)-1,FALSE),"") -> 10 | N5: =IFERROR(VLOOKUP($B5,[3]평가!$B:$Z,MATCH(LEFT(N$2,2),[3]평가!$7:$7,0)-1,FALSE),"") -> 0 | O5: =IFERROR(VLOOKUP($B5,[3]평가!$B:$Z,MATCH(LEFT(O$2,2),[3]평가!$7:$7,0)-1,FALSE),"") -> 94 | P5: =IFERROR(VLOOKUP($B5,[3]평가!$B:$Z,MATCH(LEFT(P$2,2),[3]평가!$7:$7,0)-1,FALSE),"") -> 7 | Q5: =IFERROR(VLOOKUP($B5,[4]평가!$B:$Z,MATCH(LEFT(Q$2,2),[4]평가!$7:$7,0)-1,FALSE),"") -> 0 | R5: =IFERROR(VLOOKUP($B5,[4]평가!$B:$Z,MATCH(LEFT(R$2,2),[4]평가!$7:$7,0)-1,FALSE),"") -> 94 | S5: =IFERROR(VLOOKUP($B5,[4]평가!$B:$Z,MATCH(LEFT(S$2,2),[4]평가!$7:$7,0)-1,FALSE),"") -> 2 | T5: =IFERROR(VLOOKUP($B5,[5]평가!$B:$Z,MATCH(LEFT(T$2,2),[5]평가!$7:$7,0)-1,FALSE),"") -> 0 | U5: =IFERROR(VLOOKUP($B5,[5]평가!$B:$Z,MATCH(LEFT(U$2,2),[5]평가!$7:$7,0)-1,FALSE),"") -> 94 | V5: =IFERROR(VLOOKUP($B5,[5]평가!$B:$Z,MATCH(LEFT(V$2,2),[5]평가!$7:$7,0)-1,FALSE),"") -> 2 | W5: =IFERROR(VLOOKUP($B5,대상!$B:$AD,MATCH(W$2,대상!$1:$1,0)-1,FALSE),"") -> 0 | X5: =IF(ISBLANK(B5),"",T$1-COUNTIF(H5:V5,"회피")) -> 5 | Y5: =IF($T$1=X5,(SUM(I5,L5,O5,R5,U5)-MIN(I5,L5,O5,R5,U5)-MAX(I5,L5,O5,R5,U5))/($T$1-2),SUM(I5,L5,O5,R5,U5/X5)) -> 94 | Z5: =IFERROR(VLOOKUP($B5,대상!$B:$AD,MATCH(Z$2,대상!$1:$1,0)-1,FALSE),0) -> 0 | AA5: =IFERROR(IF(W5="면제","100"+Z5,Y5+Z5),"") -> 94 | AB5: =IF(OR(W5="면제",N(Y5)=0),"",IF(AA5<60,"과락","")) | AC5: =IF(N(AA5)=0,"",RANK(AA5,AA$3:AA$202)) -> 3 | AD5: =IFERROR(TEXT(VLOOKUP($B5,[1]평가!$B:$Z,MATCH(AD$2,[1]평가!$6:$6,0)-1,FALSE),"①@ ") & CHAR(13) & TEXT(VLOOKUP($B5,[2]평가!$B:$Z,MATCH(AD$2,[2]평가!$6:$6,0)-1,FALSE),"②@ ") & CHAR(13) & TEXT(VLOOKUP($B5,[3]평가!$B:$Z,MATCH(AD$2,[3]평가!$6:$6,0)-1,FALSE),"③@ ") & CHAR(13) & TEXT(VLOOKUP($B5,[4]평가!$B:$Z,MATCH(AD$2,[4]평가!$6:$6,0)-1,FALSE),"④@ ") & CHAR(13) & TEXT(VLOOKUP($B5,[5]평가!$B:$Z,MATCH(AD$2,[5]평가!$6:$6,0)-1,FALSE),"⑤@ "),"") -> ①기술적 강점은 보이나 시장분석과 경쟁력 분석에 관한 내용과 전략이 부족함 특히 경쟁 진입자에 대한 방어대책이 더욱 적극적으로 요구됨 _x000D_②사업계획서 내용이 우수하며 및 차별성 실현가능성이 구체적으로 제시되어 우수한 것으로 판단됌. _x000D_③- 사업 아이템의 기술이 명확하고 목표 시장 및 현황분석이 잘 구성됨 - 사업화 로드맵 및 자금 조달 계획의 구체적인 기술이 필요함 _x000D_④솔루션 구현 계획이 구체적임. 성장하는 기술 분야에서의 밸류체인 침투 방안을 구체적으로 제시함. _x000D_⑤기술개발 내용이 구체적이며 시장 파급효과가 있을것으로 판단됨. | AE5: =IFERROR(TEXT(VLOOKUP($B5,[1]평가!$B:$Z,MATCH(AE$2,[1]평가!$7:$7,0)-1,FALSE),"①@ ") & CHAR(13) & TEXT(VLOOKUP($B5,[2]평가!$B:$Z,MATCH(AE$2,[2]평가!$7:$7,0)-1,FALSE),"②@ ") & CHAR(13) & TEXT(VLOOKUP($B5,[3]평가!$B:$Z,MATCH(AE$2,[3]평가!$7:$7,0)-1,FALSE),"③@ ") & CHAR(13) & TEXT(VLOOKUP($B5,[4]평가!$B:$Z,MATCH(AE$2,[4]평가!$7:$7,0)-1,FALSE),"④@ ") & CHAR(13) & TEXT(VLOOKUP($B5,[5]평가!$B:$Z,MATCH(AE$2,[5]평가!$7:$7,0)-1,FALSE),"⑤@ "),"") -> ①일치 _x000D_②일치 _x000D_③일치 _x000D_④일치 _x000D_⑤일치 | AF5: =IFERROR(TEXT(VLOOKUP($B5,[1]평가!$B:$Z,MATCH(AF$2,[1]평가!$6:$6,0)-1,FALSE),"①@ ") & CHAR(13) & TEXT(VLOOKUP($B5,[2]평가!$B:$Z,MATCH(AF$2,[2]평가!$6:$6,0)-1,FALSE),"②@ ") & CHAR(13) & TEXT(VLOOKUP($B5,[3]평가!$B:$Z,MATCH(AF$2,[3]평가!$6:$6,0)-1,FALSE),"③@ ") & CHAR(13) & TEXT(VLOOKUP($B5,[4]평가!$B:$Z,MATCH(AF$2,[4]평가!$6:$6,0)-1,FALSE),"④@ ") & CHAR(13) & TEXT(VLOOKUP($B5,[5]평가!$B:$Z,MATCH(AF$2,[5]평가!$6:$6,0)-1,FALSE),"⑤@ "),"") -> ①EUV팰리클기술을 이용하여 반도체제조공정중 불량율을 낮추고 생산수율을 높일수 이ㅛ는 기술로서 지역주력산업과 일치함 _x000D_②본 사업의 지역주력산업 연계 분야 일치함. _x000D_③반도체 부품용 나노소재 개발에대한 내용으로 분야 일치 _x000D_④시스템반도체 부품 기술로, 지역주력산업 일치함 _x000D_⑤시스템반도체 주력에 적합함
A6: 82 | B6: 20413111 | C6: =IFERROR(VLOOKUP($B6,대상!$B:$AC,MATCH(C$2,대상!$1:$1,0)-1,FALSE),"") -> 지역기반 | D6: =IFERROR(VLOOKUP($B6,대상!$B$1:$AC$2756,MATCH(D$2,대상!$1:$1,0)-1,FALSE),"") -> 안지인 | E6: =IFERROR(VLOOKUP($B6,대상!$B:$AC,MATCH(E$2,대상!$1:$1,0)-1,FALSE),"") -> 기계ㆍ소재 | F6: =IFERROR(VLOOKUP($B6,대상!$B:$AC,MATCH(F$2,대상!$1:$1,0)-1,FALSE),"") -> 건설현장 컨테이너용 ‘재사용 가능한 모듈 칸막이 Easy-Wall’ 제품화 및 사업화 | G6: =IFERROR(VLOOKUP($B6,대상!$B:$AC,MATCH(G$2,대상!$1:$1,0)-1,FALSE),"") | H6: =IFERROR(VLOOKUP($B6,[1]평가!$B:$Z,MATCH(LEFT(H$2,2),[1]평가!$7:$7,0)-1,FALSE),"") -> 0 | I6: =IFERROR(VLOOKUP($B6,[1]평가!$B:$Z,MATCH(LEFT(I$2,2),[1]평가!$7:$7,0)-1,FALSE),"") -> 94 | J6: =IFERROR(VLOOKUP($B6,[1]평가!$B:$Z,MATCH(LEFT(J$2,2),[1]평가!$7:$7,0)-1,FALSE),"") -> 2 | K6: =IFERROR(VLOOKUP($B6,[2]평가!$B:$Z,MATCH(LEFT(K$2,2),[2]평가!$7:$7,0)-1,FALSE),"") -> 0 | L6: =IFERROR(VLOOKUP($B6,[2]평가!$B:$Z,MATCH(LEFT(L$2,2),[2]평가!$7:$7,0)-1,FALSE),"") -> 97 | M6: =IFERROR(VLOOKUP($B6,[2]평가!$B:$Z,MATCH(LEFT(M$2,2),[2]평가!$7:$7,0)-1,FALSE),"") -> 1 | N6: =IFERROR(VLOOKUP($B6,[3]평가!$B:$Z,MATCH(LEFT(N$2,2),[3]평가!$7:$7,0)-1,FALSE),"") -> 0 | O6: =IFERROR(VLOOKUP($B6,[3]평가!$B:$Z,MATCH(LEFT(O$2,2),[3]평가!$7:$7,0)-1,FALSE),"") -> 91 | P6: =IFERROR(VLOOKUP($B6,[3]평가!$B:$Z,MATCH(LEFT(P$2,2),[3]평가!$7:$7,0)-1,FALSE),"") -> 8 | Q6: =IFERROR(VLOOKUP($B6,[4]평가!$B:$Z,MATCH(LEFT(Q$2,2),[4]평가!$7:$7,0)-1,FALSE),"") -> 0 | R6: =IFERROR(VLOOKUP($B6,[4]평가!$B:$Z,MATCH(LEFT(R$2,2),[4]평가!$7:$7,0)-1,FALSE),"") -> 89 | S6: =IFERROR(VLOOKUP($B6,[4]평가!$B:$Z,MATCH(LEFT(S$2,2),[4]평가!$7:$7,0)-1,FALSE),"") -> 6 | T6: =IFERROR(VLOOKUP($B6,[5]평가!$B:$Z,MATCH(LEFT(T$2,2),[5]평가!$7:$7,0)-1,FALSE),"") -> 0 | U6: =IFERROR(VLOOKUP($B6,[5]평가!$B:$Z,MATCH(LEFT(U$2,2),[5]평가!$7:$7,0)-1,FALSE),"") -> 90 | V6: =IFERROR(VLOOKUP($B6,[5]평가!$B:$Z,MATCH(LEFT(V$2,2),[5]평가!$7:$7,0)-1,FALSE),"") -> 4 | W6: =IFERROR(VLOOKUP($B6,대상!$B:$AD,MATCH(W$2,대상!$1:$1,0)-1,FALSE),"") -> 0 | X6: =IF(ISBLANK(B6),"",T$1-COUNTIF(H6:V6,"회피")) -> 5 | Y6: =IF($T$1=X6,(SUM(I6,L6,O6,R6,U6)-MIN(I6,L6,O6,R6,U6)-MAX(I6,L6,O6,R6,U6))/($T$1-2),SUM(I6,L6,O6,R6,U6/X6)) -> 91.666667 | Z6: =IFERROR(VLOOKUP($B6,대상!$B:$AD,MATCH(Z$2,대상!$1:$1,0)-1,FALSE),0) -> 2 | AA6: =IFERROR(IF(W6="면제","100"+Z6,Y6+Z6),"") -> 93.666667 | AB6: =IF(OR(W6="면제",N(Y6)=0),"",IF(AA6<60,"과락","")) | AC6: =IF(N(AA6)=0,"",RANK(AA6,AA$3:AA$202)) -> 4 | AD6: =IFERROR(TEXT(VLOOKUP($B6,[1]평가!$B:$Z,MATCH(AD$2,[1]평가!$6:$6,0)-1,FALSE),"①@ ") & CHAR(13) & TEXT(VLOOKUP($B6,[2]평가!$B:$Z,MATCH(AD$2,[2]평가!$6:$6,0)-1,FALSE),"②@ ") & CHAR(13) & TEXT(VLOOKUP($B6,[3]평가!$B:$Z,MATCH(AD$2,[3]평가!$6:$6,0)-1,FALSE),"③@ ") & CHAR(13) & TEXT(VLOOKUP($B6,[4]평가!$B:$Z,MATCH(AD$2,[4]평가!$6:$6,0)-1,FALSE),"④@ ") & CHAR(13) & TEXT(VLOOKUP($B6,[5]평가!$B:$Z,MATCH(AD$2,[5]평가!$6:$6,0)-1,FALSE),"⑤@ "),"") -> ①기술적 강점은 보이나 시장분석과 경쟁력 분석에 관한 내용과 전략이 부족함 특히 경쟁 진입자에 대한 방어대책이 더욱 적극적으로 요구됨 _x000D_②사업계획서의 내용은 양호하나 재사용에 대한 강도 및 내구성 검증이 선행되어야 안전성이 확보가능하나 규격 제시가 미흡함. _x000D_③- 사업화를 위한 목표 시장 분석이 명확하게 작성됨 - 창업 아이템의 구체화된 제시와 협약기간내 목표 방안의 구체적인 제시가 필요함 _x000D_④현장에서 발생가능한 문제를 타겟한 솔루션을 제안함. 현장의 니즈와 침투 방안에 대한 더 면밀한 사전 조사가 다소 부족함. _x000D_⑤난연 칸막이에 대한 필요성이 보이며, 기술개발의 내용이 구체적으로 설명됨. | AE6: =IFERROR(TEXT(VLOOKUP($B6,[1]평가!$B:$Z,MATCH(AE$2,[1]평가!$7:$7,0)-1,FALSE),"①@ ") & CHAR(13) & TEXT(VLOOKUP($B6,[2]평가!$B:$Z,MATCH(AE$2,[2]평가!$7:$7,0)-1,FALSE),"②@ ") & CHAR(13) & TEXT(VLOOKUP($B6,[3]평가!$B:$Z,MATCH(AE$2,[3]평가!$7:$7,0)-1,FALSE),"③@ ") & CHAR(13) & TEXT(VLOOKUP($B6,[4]평가!$B:$Z,MATCH(AE$2,[4]평가!$7:$7,0)-1,FALSE),"④@ ") & CHAR(13) & TEXT(VLOOKUP($B6,[5]평가!$B:$Z,MATCH(AE$2,[5]평가!$7:$7,0)-1,FALSE),"⑤@ "),"") -> 0_x000D_0_x000D_0_x000D_0_x000D_0 | AF6: =IFERROR(TEXT(VLOOKUP($B6,[1]평가!$B:$Z,MATCH(AF$2,[1]평가!$6:$6,0)-1,FALSE),"①@ ") & CHAR(13) & TEXT(VLOOKUP($B6,[2]평가!$B:$Z,MATCH(AF$2,[2]평가!$6:$6,0)-1,FALSE),"②@ ") & CHAR(13) & TEXT(VLOOKUP($B6,[3]평가!$B:$Z,MATCH(AF$2,[3]평가!$6:$6,0)-1,FALSE),"③@ ") & CHAR(13) & TEXT(VLOOKUP($B6,[4]평가!$B:$Z,MATCH(AF$2,[4]평가!$6:$6,0)-1,FALSE),"④@ ") & CHAR(13) & TEXT(VLOOKUP($B6,[5]평가!$B:$Z,MATCH(AF$2,[5]평가!$6:$6,0)-1,FALSE),"⑤@ "),"") -> 0_x000D_0_x000D_0_x000D_0_x000D_0
A7: 116 | B7: 20422710 | C7: =IFERROR(VLOOKUP($B7,대상!$B:$AC,MATCH(C$2,대상!$1:$1,0)-1,FALSE),"") -> 지역기반 | D7: =IFERROR(VLOOKUP($B7,대상!$B$1:$AC$2756,MATCH(D$2,대상!$1:$1,0)-1,FALSE),"") -> 유봉현 | E7: =IFERROR(VLOOKUP($B7,대상!$B:$AC,MATCH(E$2,대상!$1:$1,0)-1,FALSE),"") -> 기계ㆍ소재 | F7: =IFERROR(VLOOKUP($B7,대상!$B:$AC,MATCH(F$2,대상!$1:$1,0)-1,FALSE),"") -> 고화질 OLED 폴더블 디스플레이용 그라파이트 고열전도, 고탄성 방열소재 개발 | G7: =IFERROR(VLOOKUP($B7,대상!$B:$AC,MATCH(G$2,대상!$1:$1,0)-1,FALSE),"") | H7: =IFERROR(VLOOKUP($B7,[1]평가!$B:$Z,MATCH(LEFT(H$2,2),[1]평가!$7:$7,0)-1,FALSE),"") -> 0 | I7: =IFERROR(VLOOKUP($B7,[1]평가!$B:$Z,MATCH(LEFT(I$2,2),[1]평가!$7:$7,0)-1,FALSE),"") -> 92 | J7: =IFERROR(VLOOKUP($B7,[1]평가!$B:$Z,MATCH(LEFT(J$2,2),[1]평가!$7:$7,0)-1,FALSE),"") -> 6 | K7: =IFERROR(VLOOKUP($B7,[2]평가!$B:$Z,MATCH(LEFT(K$2,2),[2]평가!$7:$7,0)-1,FALSE),"") -> 0 | L7: =IFERROR(VLOOKUP($B7,[2]평가!$B:$Z,MATCH(LEFT(L$2,2),[2]평가!$7:$7,0)-1,FALSE),"") -> 95 | M7: =IFERROR(VLOOKUP($B7,[2]평가!$B:$Z,MATCH(LEFT(M$2,2),[2]평가!$7:$7,0)-1,FALSE),"") -> 6 | N7: =IFERROR(VLOOKUP($B7,[3]평가!$B:$Z,MATCH(LEFT(N$2,2),[3]평가!$7:$7,0)-1,FALSE),"") -> 0 | O7: =IFERROR(VLOOKUP($B7,[3]평가!$B:$Z,MATCH(LEFT(O$2,2),[3]평가!$7:$7,0)-1,FALSE),"") -> 95 | P7: =IFERROR(VLOOKUP($B7,[3]평가!$B:$Z,MATCH(LEFT(P$2,2),[3]평가!$7:$7,0)-1,FALSE),"") -> 6 | Q7: =IFERROR(VLOOKUP($B7,[4]평가!$B:$Z,MATCH(LEFT(Q$2,2),[4]평가!$7:$7,0)-1,FALSE),"") -> 0 | R7: =IFERROR(VLOOKUP($B7,[4]평가!$B:$Z,MATCH(LEFT(R$2,2),[4]평가!$7:$7,0)-1,FALSE),"") -> 94 | S7: =IFERROR(VLOOKUP($B7,[4]평가!$B:$Z,MATCH(LEFT(S$2,2),[4]평가!$7:$7,0)-1,FALSE),"") -> 2 | T7: =IFERROR(VLOOKUP($B7,[5]평가!$B:$Z,MATCH(LEFT(T$2,2),[5]평가!$7:$7,0)-1,FALSE),"") -> 0 | U7: =IFERROR(VLOOKUP($B7,[5]평가!$B:$Z,MATCH(LEFT(U$2,2),[5]평가!$7:$7,0)-1,FALSE),"") -> 92 | V7: =IFERROR(VLOOKUP($B7,[5]평가!$B:$Z,MATCH(LEFT(V$2,2),[5]평가!$7:$7,0)-1,FALSE),"") -> 4 | W7: =IFERROR(VLOOKUP($B7,대상!$B:$AD,MATCH(W$2,대상!$1:$1,0)-1,FALSE),"") -> 0 | X7: =IF(ISBLANK(B7),"",T$1-COUNTIF(H7:V7,"회피")) -> 5 | Y7: =IF($T$1=X7,(SUM(I7,L7,O7,R7,U7)-MIN(I7,L7,O7,R7,U7)-MAX(I7,L7,O7,R7,U7))/($T$1-2),SUM(I7,L7,O7,R7,U7/X7)) -> 93.666667 | Z7: =IFERROR(VLOOKUP($B7,대상!$B:$AD,MATCH(Z$2,대상!$1:$1,0)-1,FALSE),0) -> 0 | AA7: =IFERROR(IF(W7="면제","100"+Z7,Y7+Z7),"") -> 93.666667 | AB7: =IF(OR(W7="면제",N(Y7)=0),"",IF(AA7<60,"과락","")) | AC7: =IF(N(AA7)=0,"",RANK(AA7,AA$3:AA$202)) -> 4 | AD7: =IFERROR(TEXT(VLOOKUP($B7,[1]평가!$B:$Z,MATCH(AD$2,[1]평가!$6:$6,0)-1,FALSE),"①@ ") & CHAR(13) & TEXT(VLOOKUP($B7,[2]평가!$B:$Z,MATCH(AD$2,[2]평가!$6:$6,0)-1,FALSE),"②@ ") & CHAR(13) & TEXT(VLOOKUP($B7,[3]평가!$B:$Z,MATCH(AD$2,[3]평가!$6:$6,0)-1,FALSE),"③@ ") & CHAR(13) & TEXT(VLOOKUP($B7,[4]평가!$B:$Z,MATCH(AD$2,[4]평가!$6:$6,0)-1,FALSE),"④@ ") & CHAR(13) & TEXT(VLOOKUP($B7,[5]평가!$B:$Z,MATCH(AD$2,[5]평가!$6:$6,0)-1,FALSE),"⑤@ "),"") -> ①기존시장에 대한 진입 전략과 경쟁력확보에 관한 세부적인 전략이 필요함 _x000D_②사업 추진 계획은 우수하며 시장 계획의 구체적이고 기술성 및 목ㅍ시장 분석이 구체적으로 제시되어 실현 가능성이 충분함. _x000D_③- 사업 아이템의 상세 기술 및 목표가 명확하게 상세하기 기술되었음 - 자금 조달 계획 및 발생 매출 계획 등이 미흡하여 보완이 필요함 _x000D_④성장하는 시장에서의 주요 문제를 해결하려는 시도가 우수함. 외부 네트워킹 기반이 우수하고, 제품 개발 역량 및 사업화 역량이 우수함. _x000D_⑤방열소재 기술개발 과제임. 기술개발이 완료되면 수요가 커질것으로 판단됨. 기술개발목표가 설명되어 있음. | AE7: =IFERROR(TEXT(VLOOKUP($B7,[1]평가!$B:$Z,MATCH(AE$2,[1]평가!$7:$7,0)-1,FALSE),"①@ ") & CHAR(13) & TEXT(VLOOKUP($B7,[2]평가!$B:$Z,MATCH(AE$2,[2]평가!$7:$7,0)-1,FALSE),"②@ ") & CHAR(13) & TEXT(VLOOKUP($B7,[3]평가!$B:$Z,MATCH(AE$2,[3]평가!$7:$7,0)-1,FALSE),"③@ ") & CHAR(13) & TEXT(VLOOKUP($B7,[4]평가!$B:$Z,MATCH(AE$2,[4]평가!$7:$7,0)-1,FALSE),"④@ ") & CHAR(13) & TEXT(VLOOKUP($B7,[5]평가!$B:$Z,MATCH(AE$2,[5]평가!$7:$7,0)-1,FALSE),"⑤@ "),"") -> 0_x000D_0_x000D_0_x000D_0_x000D_0 | AF7: =IFERROR(TEXT(VLOOKUP($B7,[1]평가!$B:$Z,MATCH(AF$2,[1]평가!$6:$6,0)-1,FALSE),"①@ ") & CHAR(13) & TEXT(VLOOKUP($B7,[2]평가!$B:$Z,MATCH(AF$2,[2]평가!$6:$6,0)-1,FALSE),"②@ ") & CHAR(13) & TEXT(VLOOKUP($B7,[3]평가!$B:$Z,MATCH(AF$2,[3]평가!$6:$6,0)-1,FALSE),"③@ ") & CHAR(13) & TEXT(VLOOKUP($B7,[4]평가!$B:$Z,MATCH(AF$2,[4]평가!$6:$6,0)-1,FALSE),"④@ ") & CHAR(13) & TEXT(VLOOKUP($B7,[5]평가!$B:$Z,MATCH(AF$2,[5]평가!$6:$6,0)-1,FALSE),"⑤@ "),"") -> 0_x000D_0_x000D_0_x000D_0_x000D_0
A8: 155 | B8: 20431761 | C8: =IFERROR(VLOOKUP($B8,대상!$B:$AC,MATCH(C$2,대상!$1:$1,0)-1,FALSE),"") -> 지역기반 | D8: =IFERROR(VLOOKUP($B8,대상!$B$1:$AC$2756,MATCH(D$2,대상!$1:$1,0)-1,FALSE),"") -> 김범수 | E8: =IFERROR(VLOOKUP($B8,대상!$B:$AC,MATCH(E$2,대상!$1:$1,0)-1,FALSE),"") -> 기계ㆍ소재 | F8: =IFERROR(VLOOKUP($B8,대상!$B:$AC,MATCH(F$2,대상!$1:$1,0)-1,FALSE),"") -> 저비용 및 소형화를 구현한 상지 재활 로봇 | G8: =IFERROR(VLOOKUP($B8,대상!$B:$AC,MATCH(G$2,대상!$1:$1,0)-1,FALSE),"") | H8: =IFERROR(VLOOKUP($B8,[1]평가!$B:$Z,MATCH(LEFT(H$2,2),[1]평가!$7:$7,0)-1,FALSE),"") -> 0 | I8: =IFERROR(VLOOKUP($B8,[1]평가!$B:$Z,MATCH(LEFT(I$2,2),[1]평가!$7:$7,0)-1,FALSE),"") -> 93 | J8: =IFERROR(VLOOKUP($B8,[1]평가!$B:$Z,MATCH(LEFT(J$2,2),[1]평가!$7:$7,0)-1,FALSE),"") -> 4 | K8: =IFERROR(VLOOKUP($B8,[2]평가!$B:$Z,MATCH(LEFT(K$2,2),[2]평가!$7:$7,0)-1,FALSE),"") -> 0 | L8: =IFERROR(VLOOKUP($B8,[2]평가!$B:$Z,MATCH(LEFT(L$2,2),[2]평가!$7:$7,0)-1,FALSE),"") -> 92 | M8: =IFERROR(VLOOKUP($B8,[2]평가!$B:$Z,MATCH(LEFT(M$2,2),[2]평가!$7:$7,0)-1,FALSE),"") -> 12 | N8: =IFERROR(VLOOKUP($B8,[3]평가!$B:$Z,MATCH(LEFT(N$2,2),[3]평가!$7:$7,0)-1,FALSE),"") -> 0 | O8: =IFERROR(VLOOKUP($B8,[3]평가!$B:$Z,MATCH(LEFT(O$2,2),[3]평가!$7:$7,0)-1,FALSE),"") -> 98 | P8: =IFERROR(VLOOKUP($B8,[3]평가!$B:$Z,MATCH(LEFT(P$2,2),[3]평가!$7:$7,0)-1,FALSE),"") -> 1 | Q8: =IFERROR(VLOOKUP($B8,[4]평가!$B:$Z,MATCH(LEFT(Q$2,2),[4]평가!$7:$7,0)-1,FALSE),"") -> 0 | R8: =IFERROR(VLOOKUP($B8,[4]평가!$B:$Z,MATCH(LEFT(R$2,2),[4]평가!$7:$7,0)-1,FALSE),"") -> 91 | S8: =IFERROR(VLOOKUP($B8,[4]평가!$B:$Z,MATCH(LEFT(S$2,2),[4]평가!$7:$7,0)-1,FALSE),"") -> 6 | T8: =IFERROR(VLOOKUP($B8,[5]평가!$B:$Z,MATCH(LEFT(T$2,2),[5]평가!$7:$7,0)-1,FALSE),"") -> 0 | U8: =IFERROR(VLOOKUP($B8,[5]평가!$B:$Z,MATCH(LEFT(U$2,2),[5]평가!$7:$7,0)-1,FALSE),"") -> 94 | V8: =IFERROR(VLOOKUP($B8,[5]평가!$B:$Z,MATCH(LEFT(V$2,2),[5]평가!$7:$7,0)-1,FALSE),"") -> 2 | W8: =IFERROR(VLOOKUP($B8,대상!$B:$AD,MATCH(W$2,대상!$1:$1,0)-1,FALSE),"") -> 0 | X8: =IF(ISBLANK(B8),"",T$1-COUNTIF(H8:V8,"회피")) -> 5 | Y8: =IF($T$1=X8,(SUM(I8,L8,O8,R8,U8)-MIN(I8,L8,O8,R8,U8)-MAX(I8,L8,O8,R8,U8))/($T$1-2),SUM(I8,L8,O8,R8,U8/X8)) -> 93 | Z8: =IFERROR(VLOOKUP($B8,대상!$B:$AD,MATCH(Z$2,대상!$1:$1,0)-1,FALSE),0) -> 0 | AA8: =IFERROR(IF(W8="면제","100"+Z8,Y8+Z8),"") -> 93 | AB8: =IF(OR(W8="면제",N(Y8)=0),"",IF(AA8<60,"과락","")) | AC8: =IF(N(AA8)=0,"",RANK(AA8,AA$3:AA$202)) -> 6 | AD8: =IFERROR(TEXT(VLOOKUP($B8,[1]평가!$B:$Z,MATCH(AD$2,[1]평가!$6:$6,0)-1,FALSE),"①@ ") & CHAR(13) & TEXT(VLOOKUP($B8,[2]평가!$B:$Z,MATCH(AD$2,[2]평가!$6:$6,0)-1,FALSE),"②@ ") & CHAR(13) & TEXT(VLOOKUP($B8,[3]평가!$B:$Z,MATCH(AD$2,[3]평가!$6:$6,0)-1,FALSE),"③@ ") & CHAR(13) & TEXT(VLOOKUP($B8,[4]평가!$B:$Z,MATCH(AD$2,[4]평가!$6:$6,0)-1,FALSE),"④@ ") & CHAR(13) & TEXT(VLOOKUP($B8,[5]평가!$B:$Z,MATCH(AD$2,[5]평가!$6:$6,0)-1,FALSE),"⑤@ "),"") -> ①사회적으러 주목받는 기술이나 기슬적인 소개가 부족함 후발 진입자에 대한 방어 대첵이 필요함 _x000D_②사업 추진 계획은 우수하며 시장 계획의 구체적이고 기술성 및 목표시장 분석이 구체적으로 제시되어 실현 가능성이 충분함 _x000D_③- 목표 시장 분석 명확하게 잘 작성됨 - 기술의 차별성 및 경쟁력 확보 전략이 구체적으로 작성됨 - 경쟁사의 분석이 미흡하고, 비즈니스 모델의 보완이 필요함 _x000D_④사업 영역에 대한 이해도가 높고 외부 네트워킹이 잘 구축되어있음. 해외 제품 대비 경쟁력에 대한 설명이 부족하고, 매출 산정 근거와 사업화 전략이 다소 부족함. _x000D_⑤재활로봇 개발과제임. 기술개발내용이 구체적으로 설명되어 있으며, 시장진입이 가능할 것으로 보임. | AE8: =IFERROR(TEXT(VLOOKUP($B8,[1]평가!$B:$Z,MATCH(AE$2,[1]평가!$7:$7,0)-1,FALSE),"①@ ") & CHAR(13) & TEXT(VLOOKUP($B8,[2]평가!$B:$Z,MATCH(AE$2,[2]평가!$7:$7,0)-1,FALSE),"②@ ") & CHAR(13) & TEXT(VLOOKUP($B8,[3]평가!$B:$Z,MATCH(AE$2,[3]평가!$7:$7,0)-1,FALSE),"③@ ") & CHAR(13) & TEXT(VLOOKUP($B8,[4]평가!$B:$Z,MATCH(AE$2,[4]평가!$7:$7,0)-1,FALSE),"④@ ") & CHAR(13) & TEXT(VLOOKUP($B8,[5]평가!$B:$Z,MATCH(AE$2,[5]평가!$7:$7,0)-1,FALSE),"⑤@ "),"") -> 0_x000D_0_x000D_0_x000D_0_x000D_0 | AF8: =IFERROR(TEXT(VLOOKUP($B8,[1]평가!$B:$Z,MATCH(AF$2,[1]평가!$6:$6,0)-1,FALSE),"①@ ") & CHAR(13) & TEXT(VLOOKUP($B8,[2]평가!$B:$Z,MATCH(AF$2,[2]평가!$6:$6,0)-1,FALSE),"②@ ") & CHAR(13) & TEXT(VLOOKUP($B8,[3]평가!$B:$Z,MATCH(AF$2,[3]평가!$6:$6,0)-1,FALSE),"③@ ") & CHAR(13) & TEXT(VLOOKUP($B8,[4]평가!$B:$Z,MATCH(AF$2,[4]평가!$6:$6,0)-1,FALSE),"④@ ") & CHAR(13) & TEXT(VLOOKUP($B8,[5]평가!$B:$Z,MATCH(AF$2,[5]평가!$6:$6,0)-1,FALSE),"⑤@ "),"") -> 0_x000D_0_x000D_0_x000D_0_x000D_0
A9: 83 | B9: 20413444 | C9: =IFERROR(VLOOKUP($B9,대상!$B:$AC,MATCH(C$2,대상!$1:$1,0)-1,FALSE),"") -> 지역기반 | D9: =IFERROR(VLOOKUP($B9,대상!$B$1:$AC$2756,MATCH(D$2,대상!$1:$1,0)-1,FALSE),"") -> 박재민 | E9: =IFERROR(VLOOKUP($B9,대상!$B:$AC,MATCH(E$2,대상!$1:$1,0)-1,FALSE),"") -> 기계ㆍ소재 | F9: =IFERROR(VLOOKUP($B9,대상!$B:$AC,MATCH(F$2,대상!$1:$1,0)-1,FALSE),"") -> 반영구 항균/항바이러스 세라믹 복합소재의 제품화를 통한 폐기물 저감 사업화 | G9: =IFERROR(VLOOKUP($B9,대상!$B:$AC,MATCH(G$2,대상!$1:$1,0)-1,FALSE),"") | H9: =IFERROR(VLOOKUP($B9,[1]평가!$B:$Z,MATCH(LEFT(H$2,2),[1]평가!$7:$7,0)-1,FALSE),"") -> 0 | I9: =IFERROR(VLOOKUP($B9,[1]평가!$B:$Z,MATCH(LEFT(I$2,2),[1]평가!$7:$7,0)-1,FALSE),"") -> 91 | J9: =IFERROR(VLOOKUP($B9,[1]평가!$B:$Z,MATCH(LEFT(J$2,2),[1]평가!$7:$7,0)-1,FALSE),"") -> 8 | K9: =IFERROR(VLOOKUP($B9,[2]평가!$B:$Z,MATCH(LEFT(K$2,2),[2]평가!$7:$7,0)-1,FALSE),"") -> 0 | L9: =IFERROR(VLOOKUP($B9,[2]평가!$B:$Z,MATCH(LEFT(L$2,2),[2]평가!$7:$7,0)-1,FALSE),"") -> 96 | M9: =IFERROR(VLOOKUP($B9,[2]평가!$B:$Z,MATCH(LEFT(M$2,2),[2]평가!$7:$7,0)-1,FALSE),"") -> 5 | N9: =IFERROR(VLOOKUP($B9,[3]평가!$B:$Z,MATCH(LEFT(N$2,2),[3]평가!$7:$7,0)-1,FALSE),"") -> 0 | O9: =IFERROR(VLOOKUP($B9,[3]평가!$B:$Z,MATCH(LEFT(O$2,2),[3]평가!$7:$7,0)-1,FALSE),"") -> 97 | P9: =IFERROR(VLOOKUP($B9,[3]평가!$B:$Z,MATCH(LEFT(P$2,2),[3]평가!$7:$7,0)-1,FALSE),"") -> 2 | Q9: =IFERROR(VLOOKUP($B9,[4]평가!$B:$Z,MATCH(LEFT(Q$2,2),[4]평가!$7:$7,0)-1,FALSE),"") -> 0 | R9: =IFERROR(VLOOKUP($B9,[4]평가!$B:$Z,MATCH(LEFT(R$2,2),[4]평가!$7:$7,0)-1,FALSE),"") -> 91 | S9: =IFERROR(VLOOKUP($B9,[4]평가!$B:$Z,MATCH(LEFT(S$2,2),[4]평가!$7:$7,0)-1,FALSE),"") -> 6 | T9: =IFERROR(VLOOKUP($B9,[5]평가!$B:$Z,MATCH(LEFT(T$2,2),[5]평가!$7:$7,0)-1,FALSE),"") -> 0 | U9: =IFERROR(VLOOKUP($B9,[5]평가!$B:$Z,MATCH(LEFT(U$2,2),[5]평가!$7:$7,0)-1,FALSE),"") -> 91 | V9: =IFERROR(VLOOKUP($B9,[5]평가!$B:$Z,MATCH(LEFT(V$2,2),[5]평가!$7:$7,0)-1,FALSE),"") -> 7 | W9: =IFERROR(VLOOKUP($B9,대상!$B:$AD,MATCH(W$2,대상!$1:$1,0)-1,FALSE),"") -> 0 | X9: =IF(ISBLANK(B9),"",T$1-COUNTIF(H9:V9,"회피")) -> 5 | Y9: =IF($T$1=X9,(SUM(I9,L9,O9,R9,U9)-MIN(I9,L9,O9,R9,U9)-MAX(I9,L9,O9,R9,U9))/($T$1-2),SUM(I9,L9,O9,R9,U9/X9)) -> 92.666667 | Z9: =IFERROR(VLOOKUP($B9,대상!$B:$AD,MATCH(Z$2,대상!$1:$1,0)-1,FALSE),0) -> 0 | AA9: =IFERROR(IF(W9="면제","100"+Z9,Y9+Z9),"") -> 92.666667 | AB9: =IF(OR(W9="면제",N(Y9)=0),"",IF(AA9<60,"과락","")) | AC9: =IF(N(AA9)=0,"",RANK(AA9,AA$3:AA$202)) -> 7 | AD9: =IFERROR(TEXT(VLOOKUP($B9,[1]평가!$B:$Z,MATCH(AD$2,[1]평가!$6:$6,0)-1,FALSE),"①@ ") & CHAR(13) & TEXT(VLOOKUP($B9,[2]평가!$B:$Z,MATCH(AD$2,[2]평가!$6:$6,0)-1,FALSE),"②@ ") & CHAR(13) & TEXT(VLOOKUP($B9,[3]평가!$B:$Z,MATCH(AD$2,[3]평가!$6:$6,0)-1,FALSE),"③@ ") & CHAR(13) & TEXT(VLOOKUP($B9,[4]평가!$B:$Z,MATCH(AD$2,[4]평가!$6:$6,0)-1,FALSE),"④@ ") & CHAR(13) & TEXT(VLOOKUP($B9,[5]평가!$B:$Z,MATCH(AD$2,[5]평가!$6:$6,0)-1,FALSE),"⑤@ "),"") -> ①기술적 강점은 보이나 시장분석과 경쟁력 분석에 관한 내용과 전략이 부족함 특히 경쟁 진입자에 대한 방어대책이 더욱 적극적으로 요구됨 _x000D_②사업게획은 우수하며 비즈니스 모델이 구체적이며 기술 차별성 및 목표시장에 대한 접근방법이 우수하여 사업성이 충분함.. _x000D_③- 창업아이템의 실현 가능성 및 준비현황이 구체적으로 작성되었음 - 매출 경로 및 자금 조달 계획의 명확한 제시가 필요함 _x000D_④문제 인식 및 솔루션 개발 진행도가 높음. 지원에 따른 사업 확장 및 성장 전략이 다소 부족함. _x000D_⑤기능성 소재개발수행 과제임. 구체적인 개발계획이 설명되어 있으며, 시장진입및 확장이 가능할것으로 보임 | AE9: =IFERROR(TEXT(VLOOKUP($B9,[1]평가!$B:$Z,MATCH(AE$2,[1]평가!$7:$7,0)-1,FALSE),"①@ ") & CHAR(13) & TEXT(VLOOKUP($B9,[2]평가!$B:$Z,MATCH(AE$2,[2]평가!$7:$7,0)-1,FALSE),"②@ ") & CHAR(13) & TEXT(VLOOKUP($B9,[3]평가!$B:$Z,MATCH(AE$2,[3]평가!$7:$7,0)-1,FALSE),"③@ ") & CHAR(13) & TEXT(VLOOKUP($B9,[4]평가!$B:$Z,MATCH(AE$2,[4]평가!$7:$7,0)-1,FALSE),"④@ ") & CHAR(13) & TEXT(VLOOKUP($B9,[5]평가!$B:$Z,MATCH(AE$2,[5]평가!$7:$7,0)-1,FALSE),"⑤@ "),"") -> 0_x000D_0_x000D_0_x000D_0_x000D_0 | AF9: =IFERROR(TEXT(VLOOKUP($B9,[1]평가!$B:$Z,MATCH(AF$2,[1]평가!$6:$6,0)-1,FALSE),"①@ ") & CHAR(13) & TEXT(VLOOKUP($B9,[2]평가!$B:$Z,MATCH(AF$2,[2]평가!$6:$6,0)-1,FALSE),"②@ ") & CHAR(13) & TEXT(VLOOKUP($B9,[3]평가!$B:$Z,MATCH(AF$2,[3]평가!$6:$6,0)-1,FALSE),"③@ ") & CHAR(13) & TEXT(VLOOKUP($B9,[4]평가!$B:$Z,MATCH(AF$2,[4]평가!$6:$6,0)-1,FALSE),"④@ ") & CHAR(13) & TEXT(VLOOKUP($B9,[5]평가!$B:$Z,MATCH(AF$2,[5]평가!$6:$6,0)-1,FALSE),"⑤@ "),"") -> 0_x000D_0_x000D_0_x000D_0_x000D_0
A10: 141 | B10: 20428661 | C10: =IFERROR(VLOOKUP($B10,대상!$B:$AC,MATCH(C$2,대상!$1:$1,0)-1,FALSE),"") -> 지역기반 | D10: =IFERROR(VLOOKUP($B10,대상!$B$1:$AC$2756,MATCH(D$2,대상!$1:$1,0)-1,FALSE),"") -> 이준영 | E10: =IFERROR(VLOOKUP($B10,대상!$B:$AC,MATCH(E$2,대상!$1:$1,0)-1,FALSE),"") -> 기계ㆍ소재 | F10: =IFERROR(VLOOKUP($B10,대상!$B:$AC,MATCH(F$2,대상!$1:$1,0)-1,FALSE),"") -> AI LMS 디지털 트윈 시뮬레이션 솔루션 | G10: =IFERROR(VLOOKUP($B10,대상!$B:$AC,MATCH(G$2,대상!$1:$1,0)-1,FALSE),"") | H10: =IFERROR(VLOOKUP($B10,[1]평가!$B:$Z,MATCH(LEFT(H$2,2),[1]평가!$7:$7,0)-1,FALSE),"") -> 0 | I10: =IFERROR(VLOOKUP($B10,[1]평가!$B:$Z,MATCH(LEFT(I$2,2),[1]평가!$7:$7,0)-1,FALSE),"") -> 91 | J10: =IFERROR(VLOOKUP($B10,[1]평가!$B:$Z,MATCH(LEFT(J$2,2),[1]평가!$7:$7,0)-1,FALSE),"") -> 8 | K10: =IFERROR(VLOOKUP($B10,[2]평가!$B:$Z,MATCH(LEFT(K$2,2),[2]평가!$7:$7,0)-1,FALSE),"") -> 0 | L10: =IFERROR(VLOOKUP($B10,[2]평가!$B:$Z,MATCH(LEFT(L$2,2),[2]평가!$7:$7,0)-1,FALSE),"") -> 95 | M10: =IFERROR(VLOOKUP($B10,[2]평가!$B:$Z,MATCH(LEFT(M$2,2),[2]평가!$7:$7,0)-1,FALSE),"") -> 6 | N10: =IFERROR(VLOOKUP($B10,[3]평가!$B:$Z,MATCH(LEFT(N$2,2),[3]평가!$7:$7,0)-1,FALSE),"") -> 0 | O10: =IFERROR(VLOOKUP($B10,[3]평가!$B:$Z,MATCH(LEFT(O$2,2),[3]평가!$7:$7,0)-1,FALSE),"") -> 96 | P10: =IFERROR(VLOOKUP($B10,[3]평가!$B:$Z,MATCH(LEFT(P$2,2),[3]평가!$7:$7,0)-1,FALSE),"") -> 4 | Q10: =IFERROR(VLOOKUP($B10,[4]평가!$B:$Z,MATCH(LEFT(Q$2,2),[4]평가!$7:$7,0)-1,FALSE),"") -> 0 | R10: =IFERROR(VLOOKUP($B10,[4]평가!$B:$Z,MATCH(LEFT(R$2,2),[4]평가!$7:$7,0)-1,FALSE),"") -> 92 | S10: =IFERROR(VLOOKUP($B10,[4]평가!$B:$Z,MATCH(LEFT(S$2,2),[4]평가!$7:$7,0)-1,FALSE),"") -> 4 | T10: =IFERROR(VLOOKUP($B10,[5]평가!$B:$Z,MATCH(LEFT(T$2,2),[5]평가!$7:$7,0)-1,FALSE),"") -> 0 | U10: =IFERROR(VLOOKUP($B10,[5]평가!$B:$Z,MATCH(LEFT(U$2,2),[5]평가!$7:$7,0)-1,FALSE),"") -> 91 | V10: =IFERROR(VLOOKUP($B10,[5]평가!$B:$Z,MATCH(LEFT(V$2,2),[5]평가!$7:$7,0)-1,FALSE),"") -> 7 | W10: =IFERROR(VLOOKUP($B10,대상!$B:$AD,MATCH(W$2,대상!$1:$1,0)-1,FALSE),"") -> 0 | X10: =IF(ISBLANK(B10),"",T$1-COUNTIF(H10:V10,"회피")) -> 5 | Y10: =IF($T$1=X10,(SUM(I10,L10,O10,R10,U10)-MIN(I10,L10,O10,R10,U10)-MAX(I10,L10,O10,R10,U10))/($T$1-2),SUM(I10,L10,O10,R10,U10/X10)) -> 92.666667 | Z10: =IFERROR(VLOOKUP($B10,대상!$B:$AD,MATCH(Z$2,대상!$1:$1,0)-1,FALSE),0) -> 0 | AA10: =IFERROR(IF(W10="면제","100"+Z10,Y10+Z10),"") -> 92.666667 | AB10: =IF(OR(W10="면제",N(Y10)=0),"",IF(AA10<60,"과락","")) | AC10: =IF(N(AA10)=0,"",RANK(AA10,AA$3:AA$202)) -> 7 | AD10: =IFERROR(TEXT(VLOOKUP($B10,[1]평가!$B:$Z,MATCH(AD$2,[1]평가!$6:$6,0)-1,FALSE),"①@ ") & CHAR(13) & TEXT(VLOOKUP($B10,[2]평가!$B:$Z,MATCH(AD$2,[2]평가!$6:$6,0)-1,FALSE),"②@ ") & CHAR(13) & TEXT(VLOOKUP($B10,[3]평가!$B:$Z,MATCH(AD$2,[3]평가!$6:$6,0)-1,FALSE),"③@ ") & CHAR(13) & TEXT(VLOOKUP($B10,[4]평가!$B:$Z,MATCH(AD$2,[4]평가!$6:$6,0)-1,FALSE),"④@ ") & CHAR(13) & TEXT(VLOOKUP($B10,[5]평가!$B:$Z,MATCH(AD$2,[5]평가!$6:$6,0)-1,FALSE),"⑤@ "),"") -> ①기술적 강점은 보이나 시장분석과 경쟁력 분석에 관한 내용과 전략이 부족함 특히 경쟁 진입자에 대한 방어대책이 더욱 적극적으로 요구됨 _x000D_②사업 추진 계획은 양호하나 개발개선 사항에 대한 기본자료 제시가 부족하여 실현 가능성이 미비함. _x000D_③- 창업 아이템의 필요성이 명확하고 비즈니스 모델이 구체적으로 작성됨 - 아이템의 기술적 차별성의 보완이 필요함 _x000D_④기존 제품 판매에서 이어지는 아이템 도출 과정이 합리적임. 사업 성장을 위한 지원 필요성과 계획이 상세함. _x000D_⑤자동화설비에 AI 기술을 접목하는 과제임. 기술개발 내용이 구체적으로 설명되어 있으며, 시장 진입이 가능할것으로 보임 | AE10: =IFERROR(TEXT(VLOOKUP($B10,[1]평가!$B:$Z,MATCH(AE$2,[1]평가!$7:$7,0)-1,FALSE),"①@ ") & CHAR(13) & TEXT(VLOOKUP($B10,[2]평가!$B:$Z,MATCH(AE$2,[2]평가!$7:$7,0)-1,FALSE),"②@ ") & CHAR(13) & TEXT(VLOOKUP($B10,[3]평가!$B:$Z,MATCH(AE$2,[3]평가!$7:$7,0)-1,FALSE),"③@ ") & CHAR(13) & TEXT(VLOOKUP($B10,[4]평가!$B:$Z,MATCH(AE$2,[4]평가!$7:$7,0)-1,FALSE),"④@ ") & CHAR(13) & TEXT(VLOOKUP($B10,[5]평가!$B:$Z,MATCH(AE$2,[5]평가!$7:$7,0)-1,FALSE),"⑤@ "),"") -> 0_x000D_0_x000D_0_x000D_0_x000D_0 | AF10: =IFERROR(TEXT(VLOOKUP($B10,[1]평가!$B:$Z,MATCH(AF$2,[1]평가!$6:$6,0)-1,FALSE),"①@ ") & CHAR(13) & TEXT(VLOOKUP($B10,[2]평가!$B:$Z,MATCH(AF$2,[2]평가!$6:$6,0)-1,FALSE),"②@ ") & CHAR(13) & TEXT(VLOOKUP($B10,[3]평가!$B:$Z,MATCH(AF$2,[3]평가!$6:$6,0)-1,FALSE),"③@ ") & CHAR(13) & TEXT(VLOOKUP($B10,[4]평가!$B:$Z,MATCH(AF$2,[4]평가!$6:$6,0)-1,FALSE),"④@ ") & CHAR(13) & TEXT(VLOOKUP($B10,[5]평가!$B:$Z,MATCH(AF$2,[5]평가!$6:$6,0)-1,FALSE),"⑤@ "),"") -> 0_x000D_0_x000D_0_x000D_0_x000D_0
A11: 6 | B11: 20408877 | C11: =IFERROR(VLOOKUP($B11,대상!$B:$AC,MATCH(C$2,대상!$1:$1,0)-1,FALSE),"") -> 지역기반 | D11: =IFERROR(VLOOKUP($B11,대상!$B$1:$AC$2756,MATCH(D$2,대상!$1:$1,0)-1,FALSE),"") -> 노형도 | E11: =IFERROR(VLOOKUP($B11,대상!$B:$AC,MATCH(E$2,대상!$1:$1,0)-1,FALSE),"") -> 기계ㆍ소재 | F11: =IFERROR(VLOOKUP($B11,대상!$B:$AC,MATCH(F$2,대상!$1:$1,0)-1,FALSE),"") -> CFRP 기반 전기차 배터리 하우징 구조 건전성 자가진단 시스템 | G11: =IFERROR(VLOOKUP($B11,대상!$B:$AC,MATCH(G$2,대상!$1:$1,0)-1,FALSE),"") | H11: =IFERROR(VLOOKUP($B11,[1]평가!$B:$Z,MATCH(LEFT(H$2,2),[1]평가!$7:$7,0)-1,FALSE),"") -> 0 | I11: =IFERROR(VLOOKUP($B11,[1]평가!$B:$Z,MATCH(LEFT(I$2,2),[1]평가!$7:$7,0)-1,FALSE),"") -> 91 | J11: =IFERROR(VLOOKUP($B11,[1]평가!$B:$Z,MATCH(LEFT(J$2,2),[1]평가!$7:$7,0)-1,FALSE),"") -> 8 | K11: =IFERROR(VLOOKUP($B11,[2]평가!$B:$Z,MATCH(LEFT(K$2,2),[2]평가!$7:$7,0)-1,FALSE),"") -> 0 | L11: =IFERROR(VLOOKUP($B11,[2]평가!$B:$Z,MATCH(LEFT(L$2,2),[2]평가!$7:$7,0)-1,FALSE),"") -> 95 | M11: =IFERROR(VLOOKUP($B11,[2]평가!$B:$Z,MATCH(LEFT(M$2,2),[2]평가!$7:$7,0)-1,FALSE),"") -> 6 | N11: =IFERROR(VLOOKUP($B11,[3]평가!$B:$Z,MATCH(LEFT(N$2,2),[3]평가!$7:$7,0)-1,FALSE),"") -> 0 | O11: =IFERROR(VLOOKUP($B11,[3]평가!$B:$Z,MATCH(LEFT(O$2,2),[3]평가!$7:$7,0)-1,FALSE),"") -> 96 | P11: =IFERROR(VLOOKUP($B11,[3]평가!$B:$Z,MATCH(LEFT(P$2,2),[3]평가!$7:$7,0)-1,FALSE),"") -> 4 | Q11: =IFERROR(VLOOKUP($B11,[4]평가!$B:$Z,MATCH(LEFT(Q$2,2),[4]평가!$7:$7,0)-1,FALSE),"") -> 0 | R11: =IFERROR(VLOOKUP($B11,[4]평가!$B:$Z,MATCH(LEFT(R$2,2),[4]평가!$7:$7,0)-1,FALSE),"") -> 91 | S11: =IFERROR(VLOOKUP($B11,[4]평가!$B:$Z,MATCH(LEFT(S$2,2),[4]평가!$7:$7,0)-1,FALSE),"") -> 6 | T11: =IFERROR(VLOOKUP($B11,[5]평가!$B:$Z,MATCH(LEFT(T$2,2),[5]평가!$7:$7,0)-1,FALSE),"") -> 0 | U11: =IFERROR(VLOOKUP($B11,[5]평가!$B:$Z,MATCH(LEFT(U$2,2),[5]평가!$7:$7,0)-1,FALSE),"") -> 91 | V11: =IFERROR(VLOOKUP($B11,[5]평가!$B:$Z,MATCH(LEFT(V$2,2),[5]평가!$7:$7,0)-1,FALSE),"") -> 7 | W11: =IFERROR(VLOOKUP($B11,대상!$B:$AD,MATCH(W$2,대상!$1:$1,0)-1,FALSE),"") -> 0 | X11: =IF(ISBLANK(B11),"",T$1-COUNTIF(H11:V11,"회피")) -> 5 | Y11: =IF($T$1=X11,(SUM(I11,L11,O11,R11,U11)-MIN(I11,L11,O11,R11,U11)-MAX(I11,L11,O11,R11,U11))/($T$1-2),SUM(I11,L11,O11,R11,U11/X11)) -> 92.333333 | Z11: =IFERROR(VLOOKUP($B11,대상!$B:$AD,MATCH(Z$2,대상!$1:$1,0)-1,FALSE),0) -> 0 | AA11: =IFERROR(IF(W11="면제","100"+Z11,Y11+Z11),"") -> 92.333333 | AB11: =IF(OR(W11="면제",N(Y11)=0),"",IF(AA11<60,"과락","")) | AC11: =IF(N(AA11)=0,"",RANK(AA11,AA$3:AA$202)) -> 9 | AD11: =IFERROR(TEXT(VLOOKUP($B11,[1]평가!$B:$Z,MATCH(AD$2,[1]평가!$6:$6,0)-1,FALSE),"①@ ") & CHAR(13) & TEXT(VLOOKUP($B11,[2]평가!$B:$Z,MATCH(AD$2,[2]평가!$6:$6,0)-1,FALSE),"②@ ") & CHAR(13) & TEXT(VLOOKUP($B11,[3]평가!$B:$Z,MATCH(AD$2,[3]평가!$6:$6,0)-1,FALSE),"③@ ") & CHAR(13) & TEXT(VLOOKUP($B11,[4]평가!$B:$Z,MATCH(AD$2,[4]평가!$6:$6,0)-1,FALSE),"④@ ") & CHAR(13) & TEXT(VLOOKUP($B11,[5]평가!$B:$Z,MATCH(AD$2,[5]평가!$6:$6,0)-1,FALSE),"⑤@ "),"") -> ①기술적 강점은 보이나 시장분석과 경쟁력 분석에 관한 내용과 전략이 부족함 특히 경쟁 진입자에 대한 방어대책이 더욱 적극적으로 요구됨 _x000D_②사업계획 내용이 우수하며 구체적이고, 기술성 및 기술 차별성이 우수하여 실현 가능성 및 사업화 가능성이 충분함. _x000D_③- 아이템의 기술적 특징 및 차별성이 명확히 작성되어있음 - 전반적으로 BM 모델은 적절하나 사업화 논리 부분이 일부 제한적으로 보여짐 _x000D_④창업 아이템에 대한 배경 설정과 내부적 동기의 결합에 따른 솔루션 도출 과정이 합리적임. 제품 고도화 방안에 대한 구체적인 계획이 다소 미흡함. _x000D_⑤카본소재 외장품 개발을 통한 전기차 화재방지효과를 내기 위한 과제임. 소재에 대한 근거와 준비과정이 잘 소개되어 있음. 시장 진입이 가능할것으로 보임. | AE11: =IFERROR(TEXT(VLOOKUP($B11,[1]평가!$B:$Z,MATCH(AE$2,[1]평가!$7:$7,0)-1,FALSE),"①@ ") & CHAR(13) & TEXT(VLOOKUP($B11,[2]평가!$B:$Z,MATCH(AE$2,[2]평가!$7:$7,0)-1,FALSE),"②@ ") & CHAR(13) & TEXT(VLOOKUP($B11,[3]평가!$B:$Z,MATCH(AE$2,[3]평가!$7:$7,0)-1,FALSE),"③@ ") & CHAR(13) & TEXT(VLOOKUP($B11,[4]평가!$B:$Z,MATCH(AE$2,[4]평가!$7:$7,0)-1,FALSE),"④@ ") & CHAR(13) & TEXT(VLOOKUP($B11,[5]평가!$B:$Z,MATCH(AE$2,[5]평가!$7:$7,0)-1,FALSE),"⑤@ "),"") -> 0_x000D_0_x000D_0_x000D_0_x000D_0 | AF11: =IFERROR(TEXT(VLOOKUP($B11,[1]평가!$B:$Z,MATCH(AF$2,[1]평가!$6:$6,0)-1,FALSE),"①@ ") & CHAR(13) & TEXT(VLOOKUP($B11,[2]평가!$B:$Z,MATCH(AF$2,[2]평가!$6:$6,0)-1,FALSE),"②@ ") & CHAR(13) & TEXT(VLOOKUP($B11,[3]평가!$B:$Z,MATCH(AF$2,[3]평가!$6:$6,0)-1,FALSE),"③@ ") & CHAR(13) & TEXT(VLOOKUP($B11,[4]평가!$B:$Z,MATCH(AF$2,[4]평가!$6:$6,0)-1,FALSE),"④@ ") & CHAR(13) & TEXT(VLOOKUP($B11,[5]평가!$B:$Z,MATCH(AF$2,[5]평가!$6:$6,0)-1,FALSE),"⑤@ "),"") -> 0_x000D_0_x000D_0_x000D_0_x000D_0
